Workbook

Sheet Yönetici Özeti
A1: 2026 YILLIK İŞ PLANI - YÖNETİCİ ÖZETİ
A5: Yönetim Beyanı | BIGR | Buluts | Dış Hizmet ve Süreç Denetimleri Tüm değerler 'İş Planı' sayfasından otomatik hesaplanır.
B8: TOPLAM İŞ KALEMİ | J8: PLANLANAN | R8: DEVAM EDİYOR | Z8: TAMAMLANDI | AH8: GECİKMİŞ | AP8: GENEL İLERLEME
B9: =Hesap!$U$2 | J9: =Hesap!$U$6 | R9: =Hesap!$U$4 | Z9: =Hesap!$U$3 | AH9: =Hesap!$U$5 | AP9: =Hesap!$U$7
B11: Plandaki toplam satır | J11: Henüz başlamamış | R11: Açık çalışma | Z11: Kapanan iş sayısı | AH11: Süresi geçmiş - otomatik | AP11: Ağırlıksız ortalama
B15: DURUM DAĞILIMI | S15: AYLIK İŞ YÜKÜ
B16: Durum (Otomatik) sütununa göre | S16: Her ayda aktif (başlamış ve bitmemiş) iş kalemi sayısı
B35: HAFTALIK İLERLEME EĞRİSİ
B36: Kümülatif: o haftanın sonuna kadar bitmesi planlanan iş sayısı ile bunlardan tamamlananların sayısı
B57: AYLIK İLERLEME EĞRİSİ
B58: Aynı hesap ayın son gününe göre - yönetim raporlaması için
B79: DENETİM BAŞLIĞINA GÖRE İŞ DURUMU
B80: Yalnızca İş Planı'nda fiilen kullanılan denetim başlıkları listelenir; Listeler sayfasındaki her değişiklik burada anında yansır
B105: KİŞİ BAZLI İŞ YÜKÜ
B106: Sorumlu 1-3 sütunlarının tamamı sayılır; tamamlanan işler hariçtir. Kırmızı bölüm o kişinin süresi geçmiş işlerini gösterir
B131: GECİKME ANALİZİ
B132: En yüksek 10 gecikme: elle girilen Gecikme (Gün) ile orijinal Bitiş tarihinin aşımından hangisi büyükse o alınır - gün girilmemiş işler de sayılır
B153: RENK LEJANDI
E154: Planlanan
E155: Devam Ediyor
E156: Tamamlandı
E157: Gecikmiş

Sheet Listeler
B1: AÇILIR LİSTE KAYNAKLARI
B3: Denetim Başlıkları | D3: Kişiler | F3: Öncelik | H3: Durum (referans)
B4: Yönetim Beyanı | D4: Örnek Soyad1 | F4: Yüksek | H4: Planlanan
B5: BIGR | D5: Örnek Soyad2 | F5: Orta | H5: Devam Ediyor
B6: Buluts | D6: Örnek Soyad3 | F6: Düşük | H6: Tamamlandı
B7: Firma Teknoloji Dış Hizmet Denetimi | D7: Örnek Soyad4 | H7: Gecikmiş
B8: WS Entegrasyon Denetimi | D8: Örnek Soyad5
B9: Süreç Denetimleri | D9: Örnek Soyad6
B10: Destek Hizmeti Denetimler | D10: Örnek Soyad7
B11: Rehberlik Faaliyeti | D11: Örnek Soyad8
B12: MPP-631 | D12: Örnek Soyad9
B13: MPP-102 | D13: Örnek Soyad10
B14: MPP-463 | D14: Örnek Soyad11
B15: MPP-370 | D15: Örnek Soyad12
B16: Ad-Hoc İşler | D16: Örnek Soyad13
B17: Rutin Faaliyetler
B18: AVM Faz 2 Denetimi
B19: Gündem
B20: Kararlar
B46: Denetim Başlıkları, Kişiler ve Öncelik sütunları 'İş Planı' sayfasındaki açılır listeleri besler. Yeni bir değer eklemek için ilgili sütundaki ilk boş hücreye yazmanız yeterlidir - liste ve Yönetici Özeti'ndeki denetim başlığı grafikleri anında güncellenir. Durum (referans) sütunu açılır liste DEĞİLDİR: durum, İş Planı'nda İlerleme % ve tarihlerden otomatik hesaplanır. Bu dört ad Gantt renk kurallarına ve Yönetici Özeti formüllerine gömülüdür; buradan değiştirilemez.

Sheet Hesap
A1: Bu sayfa Yönetici Özeti grafiklerinin veri kaynağıdır. Elle değiştirmeyin; tüm hücreler İş Planı'ndan hesaplanır. İsterseniz sayfa sekmesine sağ tıklayıp gizleyebilirsiniz. | E1: Durum | F1: Adet | H1: Ay | I1: Ay Başı | J1: Aktif İş | L1: Sıra | M1: İş Kalemi | N1: Gecikme (Gün) | T1: KPI | W1: Denetim Başlığı | X1: Tamamlanan | Y1: Devam Eden | Z1: Gecikmiş | AB1: Hafta | AC1: Planlanan (Küm.) | AD1: Gerçekleşen (Küm.) | AF1: Ay | AG1: Ay Sonu | AH1: Planlanan (Küm.) | AI1: Gerçekleşen (Küm.) | AK1: Kişi | AL1: Açık İş | AM1: Gecikmiş
E2: Planlanan | F2: =COUNTIFS('İş Planı'!$N$5:$N$204,E2,'İş Planı'!$C$5:$C$204,"<>") | H2: Oca | I2: 46023 | J2: =SUMPRODUCT(('İş Planı'!$C$5:$C$204<>"")*('İş Planı'!$H$5:$H$204<>"")*('İş Planı'!$I$5:$I$204<>"")*('İş Planı'!$H$5:$H$204<=EOMONTH(I2,0))*('İş Planı'!$L$5:$L$204>=I2)) | L2: 10 | M2: =IFERROR(IF(LARGE($R$5:$R$204,L2)<0.5,"",INDEX('İş Planı'!$C$5:$C$204,MATCH(LARGE($R$5:$R$204,L2),$R$5:$R$204,0))),"") | N2: =IFERROR(IF(LARGE($R$5:$R$204,L2)<0.5,0,INT(LARGE($R$5:$R$204,L2))),0) | T2: Toplam İş Kalemi | U2: =COUNTA('İş Planı'!$C$5:$C$204) | W2: =IFERROR(INDEX(Listeler!$B$4:$B$43,SMALL($BB$4:$BB$43,22-ROW())),"") | X2: =IF($W2="","",COUNTIFS('İş Planı'!$B$5:$B$204,$W2,'İş Planı'!$N$5:$N$204,"Tamamlandı")) | Y2: =IF($W2="","",COUNTIFS('İş Planı'!$B$5:$B$204,$W2,'İş Planı'!$N$5:$N$204,"Devam Ediyor")) | Z2: =IF($W2="","",COUNTIFS('İş Planı'!$B$5:$B$204,$W2,'İş Planı'!$N$5:$N$204,"Gecikmiş")) | AB2: 46029 | AC2: =SUMPRODUCT(('İş Planı'!$C$5:$C$204<>"")*('İş Planı'!$L$5:$L$204<>"")*('İş Planı'!$L$5:$L$204<=AB2)) | AD2: =SUMPRODUCT(('İş Planı'!$C$5:$C$204<>"")*('İş Planı'!$L$5:$L$204<>"")*('İş Planı'!$L$5:$L$204<=AB2)*('İş Planı'!$N$5:$N$204="Tamamlandı")) | AF2: Oca | AG2: 46053 | AH2: =SUMPRODUCT(('İş Planı'!$C$5:$C$204<>"")*('İş Planı'!$L$5:$L$204<>"")*('İş Planı'!$L$5:$L$204<=AG2)) | AI2: =SUMPRODUCT(('İş Planı'!$C$5:$C$204<>"")*('İş Planı'!$L$5:$L$204<>"")*('İş Planı'!$L$5:$L$204<=AG2)*('İş Planı'!$N$5:$N$204="Tamamlandı")) | AK2: =IFERROR(INDEX(Listeler!$D$4:$D$43,SMALL($BD$4:$BD$43,22-ROW())),"") | AL2: =IF($AK2="","",COUNTIFS('İş Planı'!$D$5:$D$204,$AK2,'İş Planı'!$N$5:$N$204,"Planlanan")+COUNTIFS('İş Planı'!$E$5:$E$204,$AK2,'İş Planı'!$N$5:$N$204,"Planlanan")+COUNTIFS('İş Planı'!$F$5:$F$204,$AK2,'İş Planı'!$N$5:$N$204,"Planlanan")+COUNTIFS('İş Planı'!$D$5:$D$204,$AK2,'İş Planı'!$N$5:$N$204,"Devam Ediyor")+COUNTIFS('İş Planı'!$E$5:$E$204,$AK2,'İş Planı'!$N$5:$N$204,"Devam Ediyor")+COUNTIFS('İş Planı'!$F$5:$F$204,$AK2,'İş Planı'!$N$5:$N$204,"Devam Ediyor")) | AM2: =IF($AK2="","",COUNTIFS('İş Planı'!$D$5:$D$204,$AK2,'İş Planı'!$N$5:$N$204,"Gecikmiş")+COUNTIFS('İş Planı'!$E$5:$E$204,$AK2,'İş Planı'!$N$5:$N$204,"Gecikmiş")+COUNTIFS('İş Planı'!$F$5:$F$204,$AK2,'İş Planı'!$N$5:$N$204,"Gecikmiş"))
E3: Devam Ediyor | F3: =COUNTIFS('İş Planı'!$N$5:$N$204,E3,'İş Planı'!$C$5:$C$204,"<>") | H3: Şub | I3: 46054 | J3: =SUMPRODUCT(('İş Planı'!$C$5:$C$204<>"")*('İş Planı'!$H$5:$H$204<>"")*('İş Planı'!$I$5:$I$204<>"")*('İş Planı'!$H$5:$H$204<=EOMONTH(I3,0))*('İş Planı'!$L$5:$L$204>=I3)) | L3: 9 | M3: =IFERROR(IF(LARGE($R$5:$R$204,L3)<0.5,"",INDEX('İş Planı'!$C$5:$C$204,MATCH(LARGE($R$5:$R$204,L3),$R$5:$R$204,0))),"") | N3: =IFERROR(IF(LARGE($R$5:$R$204,L3)<0.5,0,INT(LARGE($R$5:$R$204,L3))),0) | T3: Tamamlandı | U3: =F4 | W3: =IFERROR(INDEX(Listeler!$B$4:$B$43,SMALL($BB$4:$BB$43,22-ROW())),"") | X3: =IF($W3="","",COUNTIFS('İş Planı'!$B$5:$B$204,$W3,'İş Planı'!$N$5:$N$204,"Tamamlandı")) | Y3: =IF($W3="","",COUNTIFS('İş Planı'!$B$5:$B$204,$W3,'İş Planı'!$N$5:$N$204,"Devam Ediyor")) | Z3: =IF($W3="","",COUNTIFS('İş Planı'!$B$5:$B$204,$W3,'İş Planı'!$N$5:$N$204,"Gecikmiş")) | AB3: 46036 | AC3: =SUMPRODUCT(('İş Planı'!$C$5:$C$204<>"")*('İş Planı'!$L$5:$L$204<>"")*('İş Planı'!$L$5:$L$204<=AB3)) | AD3: =SUMPRODUCT(('İş Planı'!$C$5:$C$204<>"")*('İş Planı'!$L$5:$L$204<>"")*('İş Planı'!$L$5:$L$204<=AB3)*('İş Planı'!$N$5:$N$204="Tamamlandı")) | AF3: Şub | AG3: 46081 | AH3: =SUMPRODUCT(('İş Planı'!$C$5:$C$204<>"")*('İş Planı'!$L$5:$L$204<>"")*('İş Planı'!$L$5:$L$204<=AG3)) | AI3: =SUMPRODUCT(('İş Planı'!$C$5:$C$204<>"")*('İş Planı'!$L$5:$L$204<>"")*('İş Planı'!$L$5:$L$204<=AG3)*('İş Planı'!$N$5:$N$204="Tamamlandı")) | AK3: =IFERROR(INDEX(Listeler!$D$4:$D$43,SMALL($BD$4:$BD$43,22-ROW())),"") | AL3: =IF($AK3="","",COUNTIFS('İş Planı'!$D$5:$D$204,$AK3,'İş Planı'!$N$5:$N$204,"Planlanan")+COUNTIFS('İş Planı'!$E$5:$E$204,$AK3,'İş Planı'!$N$5:$N$204,"Planlanan")+COUNTIFS('İş Planı'!$F$5:$F$204,$AK3,'İş Planı'!$N$5:$N$204,"Planlanan")+COUNTIFS('İş Planı'!$D$5:$D$204,$AK3,'İş Planı'!$N$5:$N$204,"Devam Ediyor")+COUNTIFS('İş Planı'!$E$5:$E$204,$AK3,'İş Planı'!$N$5:$N$204,"Devam Ediyor")+COUNTIFS('İş Planı'!$F$5:$F$204,$AK3,'İş Planı'!$N$5:$N$204,"Devam Ediyor")) | AM3: =IF($AK3="","",COUNTIFS('İş Planı'!$D$5:$D$204,$AK3,'İş Planı'!$N$5:$N$204,"Gecikmiş")+COUNTIFS('İş Planı'!$E$5:$E$204,$AK3,'İş Planı'!$N$5:$N$204,"Gecikmiş")+COUNTIFS('İş Planı'!$F$5:$F$204,$AK3,'İş Planı'!$N$5:$N$204,"Gecikmiş")) | BA3: Kullanılan başlık indeksi (Listeler B4:B43) | BC3: Yükü olan kişi indeksi (Listeler D4:D43)
E4: Tamamlandı | F4: =COUNTIFS('İş Planı'!$N$5:$N$204,E4,'İş Planı'!$C$5:$C$204,"<>") | H4: Mar | I4: 46082 | J4: =SUMPRODUCT(('İş Planı'!$C$5:$C$204<>"")*('İş Planı'!$H$5:$H$204<>"")*('İş Planı'!$I$5:$I$204<>"")*('İş Planı'!$H$5:$H$204<=EOMONTH(I4,0))*('İş Planı'!$L$5:$L$204>=I4)) | L4: 8 | M4: =IFERROR(IF(LARGE($R$5:$R$204,L4)<0.5,"",INDEX('İş Planı'!$C$5:$C$204,MATCH(LARGE($R$5:$R$204,L4),$R$5:$R$204,0))),"") | N4: =IFERROR(IF(LARGE($R$5:$R$204,L4)<0.5,0,INT(LARGE($R$5:$R$204,L4))),0) | R4: Fiili gecikme (gün) + sıralama kırıcı | T4: Devam Ediyor | U4: =F3 | W4: =IFERROR(INDEX(Listeler!$B$4:$B$43,SMALL($BB$4:$BB$43,22-ROW())),"") | X4: =IF($W4="","",COUNTIFS('İş Planı'!$B$5:$B$204,$W4,'İş Planı'!$N$5:$N$204,"Tamamlandı")) | Y4: =IF($W4="","",COUNTIFS('İş Planı'!$B$5:$B$204,$W4,'İş Planı'!$N$5:$N$204,"Devam Ediyor")) | Z4: =IF($W4="","",COUNTIFS('İş Planı'!$B$5:$B$204,$W4,'İş Planı'!$N$5:$N$204,"Gecikmiş")) | AB4: 46043 | AC4: =SUMPRODUCT(('İş Planı'!$C$5:$C$204<>"")*('İş Planı'!$L$5:$L$204<>"")*('İş Planı'!$L$5:$L$204<=AB4)) | AD4: =SUMPRODUCT(('İş Planı'!$C$5:$C$204<>"")*('İş Planı'!$L$5:$L$204<>"")*('İş Planı'!$L$5:$L$204<=AB4)*('İş Planı'!$N$5:$N$204="Tamamlandı")) | AF4: Mar | AG4: 46112 | AH4: =SUMPRODUCT(('İş Planı'!$C$5:$C$204<>"")*('İş Planı'!$L$5:$L$204<>"")*('İş Planı'!$L$5:$L$204<=AG4)) | AI4: =SUMPRODUCT(('İş Planı'!$C$5:$C$204<>"")*('İş Planı'!$L$5:$L$204<>"")*('İş Planı'!$L$5:$L$204<=AG4)*('İş Planı'!$N$5:$N$204="Tamamlandı")) | AK4: =IFERROR(INDEX(Listeler!$D$4:$D$43,SMALL($BD$4:$BD$43,22-ROW())),"") | AL4: =IF($AK4="","",COUNTIFS('İş Planı'!$D$5:$D$204,$AK4,'İş Planı'!$N$5:$N$204,"Planlanan")+COUNTIFS('İş Planı'!$E$5:$E$204,$AK4,'İş Planı'!$N$5:$N$204,"Planlanan")+COUNTIFS('İş Planı'!$F$5:$F$204,$AK4,'İş Planı'!$N$5:$N$204,"Planlanan")+COUNTIFS('İş Planı'!$D$5:$D$204,$AK4,'İş Planı'!$N$5:$N$204,"Devam Ediyor")+COUNTIFS('İş Planı'!$E$5:$E$204,$AK4,'İş Planı'!$N$5:$N$204,"Devam Ediyor")+COUNTIFS('İş Planı'!$F$5:$F$204,$AK4,'İş Planı'!$N$5:$N$204,"Devam Ediyor")) | AM4: =IF($AK4="","",COUNTIFS('İş Planı'!$D$5:$D$204,$AK4,'İş Planı'!$N$5:$N$204,"Gecikmiş")+COUNTIFS('İş Planı'!$E$5:$E$204,$AK4,'İş Planı'!$N$5:$N$204,"Gecikmiş")+COUNTIFS('İş Planı'!$F$5:$F$204,$AK4,'İş Planı'!$N$5:$N$204,"Gecikmiş")) | BB4: =IF(Listeler!$B4="","",IF(COUNTIF('İş Planı'!$B$5:$B$204,Listeler!$B4)=0,"",ROW()-3)) | BD4: =IF(Listeler!$D4="","",IF(COUNTIF('İş Planı'!$D$5:$D$204,Listeler!$D4)+COUNTIF('İş Planı'!$E$5:$E$204,Listeler!$D4)+COUNTIF('İş Planı'!$F$5:$F$204,Listeler!$D4)=0,"",ROW()-3))
E5: Gecikmiş | F5: =COUNTIFS('İş Planı'!$N$5:$N$204,E5,'İş Planı'!$C$5:$C$204,"<>") | H5: Nis | I5: 46113 | J5: =SUMPRODUCT(('İş Planı'!$C$5:$C$204<>"")*('İş Planı'!$H$5:$H$204<>"")*('İş Planı'!$I$5:$I$204<>"")*('İş Planı'!$H$5:$H$204<=EOMONTH(I5,0))*('İş Planı'!$L$5:$L$204>=I5)) | L5: 7 | M5: =IFERROR(IF(LARGE($R$5:$R$204,L5)<0.5,"",INDEX('İş Planı'!$C$5:$C$204,MATCH(LARGE($R$5:$R$204,L5),$R$5:$R$204,0))),"") | N5: =IFERROR(IF(LARGE($R$5:$R$204,L5)<0.5,0,INT(LARGE($R$5:$R$204,L5))),0) | R5: =IF('İş Planı'!$C5="","",IF('İş Planı'!$N5="Tamamlandı",N('İş Planı'!$K5),MAX(N('İş Planı'!$K5),IF(AND('İş Planı'!$I5<>"",'İş Planı'!$I5<TODAY()),TODAY()-'İş Planı'!$I5,0)))+ROW()/1000000) | T5: Gecikmiş | U5: =F5 | W5: =IFERROR(INDEX(Listeler!$B$4:$B$43,SMALL($BB$4:$BB$43,22-ROW())),"") | X5: =IF($W5="","",COUNTIFS('İş Planı'!$B$5:$B$204,$W5,'İş Planı'!$N$5:$N$204,"Tamamlandı")) | Y5: =IF($W5="","",COUNTIFS('İş Planı'!$B$5:$B$204,$W5,'İş Planı'!$N$5:$N$204,"Devam Ediyor")) | Z5: =IF($W5="","",COUNTIFS('İş Planı'!$B$5:$B$204,$W5,'İş Planı'!$N$5:$N$204,"Gecikmiş")) | AB5: 46050 | AC5: =SUMPRODUCT(('İş Planı'!$C$5:$C$204<>"")*('İş Planı'!$L$5:$L$204<>"")*('İş Planı'!$L$5:$L$204<=AB5)) | AD5: =SUMPRODUCT(('İş Planı'!$C$5:$C$204<>"")*('İş Planı'!$L$5:$L$204<>"")*('İş Planı'!$L$5:$L$204<=AB5)*('İş Planı'!$N$5:$N$204="Tamamlandı")) | AF5: Nis | AG5: 46142 | AH5: =SUMPRODUCT(('İş Planı'!$C$5:$C$204<>"")*('İş Planı'!$L$5:$L$204<>"")*('İş Planı'!$L$5:$L$204<=AG5)) | AI5: =SUMPRODUCT(('İş Planı'!$C$5:$C$204<>"")*('İş Planı'!$L$5:$L$204<>"")*('İş Planı'!$L$5:$L$204<=AG5)*('İş Planı'!$N$5:$N$204="Tamamlandı")) | AK5: =IFERROR(INDEX(Listeler!$D$4:$D$43,SMALL($BD$4:$BD$43,22-ROW())),"") | AL5: =IF($AK5="","",COUNTIFS('İş Planı'!$D$5:$D$204,$AK5,'İş Planı'!$N$5:$N$204,"Planlanan")+COUNTIFS('İş Planı'!$E$5:$E$204,$AK5,'İş Planı'!$N$5:$N$204,"Planlanan")+COUNTIFS('İş Planı'!$F$5:$F$204,$AK5,'İş Planı'!$N$5:$N$204,"Planlanan")+COUNTIFS('İş Planı'!$D$5:$D$204,$AK5,'İş Planı'!$N$5:$N$204,"Devam Ediyor")+COUNTIFS('İş Planı'!$E$5:$E$204,$AK5,'İş Planı'!$N$5:$N$204,"Devam Ediyor")+COUNTIFS('İş Planı'!$F$5:$F$204,$AK5,'İş Planı'!$N$5:$N$204,"Devam Ediyor")) | AM5: =IF($AK5="","",COUNTIFS('İş Planı'!$D$5:$D$204,$AK5,'İş Planı'!$N$5:$N$204,"Gecikmiş")+COUNTIFS('İş Planı'!$E$5:$E$204,$AK5,'İş Planı'!$N$5:$N$204,"Gecikmiş")+COUNTIFS('İş Planı'!$F$5:$F$204,$AK5,'İş Planı'!$N$5:$N$204,"Gecikmiş")) | BB5: =IF(Listeler!$B5="","",IF(COUNTIF('İş Planı'!$B$5:$B$204,Listeler!$B5)=0,"",ROW()-3)) | BD5: =IF(Listeler!$D5="","",IF(COUNTIF('İş Planı'!$D$5:$D$204,Listeler!$D5)+COUNTIF('İş Planı'!$E$5:$E$204,Listeler!$D5)+COUNTIF('İş Planı'!$F$5:$F$204,Listeler!$D5)=0,"",ROW()-3))
H6: May | I6: 46143 | J6: =SUMPRODUCT(('İş Planı'!$C$5:$C$204<>"")*('İş Planı'!$H$5:$H$204<>"")*('İş Planı'!$I$5:$I$204<>"")*('İş Planı'!$H$5:$H$204<=EOMONTH(I6,0))*('İş Planı'!$L$5:$L$204>=I6)) | L6: 6 | M6: =IFERROR(IF(LARGE($R$5:$R$204,L6)<0.5,"",INDEX('İş Planı'!$C$5:$C$204,MATCH(LARGE($R$5:$R$204,L6),$R$5:$R$204,0))),"") | N6: =IFERROR(IF(LARGE($R$5:$R$204,L6)<0.5,0,INT(LARGE($R$5:$R$204,L6))),0) | R6: =IF('İş Planı'!$C6="","",IF('İş Planı'!$N6="Tamamlandı",N('İş Planı'!$K6),MAX(N('İş Planı'!$K6),IF(AND('İş Planı'!$I6<>"",'İş Planı'!$I6<TODAY()),TODAY()-'İş Planı'!$I6,0)))+ROW()/1000000) | T6: Planlanan | U6: =F2 | W6: =IFERROR(INDEX(Listeler!$B$4:$B$43,SMALL($BB$4:$BB$43,22-ROW())),"") | X6: =IF($W6="","",COUNTIFS('İş Planı'!$B$5:$B$204,$W6,'İş Planı'!$N$5:$N$204,"Tamamlandı")) | Y6: =IF($W6="","",COUNTIFS('İş Planı'!$B$5:$B$204,$W6,'İş Planı'!$N$5:$N$204,"Devam Ediyor")) | Z6: =IF($W6="","",COUNTIFS('İş Planı'!$B$5:$B$204,$W6,'İş Planı'!$N$5:$N$204,"Gecikmiş")) | AB6: 46057 | AC6: =SUMPRODUCT(('İş Planı'!$C$5:$C$204<>"")*('İş Planı'!$L$5:$L$204<>"")*('İş Planı'!$L$5:$L$204<=AB6)) | AD6: =SUMPRODUCT(('İş Planı'!$C$5:$C$204<>"")*('İş Planı'!$L$5:$L$204<>"")*('İş Planı'!$L$5:$L$204<=AB6)*('İş Planı'!$N$5:$N$204="Tamamlandı")) | AF6: May | AG6: 46173 | AH6: =SUMPRODUCT(('İş Planı'!$C$5:$C$204<>"")*('İş Planı'!$L$5:$L$204<>"")*('İş Planı'!$L$5:$L$204<=AG6)) | AI6: =SUMPRODUCT(('İş Planı'!$C$5:$C$204<>"")*('İş Planı'!$L$5:$L$204<>"")*('İş Planı'!$L$5:$L$204<=AG6)*('İş Planı'!$N$5:$N$204="Tamamlandı")) | AK6: =IFERROR(INDEX(Listeler!$D$4:$D$43,SMALL($BD$4:$BD$43,22-ROW())),"") | AL6: =IF($AK6="","",COUNTIFS('İş Planı'!$D$5:$D$204,$AK6,'İş Planı'!$N$5:$N$204,"Planlanan")+COUNTIFS('İş Planı'!$E$5:$E$204,$AK6,'İş Planı'!$N$5:$N$204,"Planlanan")+COUNTIFS('İş Planı'!$F$5:$F$204,$AK6,'İş Planı'!$N$5:$N$204,"Planlanan")+COUNTIFS('İş Planı'!$D$5:$D$204,$AK6,'İş Planı'!$N$5:$N$204,"Devam Ediyor")+COUNTIFS('İş Planı'!$E$5:$E$204,$AK6,'İş Planı'!$N$5:$N$204,"Devam Ediyor")+COUNTIFS('İş Planı'!$F$5:$F$204,$AK6,'İş Planı'!$N$5:$N$204,"Devam Ediyor")) | AM6: =IF($AK6="","",COUNTIFS('İş Planı'!$D$5:$D$204,$AK6,'İş Planı'!$N$5:$N$204,"Gecikmiş")+COUNTIFS('İş Planı'!$E$5:$E$204,$AK6,'İş Planı'!$N$5:$N$204,"Gecikmiş")+COUNTIFS('İş Planı'!$F$5:$F$204,$AK6,'İş Planı'!$N$5:$N$204,"Gecikmiş")) | BB6: =IF(Listeler!$B6="","",IF(COUNTIF('İş Planı'!$B$5:$B$204,Listeler!$B6)=0,"",ROW()-3)) | BD6: =IF(Listeler!$D6="","",IF(COUNTIF('İş Planı'!$D$5:$D$204,Listeler!$D6)+COUNTIF('İş Planı'!$E$5:$E$204,Listeler!$D6)+COUNTIF('İş Planı'!$F$5:$F$204,Listeler!$D6)=0,"",ROW()-3))
H7: Haz | I7: 46174 | J7: =SUMPRODUCT(('İş Planı'!$C$5:$C$204<>"")*('İş Planı'!$H$5:$H$204<>"")*('İş Planı'!$I$5:$I$204<>"")*('İş Planı'!$H$5:$H$204<=EOMONTH(I7,0))*('İş Planı'!$L$5:$L$204>=I7)) | L7: 5 | M7: =IFERROR(IF(LARGE($R$5:$R$204,L7)<0.5,"",INDEX('İş Planı'!$C$5:$C$204,MATCH(LARGE($R$5:$R$204,L7),$R$5:$R$204,0))),"") | N7: =IFERROR(IF(LARGE($R$5:$R$204,L7)<0.5,0,INT(LARGE($R$5:$R$204,L7))),0) | R7: =IF('İş Planı'!$C7="","",IF('İş Planı'!$N7="Tamamlandı",N('İş Planı'!$K7),MAX(N('İş Planı'!$K7),IF(AND('İş Planı'!$I7<>"",'İş Planı'!$I7<TODAY()),TODAY()-'İş Planı'!$I7,0)))+ROW()/1000000) | T7: Genel İlerleme | U7: =IFERROR(SUMPRODUCT(('İş Planı'!$C$5:$C$204<>"")*('İş Planı'!$M$5:$M$204))/COUNTA('İş Planı'!$C$5:$C$204),0) | W7: =IFERROR(INDEX(Listeler!$B$4:$B$43,SMALL($BB$4:$BB$43,22-ROW())),"") | X7: =IF($W7="","",COUNTIFS('İş Planı'!$B$5:$B$204,$W7,'İş Planı'!$N$5:$N$204,"Tamamlandı")) | Y7: =IF($W7="","",COUNTIFS('İş Planı'!$B$5:$B$204,$W7,'İş Planı'!$N$5:$N$204,"Devam Ediyor")) | Z7: =IF($W7="","",COUNTIFS('İş Planı'!$B$5:$B$204,$W7,'İş Planı'!$N$5:$N$204,"Gecikmiş")) | AB7: 46064 | AC7: =SUMPRODUCT(('İş Planı'!$C$5:$C$204<>"")*('İş Planı'!$L$5:$L$204<>"")*('İş Planı'!$L$5:$L$204<=AB7)) | AD7: =SUMPRODUCT(('İş Planı'!$C$5:$C$204<>"")*('İş Planı'!$L$5:$L$204<>"")*('İş Planı'!$L$5:$L$204<=AB7)*('İş Planı'!$N$5:$N$204="Tamamlandı")) | AF7: Haz | AG7: 46203 | AH7: =SUMPRODUCT(('İş Planı'!$C$5:$C$204<>"")*('İş Planı'!$L$5:$L$204<>"")*('İş Planı'!$L$5:$L$204<=AG7)) | AI7: =SUMPRODUCT(('İş Planı'!$C$5:$C$204<>"")*('İş Planı'!$L$5:$L$204<>"")*('İş Planı'!$L$5:$L$204<=AG7)*('İş Planı'!$N$5:$N$204="Tamamlandı")) | AK7: =IFERROR(INDEX(Listeler!$D$4:$D$43,SMALL($BD$4:$BD$43,22-ROW())),"") | AL7: =IF($AK7="","",COUNTIFS('İş Planı'!$D$5:$D$204,$AK7,'İş Planı'!$N$5:$N$204,"Planlanan")+COUNTIFS('İş Planı'!$E$5:$E$204,$AK7,'İş Planı'!$N$5:$N$204,"Planlanan")+COUNTIFS('İş Planı'!$F$5:$F$204,$AK7,'İş Planı'!$N$5:$N$204,"Planlanan")+COUNTIFS('İş Planı'!$D$5:$D$204,$AK7,'İş Planı'!$N$5:$N$204,"Devam Ediyor")+COUNTIFS('İş Planı'!$E$5:$E$204,$AK7,'İş Planı'!$N$5:$N$204,"Devam Ediyor")+COUNTIFS('İş Planı'!$F$5:$F$204,$AK7,'İş Planı'!$N$5:$N$204,"Devam Ediyor")) | AM7: =IF($AK7="","",COUNTIFS('İş Planı'!$D$5:$D$204,$AK7,'İş Planı'!$N$5:$N$204,"Gecikmiş")+COUNTIFS('İş Planı'!$E$5:$E$204,$AK7,'İş Planı'!$N$5:$N$204,"Gecikmiş")+COUNTIFS('İş Planı'!$F$5:$F$204,$AK7,'İş Planı'!$N$5:$N$204,"Gecikmiş")) | BB7: =IF(Listeler!$B7="","",IF(COUNTIF('İş Planı'!$B$5:$B$204,Listeler!$B7)=0,"",ROW()-3)) | BD7: =IF(Listeler!$D7="","",IF(COUNTIF('İş Planı'!$D$5:$D$204,Listeler!$D7)+COUNTIF('İş Planı'!$E$5:$E$204,Listeler!$D7)+COUNTIF('İş Planı'!$F$5:$F$204,Listeler!$D7)=0,"",ROW()-3))
H8: Tem | I8: 46204 | J8: =SUMPRODUCT(('İş Planı'!$C$5:$C$204<>"")*('İş Planı'!$H$5:$H$204<>"")*('İş Planı'!$I$5:$I$204<>"")*('İş Planı'!$H$5:$H$204<=EOMONTH(I8,0))*('İş Planı'!$L$5:$L$204>=I8)) | L8: 4 | M8: =IFERROR(IF(LARGE($R$5:$R$204,L8)<0.5,"",INDEX('İş Planı'!$C$5:$C$204,MATCH(LARGE($R$5:$R$204,L8),$R$5:$R$204,0))),"") | N8: =IFERROR(IF(LARGE($R$5:$R$204,L8)<0.5,0,INT(LARGE($R$5:$R$204,L8))),0) | R8: =IF('İş Planı'!$C8="","",IF('İş Planı'!$N8="Tamamlandı",N('İş Planı'!$K8),MAX(N('İş Planı'!$K8),IF(AND('İş Planı'!$I8<>"",'İş Planı'!$I8<TODAY()),TODAY()-'İş Planı'!$I8,0)))+ROW()/1000000) | T8: Toplam Gecikme (Gün) | U8: =SUM('İş Planı'!$K$5:$K$204) | W8: =IFERROR(INDEX(Listeler!$B$4:$B$43,SMALL($BB$4:$BB$43,22-ROW())),"") | X8: =IF($W8="","",COUNTIFS('İş Planı'!$B$5:$B$204,$W8,'İş Planı'!$N$5:$N$204,"Tamamlandı")) | Y8: =IF($W8="","",COUNTIFS('İş Planı'!$B$5:$B$204,$W8,'İş Planı'!$N$5:$N$204,"Devam Ediyor")) | Z8: =IF($W8="","",COUNTIFS('İş Planı'!$B$5:$B$204,$W8,'İş Planı'!$N$5:$N$204,"Gecikmiş")) | AB8: 46071 | AC8: =SUMPRODUCT(('İş Planı'!$C$5:$C$204<>"")*('İş Planı'!$L$5:$L$204<>"")*('İş Planı'!$L$5:$L$204<=AB8)) | AD8: =SUMPRODUCT(('İş Planı'!$C$5:$C$204<>"")*('İş Planı'!$L$5:$L$204<>"")*('İş Planı'!$L$5:$L$204<=AB8)*('İş Planı'!$N$5:$N$204="Tamamlandı")) | AF8: Tem | AG8: 46234 | AH8: =SUMPRODUCT(('İş Planı'!$C$5:$C$204<>"")*('İş Planı'!$L$5:$L$204<>"")*('İş Planı'!$L$5:$L$204<=AG8)) | AI8: =SUMPRODUCT(('İş Planı'!$C$5:$C$204<>"")*('İş Planı'!$L$5:$L$204<>"")*('İş Planı'!$L$5:$L$204<=AG8)*('İş Planı'!$N$5:$N$204="Tamamlandı")) | AK8: =IFERROR(INDEX(Listeler!$D$4:$D$43,SMALL($BD$4:$BD$43,22-ROW())),"") | AL8: =IF($AK8="","",COUNTIFS('İş Planı'!$D$5:$D$204,$AK8,'İş Planı'!$N$5:$N$204,"Planlanan")+COUNTIFS('İş Planı'!$E$5:$E$204,$AK8,'İş Planı'!$N$5:$N$204,"Planlanan")+COUNTIFS('İş Planı'!$F$5:$F$204,$AK8,'İş Planı'!$N$5:$N$204,"Planlanan")+COUNTIFS('İş Planı'!$D$5:$D$204,$AK8,'İş Planı'!$N$5:$N$204,"Devam Ediyor")+COUNTIFS('İş Planı'!$E$5:$E$204,$AK8,'İş Planı'!$N$5:$N$204,"Devam Ediyor")+COUNTIFS('İş Planı'!$F$5:$F$204,$AK8,'İş Planı'!$N$5:$N$204,"Devam Ediyor")) | AM8: =IF($AK8="","",COUNTIFS('İş Planı'!$D$5:$D$204,$AK8,'İş Planı'!$N$5:$N$204,"Gecikmiş")+COUNTIFS('İş Planı'!$E$5:$E$204,$AK8,'İş Planı'!$N$5:$N$204,"Gecikmiş")+COUNTIFS('İş Planı'!$F$5:$F$204,$AK8,'İş Planı'!$N$5:$N$204,"Gecikmiş")) | BB8: =IF(Listeler!$B8="","",IF(COUNTIF('İş Planı'!$B$5:$B$204,Listeler!$B8)=0,"",ROW()-3)) | BD8: =IF(Listeler!$D8="","",IF(COUNTIF('İş Planı'!$D$5:$D$204,Listeler!$D8)+COUNTIF('İş Planı'!$E$5:$E$204,Listeler!$D8)+COUNTIF('İş Planı'!$F$5:$F$204,Listeler!$D8)=0,"",ROW()-3))
H9: Ağu | I9: 46235 | J9: =SUMPRODUCT(('İş Planı'!$C$5:$C$204<>"")*('İş Planı'!$H$5:$H$204<>"")*('İş Planı'!$I$5:$I$204<>"")*('İş Planı'!$H$5:$H$204<=EOMONTH(I9,0))*('İş Planı'!$L$5:$L$204>=I9)) | L9: 3 | M9: =IFERROR(IF(LARGE($R$5:$R$204,L9)<0.5,"",INDEX('İş Planı'!$C$5:$C$204,MATCH(LARGE($R$5:$R$204,L9),$R$5:$R$204,0))),"") | N9: =IFERROR(IF(LARGE($R$5:$R$204,L9)<0.5,0,INT(LARGE($R$5:$R$204,L9))),0) | R9: =IF('İş Planı'!$C9="","",IF('İş Planı'!$N9="Tamamlandı",N('İş Planı'!$K9),MAX(N('İş Planı'!$K9),IF(AND('İş Planı'!$I9<>"",'İş Planı'!$I9<TODAY()),TODAY()-'İş Planı'!$I9,0)))+ROW()/1000000) | W9: =IFERROR(INDEX(Listeler!$B$4:$B$43,SMALL($BB$4:$BB$43,22-ROW())),"") | X9: =IF($W9="","",COUNTIFS('İş Planı'!$B$5:$B$204,$W9,'İş Planı'!$N$5:$N$204,"Tamamlandı")) | Y9: =IF($W9="","",COUNTIFS('İş Planı'!$B$5:$B$204,$W9,'İş Planı'!$N$5:$N$204,"Devam Ediyor")) | Z9: =IF($W9="","",COUNTIFS('İş Planı'!$B$5:$B$204,$W9,'İş Planı'!$N$5:$N$204,"Gecikmiş")) | AB9: 46078 | AC9: =SUMPRODUCT(('İş Planı'!$C$5:$C$204<>"")*('İş Planı'!$L$5:$L$204<>"")*('İş Planı'!$L$5:$L$204<=AB9)) | AD9: =SUMPRODUCT(('İş Planı'!$C$5:$C$204<>"")*('İş Planı'!$L$5:$L$204<>"")*('İş Planı'!$L$5:$L$204<=AB9)*('İş Planı'!$N$5:$N$204="Tamamlandı")) | AF9: Ağu | AG9: 46265 | AH9: =SUMPRODUCT(('İş Planı'!$C$5:$C$204<>"")*('İş Planı'!$L$5:$L$204<>"")*('İş Planı'!$L$5:$L$204<=AG9)) | AI9: =SUMPRODUCT(('İş Planı'!$C$5:$C$204<>"")*('İş Planı'!$L$5:$L$204<>"")*('İş Planı'!$L$5:$L$204<=AG9)*('İş Planı'!$N$5:$N$204="Tamamlandı")) | AK9: =IFERROR(INDEX(Listeler!$D$4:$D$43,SMALL($BD$4:$BD$43,22-ROW())),"") | AL9: =IF($AK9="","",COUNTIFS('İş Planı'!$D$5:$D$204,$AK9,'İş Planı'!$N$5:$N$204,"Planlanan")+COUNTIFS('İş Planı'!$E$5:$E$204,$AK9,'İş Planı'!$N$5:$N$204,"Planlanan")+COUNTIFS('İş Planı'!$F$5:$F$204,$AK9,'İş Planı'!$N$5:$N$204,"Planlanan")+COUNTIFS('İş Planı'!$D$5:$D$204,$AK9,'İş Planı'!$N$5:$N$204,"Devam Ediyor")+COUNTIFS('İş Planı'!$E$5:$E$204,$AK9,'İş Planı'!$N$5:$N$204,"Devam Ediyor")+COUNTIFS('İş Planı'!$F$5:$F$204,$AK9,'İş Planı'!$N$5:$N$204,"Devam Ediyor")) | AM9: =IF($AK9="","",COUNTIFS('İş Planı'!$D$5:$D$204,$AK9,'İş Planı'!$N$5:$N$204,"Gecikmiş")+COUNTIFS('İş Planı'!$E$5:$E$204,$AK9,'İş Planı'!$N$5:$N$204,"Gecikmiş")+COUNTIFS('İş Planı'!$F$5:$F$204,$AK9,'İş Planı'!$N$5:$N$204,"Gecikmiş")) | BB9: =IF(Listeler!$B9="","",IF(COUNTIF('İş Planı'!$B$5:$B$204,Listeler!$B9)=0,"",ROW()-3)) | BD9: =IF(Listeler!$D9="","",IF(COUNTIF('İş Planı'!$D$5:$D$204,Listeler!$D9)+COUNTIF('İş Planı'!$E$5:$E$204,Listeler!$D9)+COUNTIF('İş Planı'!$F$5:$F$204,Listeler!$D9)=0,"",ROW()-3))
H10: Eyl | I10: 46266 | J10: =SUMPRODUCT(('İş Planı'!$C$5:$C$204<>"")*('İş Planı'!$H$5:$H$204<>"")*('İş Planı'!$I$5:$I$204<>"")*('İş Planı'!$H$5:$H$204<=EOMONTH(I10,0))*('İş Planı'!$L$5:$L$204>=I10)) | L10: 2 | M10: =IFERROR(IF(LARGE($R$5:$R$204,L10)<0.5,"",INDEX('İş Planı'!$C$5:$C$204,MATCH(LARGE($R$5:$R$204,L10),$R$5:$R$204,0))),"") | N10: =IFERROR(IF(LARGE($R$5:$R$204,L10)<0.5,0,INT(LARGE($R$5:$R$204,L10))),0) | R10: =IF('İş Planı'!$C10="","",IF('İş Planı'!$N10="Tamamlandı",N('İş Planı'!$K10),MAX(N('İş Planı'!$K10),IF(AND('İş Planı'!$I10<>"",'İş Planı'!$I10<TODAY()),TODAY()-'İş Planı'!$I10,0)))+ROW()/1000000) | W10: =IFERROR(INDEX(Listeler!$B$4:$B$43,SMALL($BB$4:$BB$43,22-ROW())),"") | X10: =IF($W10="","",COUNTIFS('İş Planı'!$B$5:$B$204,$W10,'İş Planı'!$N$5:$N$204,"Tamamlandı")) | Y10: =IF($W10="","",COUNTIFS('İş Planı'!$B$5:$B$204,$W10,'İş Planı'!$N$5:$N$204,"Devam Ediyor")) | Z10: =IF($W10="","",COUNTIFS('İş Planı'!$B$5:$B$204,$W10,'İş Planı'!$N$5:$N$204,"Gecikmiş")) | AB10: 46085 | AC10: =SUMPRODUCT(('İş Planı'!$C$5:$C$204<>"")*('İş Planı'!$L$5:$L$204<>"")*('İş Planı'!$L$5:$L$204<=AB10)) | AD10: =SUMPRODUCT(('İş Planı'!$C$5:$C$204<>"")*('İş Planı'!$L$5:$L$204<>"")*('İş Planı'!$L$5:$L$204<=AB10)*('İş Planı'!$N$5:$N$204="Tamamlandı")) | AF10: Eyl | AG10: 46295 | AH10: =SUMPRODUCT(('İş Planı'!$C$5:$C$204<>"")*('İş Planı'!$L$5:$L$204<>"")*('İş Planı'!$L$5:$L$204<=AG10)) | AI10: =SUMPRODUCT(('İş Planı'!$C$5:$C$204<>"")*('İş Planı'!$L$5:$L$204<>"")*('İş Planı'!$L$5:$L$204<=AG10)*('İş Planı'!$N$5:$N$204="Tamamlandı")) | AK10: =IFERROR(INDEX(Listeler!$D$4:$D$43,SMALL($BD$4:$BD$43,22-ROW())),"") | AL10: =IF($AK10="","",COUNTIFS('İş Planı'!$D$5:$D$204,$AK10,'İş Planı'!$N$5:$N$204,"Planlanan")+COUNTIFS('İş Planı'!$E$5:$E$204,$AK10,'İş Planı'!$N$5:$N$204,"Planlanan")+COUNTIFS('İş Planı'!$F$5:$F$204,$AK10,'İş Planı'!$N$5:$N$204,"Planlanan")+COUNTIFS('İş Planı'!$D$5:$D$204,$AK10,'İş Planı'!$N$5:$N$204,"Devam Ediyor")+COUNTIFS('İş Planı'!$E$5:$E$204,$AK10,'İş Planı'!$N$5:$N$204,"Devam Ediyor")+COUNTIFS('İş Planı'!$F$5:$F$204,$AK10,'İş Planı'!$N$5:$N$204,"Devam Ediyor")) | AM10: =IF($AK10="","",COUNTIFS('İş Planı'!$D$5:$D$204,$AK10,'İş Planı'!$N$5:$N$204,"Gecikmiş")+COUNTIFS('İş Planı'!$E$5:$E$204,$AK10,'İş Planı'!$N$5:$N$204,"Gecikmiş")+COUNTIFS('İş Planı'!$F$5:$F$204,$AK10,'İş Planı'!$N$5:$N$204,"Gecikmiş")) | BB10: =IF(Listeler!$B10="","",IF(COUNTIF('İş Planı'!$B$5:$B$204,Listeler!$B10)=0,"",ROW()-3)) | BD10: =IF(Listeler!$D10="","",IF(COUNTIF('İş Planı'!$D$5:$D$204,Listeler!$D10)+COUNTIF('İş Planı'!$E$5:$E$204,Listeler!$D10)+COUNTIF('İş Planı'!$F$5:$F$204,Listeler!$D10)=0,"",ROW()-3))
H11: Eki | I11: 46296 | J11: =SUMPRODUCT(('İş Planı'!$C$5:$C$204<>"")*('İş Planı'!$H$5:$H$204<>"")*('İş Planı'!$I$5:$I$204<>"")*('İş Planı'!$H$5:$H$204<=EOMONTH(I11,0))*('İş Planı'!$L$5:$L$204>=I11)) | L11: 1 | M11: =IFERROR(IF(LARGE($R$5:$R$204,L11)<0.5,"",INDEX('İş Planı'!$C$5:$C$204,MATCH(LARGE($R$5:$R$204,L11),$R$5:$R$204,0))),"") | N11: =IFERROR(IF(LARGE($R$5:$R$204,L11)<0.5,0,INT(LARGE($R$5:$R$204,L11))),0) | R11: =IF('İş Planı'!$C11="","",IF('İş Planı'!$N11="Tamamlandı",N('İş Planı'!$K11),MAX(N('İş Planı'!$K11),IF(AND('İş Planı'!$I11<>"",'İş Planı'!$I11<TODAY()),TODAY()-'İş Planı'!$I11,0)))+ROW()/1000000) | W11: =IFERROR(INDEX(Listeler!$B$4:$B$43,SMALL($BB$4:$BB$43,22-ROW())),"") | X11: =IF($W11="","",COUNTIFS('İş Planı'!$B$5:$B$204,$W11,'İş Planı'!$N$5:$N$204,"Tamamlandı")) | Y11: =IF($W11="","",COUNTIFS('İş Planı'!$B$5:$B$204,$W11,'İş Planı'!$N$5:$N$204,"Devam Ediyor")) | Z11: =IF($W11="","",COUNTIFS('İş Planı'!$B$5:$B$204,$W11,'İş Planı'!$N$5:$N$204,"Gecikmiş")) | AB11: 46092 | AC11: =SUMPRODUCT(('İş Planı'!$C$5:$C$204<>"")*('İş Planı'!$L$5:$L$204<>"")*('İş Planı'!$L$5:$L$204<=AB11)) | AD11: =SUMPRODUCT(('İş Planı'!$C$5:$C$204<>"")*('İş Planı'!$L$5:$L$204<>"")*('İş Planı'!$L$5:$L$204<=AB11)*('İş Planı'!$N$5:$N$204="Tamamlandı")) | AF11: Eki | AG11: 46326 | AH11: =SUMPRODUCT(('İş Planı'!$C$5:$C$204<>"")*('İş Planı'!$L$5:$L$204<>"")*('İş Planı'!$L$5:$L$204<=AG11)) | AI11: =SUMPRODUCT(('İş Planı'!$C$5:$C$204<>"")*('İş Planı'!$L$5:$L$204<>"")*('İş Planı'!$L$5:$L$204<=AG11)*('İş Planı'!$N$5:$N$204="Tamamlandı")) | AK11: =IFERROR(INDEX(Listeler!$D$4:$D$43,SMALL($BD$4:$BD$43,22-ROW())),"") | AL11: =IF($AK11="","",COUNTIFS('İş Planı'!$D$5:$D$204,$AK11,'İş Planı'!$N$5:$N$204,"Planlanan")+COUNTIFS('İş Planı'!$E$5:$E$204,$AK11,'İş Planı'!$N$5:$N$204,"Planlanan")+COUNTIFS('İş Planı'!$F$5:$F$204,$AK11,'İş Planı'!$N$5:$N$204,"Planlanan")+COUNTIFS('İş Planı'!$D$5:$D$204,$AK11,'İş Planı'!$N$5:$N$204,"Devam Ediyor")+COUNTIFS('İş Planı'!$E$5:$E$204,$AK11,'İş Planı'!$N$5:$N$204,"Devam Ediyor")+COUNTIFS('İş Planı'!$F$5:$F$204,$AK11,'İş Planı'!$N$5:$N$204,"Devam Ediyor")) | AM11: =IF($AK11="","",COUNTIFS('İş Planı'!$D$5:$D$204,$AK11,'İş Planı'!$N$5:$N$204,"Gecikmiş")+COUNTIFS('İş Planı'!$E$5:$E$204,$AK11,'İş Planı'!$N$5:$N$204,"Gecikmiş")+COUNTIFS('İş Planı'!$F$5:$F$204,$AK11,'İş Planı'!$N$5:$N$204,"Gecikmiş")) | BB11: =IF(Listeler!$B11="","",IF(COUNTIF('İş Planı'!$B$5:$B$204,Listeler!$B11)=0,"",ROW()-3)) | BD11: =IF(Listeler!$D11="","",IF(COUNTIF('İş Planı'!$D$5:$D$204,Listeler!$D11)+COUNTIF('İş Planı'!$E$5:$E$204,Listeler!$D11)+COUNTIF('İş Planı'!$F$5:$F$204,Listeler!$D11)=0,"",ROW()-3))
H12: Kas | I12: 46327 | J12: =SUMPRODUCT(('İş Planı'!$C$5:$C$204<>"")*('İş Planı'!$H$5:$H$204<>"")*('İş Planı'!$I$5:$I$204<>"")*('İş Planı'!$H$5:$H$204<=EOMONTH(I12,0))*('İş Planı'!$L$5:$L$204>=I12)) | R12: =IF('İş Planı'!$C12="","",IF('İş Planı'!$N12="Tamamlandı",N('İş Planı'!$K12),MAX(N('İş Planı'!$K12),IF(AND('İş Planı'!$I12<>"",'İş Planı'!$I12<TODAY()),TODAY()-'İş Planı'!$I12,0)))+ROW()/1000000) | W12: =IFERROR(INDEX(Listeler!$B$4:$B$43,SMALL($BB$4:$BB$43,22-ROW())),"") | X12: =IF($W12="","",COUNTIFS('İş Planı'!$B$5:$B$204,$W12,'İş Planı'!$N$5:$N$204,"Tamamlandı")) | Y12: =IF($W12="","",COUNTIFS('İş Planı'!$B$5:$B$204,$W12,'İş Planı'!$N$5:$N$204,"Devam Ediyor")) | Z12: =IF($W12="","",COUNTIFS('İş Planı'!$B$5:$B$204,$W12,'İş Planı'!$N$5:$N$204,"Gecikmiş")) | AB12: 46099 | AC12: =SUMPRODUCT(('İş Planı'!$C$5:$C$204<>"")*('İş Planı'!$L$5:$L$204<>"")*('İş Planı'!$L$5:$L$204<=AB12)) | AD12: =SUMPRODUCT(('İş Planı'!$C$5:$C$204<>"")*('İş Planı'!$L$5:$L$204<>"")*('İş Planı'!$L$5:$L$204<=AB12)*('İş Planı'!$N$5:$N$204="Tamamlandı")) | AF12: Kas | AG12: 46356 | AH12: =SUMPRODUCT(('İş Planı'!$C$5:$C$204<>"")*('İş Planı'!$L$5:$L$204<>"")*('İş Planı'!$L$5:$L$204<=AG12)) | AI12: =SUMPRODUCT(('İş Planı'!$C$5:$C$204<>"")*('İş Planı'!$L$5:$L$204<>"")*('İş Planı'!$L$5:$L$204<=AG12)*('İş Planı'!$N$5:$N$204="Tamamlandı")) | AK12: =IFERROR(INDEX(Listeler!$D$4:$D$43,SMALL($BD$4:$BD$43,22-ROW())),"") | AL12: =IF($AK12="","",COUNTIFS('İş Planı'!$D$5:$D$204,$AK12,'İş Planı'!$N$5:$N$204,"Planlanan")+COUNTIFS('İş Planı'!$E$5:$E$204,$AK12,'İş Planı'!$N$5:$N$204,"Planlanan")+COUNTIFS('İş Planı'!$F$5:$F$204,$AK12,'İş Planı'!$N$5:$N$204,"Planlanan")+COUNTIFS('İş Planı'!$D$5:$D$204,$AK12,'İş Planı'!$N$5:$N$204,"Devam Ediyor")+COUNTIFS('İş Planı'!$E$5:$E$204,$AK12,'İş Planı'!$N$5:$N$204,"Devam Ediyor")+COUNTIFS('İş Planı'!$F$5:$F$204,$AK12,'İş Planı'!$N$5:$N$204,"Devam Ediyor")) | AM12: =IF($AK12="","",COUNTIFS('İş Planı'!$D$5:$D$204,$AK12,'İş Planı'!$N$5:$N$204,"Gecikmiş")+COUNTIFS('İş Planı'!$E$5:$E$204,$AK12,'İş Planı'!$N$5:$N$204,"Gecikmiş")+COUNTIFS('İş Planı'!$F$5:$F$204,$AK12,'İş Planı'!$N$5:$N$204,"Gecikmiş")) | BB12: =IF(Listeler!$B12="","",IF(COUNTIF('İş Planı'!$B$5:$B$204,Listeler!$B12)=0,"",ROW()-3)) | BD12: =IF(Listeler!$D12="","",IF(COUNTIF('İş Planı'!$D$5:$D$204,Listeler!$D12)+COUNTIF('İş Planı'!$E$5:$E$204,Listeler!$D12)+COUNTIF('İş Planı'!$F$5:$F$204,Listeler!$D12)=0,"",ROW()-3))
H13: Ara | I13: 46357 | J13: =SUMPRODUCT(('İş Planı'!$C$5:$C$204<>"")*('İş Planı'!$H$5:$H$204<>"")*('İş Planı'!$I$5:$I$204<>"")*('İş Planı'!$H$5:$H$204<=EOMONTH(I13,0))*('İş Planı'!$L$5:$L$204>=I13)) | R13: =IF('İş Planı'!$C13="","",IF('İş Planı'!$N13="Tamamlandı",N('İş Planı'!$K13),MAX(N('İş Planı'!$K13),IF(AND('İş Planı'!$I13<>"",'İş Planı'!$I13<TODAY()),TODAY()-'İş Planı'!$I13,0)))+ROW()/1000000) | W13: =IFERROR(INDEX(Listeler!$B$4:$B$43,SMALL($BB$4:$BB$43,22-ROW())),"") | X13: =IF($W13="","",COUNTIFS('İş Planı'!$B$5:$B$204,$W13,'İş Planı'!$N$5:$N$204,"Tamamlandı")) | Y13: =IF($W13="","",COUNTIFS('İş Planı'!$B$5:$B$204,$W13,'İş Planı'!$N$5:$N$204,"Devam Ediyor")) | Z13: =IF($W13="","",COUNTIFS('İş Planı'!$B$5:$B$204,$W13,'İş Planı'!$N$5:$N$204,"Gecikmiş")) | AB13: 46106 | AC13: =SUMPRODUCT(('İş Planı'!$C$5:$C$204<>"")*('İş Planı'!$L$5:$L$204<>"")*('İş Planı'!$L$5:$L$204<=AB13)) | AD13: =SUMPRODUCT(('İş Planı'!$C$5:$C$204<>"")*('İş Planı'!$L$5:$L$204<>"")*('İş Planı'!$L$5:$L$204<=AB13)*('İş Planı'!$N$5:$N$204="Tamamlandı")) | AF13: Ara | AG13: 46387 | AH13: =SUMPRODUCT(('İş Planı'!$C$5:$C$204<>"")*('İş Planı'!$L$5:$L$204<>"")*('İş Planı'!$L$5:$L$204<=AG13)) | AI13: =SUMPRODUCT(('İş Planı'!$C$5:$C$204<>"")*('İş Planı'!$L$5:$L$204<>"")*('İş Planı'!$L$5:$L$204<=AG13)*('İş Planı'!$N$5:$N$204="Tamamlandı")) | AK13: =IFERROR(INDEX(Listeler!$D$4:$D$43,SMALL($BD$4:$BD$43,22-ROW())),"") | AL13: =IF($AK13="","",COUNTIFS('İş Planı'!$D$5:$D$204,$AK13,'İş Planı'!$N$5:$N$204,"Planlanan")+COUNTIFS('İş Planı'!$E$5:$E$204,$AK13,'İş Planı'!$N$5:$N$204,"Planlanan")+COUNTIFS('İş Planı'!$F$5:$F$204,$AK13,'İş Planı'!$N$5:$N$204,"Planlanan")+COUNTIFS('İş Planı'!$D$5:$D$204,$AK13,'İş Planı'!$N$5:$N$204,"Devam Ediyor")+COUNTIFS('İş Planı'!$E$5:$E$204,$AK13,'İş Planı'!$N$5:$N$204,"Devam Ediyor")+COUNTIFS('İş Planı'!$F$5:$F$204,$AK13,'İş Planı'!$N$5:$N$204,"Devam Ediyor")) | AM13: =IF($AK13="","",COUNTIFS('İş Planı'!$D$5:$D$204,$AK13,'İş Planı'!$N$5:$N$204,"Gecikmiş")+COUNTIFS('İş Planı'!$E$5:$E$204,$AK13,'İş Planı'!$N$5:$N$204,"Gecikmiş")+COUNTIFS('İş Planı'!$F$5:$F$204,$AK13,'İş Planı'!$N$5:$N$204,"Gecikmiş")) | BB13: =IF(Listeler!$B13="","",IF(COUNTIF('İş Planı'!$B$5:$B$204,Listeler!$B13)=0,"",ROW()-3)) | BD13: =IF(Listeler!$D13="","",IF(COUNTIF('İş Planı'!$D$5:$D$204,Listeler!$D13)+COUNTIF('İş Planı'!$E$5:$E$204,Listeler!$D13)+COUNTIF('İş Planı'!$F$5:$F$204,Listeler!$D13)=0,"",ROW()-3))
R14: =IF('İş Planı'!$C14="","",IF('İş Planı'!$N14="Tamamlandı",N('İş Planı'!$K14),MAX(N('İş Planı'!$K14),IF(AND('İş Planı'!$I14<>"",'İş Planı'!$I14<TODAY()),TODAY()-'İş Planı'!$I14,0)))+ROW()/1000000) | W14: =IFERROR(INDEX(Listeler!$B$4:$B$43,SMALL($BB$4:$BB$43,22-ROW())),"") | X14: =IF($W14="","",COUNTIFS('İş Planı'!$B$5:$B$204,$W14,'İş Planı'!$N$5:$N$204,"Tamamlandı")) | Y14: =IF($W14="","",COUNTIFS('İş Planı'!$B$5:$B$204,$W14,'İş Planı'!$N$5:$N$204,"Devam Ediyor")) | Z14: =IF($W14="","",COUNTIFS('İş Planı'!$B$5:$B$204,$W14,'İş Planı'!$N$5:$N$204,"Gecikmiş")) | AB14: 46113 | AC14: =SUMPRODUCT(('İş Planı'!$C$5:$C$204<>"")*('İş Planı'!$L$5:$L$204<>"")*('İş Planı'!$L$5:$L$204<=AB14)) | AD14: =SUMPRODUCT(('İş Planı'!$C$5:$C$204<>"")*('İş Planı'!$L$5:$L$204<>"")*('İş Planı'!$L$5:$L$204<=AB14)*('İş Planı'!$N$5:$N$204="Tamamlandı")) | AK14: =IFERROR(INDEX(Listeler!$D$4:$D$43,SMALL($BD$4:$BD$43,22-ROW())),"") | AL14: =IF($AK14="","",COUNTIFS('İş Planı'!$D$5:$D$204,$AK14,'İş Planı'!$N$5:$N$204,"Planlanan")+COUNTIFS('İş Planı'!$E$5:$E$204,$AK14,'İş Planı'!$N$5:$N$204,"Planlanan")+COUNTIFS('İş Planı'!$F$5:$F$204,$AK14,'İş Planı'!$N$5:$N$204,"Planlanan")+COUNTIFS('İş Planı'!$D$5:$D$204,$AK14,'İş Planı'!$N$5:$N$204,"Devam Ediyor")+COUNTIFS('İş Planı'!$E$5:$E$204,$AK14,'İş Planı'!$N$5:$N$204,"Devam Ediyor")+COUNTIFS('İş Planı'!$F$5:$F$204,$AK14,'İş Planı'!$N$5:$N$204,"Devam Ediyor")) | AM14: =IF($AK14="","",COUNTIFS('İş Planı'!$D$5:$D$204,$AK14,'İş Planı'!$N$5:$N$204,"Gecikmiş")+COUNTIFS('İş Planı'!$E$5:$E$204,$AK14,'İş Planı'!$N$5:$N$204,"Gecikmiş")+COUNTIFS('İş Planı'!$F$5:$F$204,$AK14,'İş Planı'!$N$5:$N$204,"Gecikmiş")) | BB14: =IF(Listeler!$B14="","",IF(COUNTIF('İş Planı'!$B$5:$B$204,Listeler!$B14)=0,"",ROW()-3)) | BD14: =IF(Listeler!$D14="","",IF(COUNTIF('İş Planı'!$D$5:$D$204,Listeler!$D14)+COUNTIF('İş Planı'!$E$5:$E$204,Listeler!$D14)+COUNTIF('İş Planı'!$F$5:$F$204,Listeler!$D14)=0,"",ROW()-3))
R15: =IF('İş Planı'!$C15="","",IF('İş Planı'!$N15="Tamamlandı",N('İş Planı'!$K15),MAX(N('İş Planı'!$K15),IF(AND('İş Planı'!$I15<>"",'İş Planı'!$I15<TODAY()),TODAY()-'İş Planı'!$I15,0)))+ROW()/1000000) | W15: =IFERROR(INDEX(Listeler!$B$4:$B$43,SMALL($BB$4:$BB$43,22-ROW())),"") | X15: =IF($W15="","",COUNTIFS('İş Planı'!$B$5:$B$204,$W15,'İş Planı'!$N$5:$N$204,"Tamamlandı")) | Y15: =IF($W15="","",COUNTIFS('İş Planı'!$B$5:$B$204,$W15,'İş Planı'!$N$5:$N$204,"Devam Ediyor")) | Z15: =IF($W15="","",COUNTIFS('İş Planı'!$B$5:$B$204,$W15,'İş Planı'!$N$5:$N$204,"Gecikmiş")) | AB15: 46120 | AC15: =SUMPRODUCT(('İş Planı'!$C$5:$C$204<>"")*('İş Planı'!$L$5:$L$204<>"")*('İş Planı'!$L$5:$L$204<=AB15)) | AD15: =SUMPRODUCT(('İş Planı'!$C$5:$C$204<>"")*('İş Planı'!$L$5:$L$204<>"")*('İş Planı'!$L$5:$L$204<=AB15)*('İş Planı'!$N$5:$N$204="Tamamlandı")) | AK15: =IFERROR(INDEX(Listeler!$D$4:$D$43,SMALL($BD$4:$BD$43,22-ROW())),"") | AL15: =IF($AK15="","",COUNTIFS('İş Planı'!$D$5:$D$204,$AK15,'İş Planı'!$N$5:$N$204,"Planlanan")+COUNTIFS('İş Planı'!$E$5:$E$204,$AK15,'İş Planı'!$N$5:$N$204,"Planlanan")+COUNTIFS('İş Planı'!$F$5:$F$204,$AK15,'İş Planı'!$N$5:$N$204,"Planlanan")+COUNTIFS('İş Planı'!$D$5:$D$204,$AK15,'İş Planı'!$N$5:$N$204,"Devam Ediyor")+COUNTIFS('İş Planı'!$E$5:$E$204,$AK15,'İş Planı'!$N$5:$N$204,"Devam Ediyor")+COUNTIFS('İş Planı'!$F$5:$F$204,$AK15,'İş Planı'!$N$5:$N$204,"Devam Ediyor")) | AM15: =IF($AK15="","",COUNTIFS('İş Planı'!$D$5:$D$204,$AK15,'İş Planı'!$N$5:$N$204,"Gecikmiş")+COUNTIFS('İş Planı'!$E$5:$E$204,$AK15,'İş Planı'!$N$5:$N$204,"Gecikmiş")+COUNTIFS('İş Planı'!$F$5:$F$204,$AK15,'İş Planı'!$N$5:$N$204,"Gecikmiş")) | BB15: =IF(Listeler!$B15="","",IF(COUNTIF('İş Planı'!$B$5:$B$204,Listeler!$B15)=0,"",ROW()-3)) | BD15: =IF(Listeler!$D15="","",IF(COUNTIF('İş Planı'!$D$5:$D$204,Listeler!$D15)+COUNTIF('İş Planı'!$E$5:$E$204,Listeler!$D15)+COUNTIF('İş Planı'!$F$5:$F$204,Listeler!$D15)=0,"",ROW()-3))
R16: =IF('İş Planı'!$C16="","",IF('İş Planı'!$N16="Tamamlandı",N('İş Planı'!$K16),MAX(N('İş Planı'!$K16),IF(AND('İş Planı'!$I16<>"",'İş Planı'!$I16<TODAY()),TODAY()-'İş Planı'!$I16,0)))+ROW()/1000000) | W16: =IFERROR(INDEX(Listeler!$B$4:$B$43,SMALL($BB$4:$BB$43,22-ROW())),"") | X16: =IF($W16="","",COUNTIFS('İş Planı'!$B$5:$B$204,$W16,'İş Planı'!$N$5:$N$204,"Tamamlandı")) | Y16: =IF($W16="","",COUNTIFS('İş Planı'!$B$5:$B$204,$W16,'İş Planı'!$N$5:$N$204,"Devam Ediyor")) | Z16: =IF($W16="","",COUNTIFS('İş Planı'!$B$5:$B$204,$W16,'İş Planı'!$N$5:$N$204,"Gecikmiş")) | AB16: 46127 | AC16: =SUMPRODUCT(('İş Planı'!$C$5:$C$204<>"")*('İş Planı'!$L$5:$L$204<>"")*('İş Planı'!$L$5:$L$204<=AB16)) | AD16: =SUMPRODUCT(('İş Planı'!$C$5:$C$204<>"")*('İş Planı'!$L$5:$L$204<>"")*('İş Planı'!$L$5:$L$204<=AB16)*('İş Planı'!$N$5:$N$204="Tamamlandı")) | AK16: =IFERROR(INDEX(Listeler!$D$4:$D$43,SMALL($BD$4:$BD$43,22-ROW())),"") | AL16: =IF($AK16="","",COUNTIFS('İş Planı'!$D$5:$D$204,$AK16,'İş Planı'!$N$5:$N$204,"Planlanan")+COUNTIFS('İş Planı'!$E$5:$E$204,$AK16,'İş Planı'!$N$5:$N$204,"Planlanan")+COUNTIFS('İş Planı'!$F$5:$F$204,$AK16,'İş Planı'!$N$5:$N$204,"Planlanan")+COUNTIFS('İş Planı'!$D$5:$D$204,$AK16,'İş Planı'!$N$5:$N$204,"Devam Ediyor")+COUNTIFS('İş Planı'!$E$5:$E$204,$AK16,'İş Planı'!$N$5:$N$204,"Devam Ediyor")+COUNTIFS('İş Planı'!$F$5:$F$204,$AK16,'İş Planı'!$N$5:$N$204,"Devam Ediyor")) | AM16: =IF($AK16="","",COUNTIFS('İş Planı'!$D$5:$D$204,$AK16,'İş Planı'!$N$5:$N$204,"Gecikmiş")+COUNTIFS('İş Planı'!$E$5:$E$204,$AK16,'İş Planı'!$N$5:$N$204,"Gecikmiş")+COUNTIFS('İş Planı'!$F$5:$F$204,$AK16,'İş Planı'!$N$5:$N$204,"Gecikmiş")) | BB16: =IF(Listeler!$B16="","",IF(COUNTIF('İş Planı'!$B$5:$B$204,Listeler!$B16)=0,"",ROW()-3)) | BD16: =IF(Listeler!$D16="","",IF(COUNTIF('İş Planı'!$D$5:$D$204,Listeler!$D16)+COUNTIF('İş Planı'!$E$5:$E$204,Listeler!$D16)+COUNTIF('İş Planı'!$F$5:$F$204,Listeler!$D16)=0,"",ROW()-3))
R17: =IF('İş Planı'!$C17="","",IF('İş Planı'!$N17="Tamamlandı",N('İş Planı'!$K17),MAX(N('İş Planı'!$K17),IF(AND('İş Planı'!$I17<>"",'İş Planı'!$I17<TODAY()),TODAY()-'İş Planı'!$I17,0)))+ROW()/1000000) | W17: =IFERROR(INDEX(Listeler!$B$4:$B$43,SMALL($BB$4:$BB$43,22-ROW())),"") | X17: =IF($W17="","",COUNTIFS('İş Planı'!$B$5:$B$204,$W17,'İş Planı'!$N$5:$N$204,"Tamamlandı")) | Y17: =IF($W17="","",COUNTIFS('İş Planı'!$B$5:$B$204,$W17,'İş Planı'!$N$5:$N$204,"Devam Ediyor")) | Z17: =IF($W17="","",COUNTIFS('İş Planı'!$B$5:$B$204,$W17,'İş Planı'!$N$5:$N$204,"Gecikmiş")) | AB17: 46134 | AC17: =SUMPRODUCT(('İş Planı'!$C$5:$C$204<>"")*('İş Planı'!$L$5:$L$204<>"")*('İş Planı'!$L$5:$L$204<=AB17)) | AD17: =SUMPRODUCT(('İş Planı'!$C$5:$C$204<>"")*('İş Planı'!$L$5:$L$204<>"")*('İş Planı'!$L$5:$L$204<=AB17)*('İş Planı'!$N$5:$N$204="Tamamlandı")) | AK17: =IFERROR(INDEX(Listeler!$D$4:$D$43,SMALL($BD$4:$BD$43,22-ROW())),"") | AL17: =IF($AK17="","",COUNTIFS('İş Planı'!$D$5:$D$204,$AK17,'İş Planı'!$N$5:$N$204,"Planlanan")+COUNTIFS('İş Planı'!$E$5:$E$204,$AK17,'İş Planı'!$N$5:$N$204,"Planlanan")+COUNTIFS('İş Planı'!$F$5:$F$204,$AK17,'İş Planı'!$N$5:$N$204,"Planlanan")+COUNTIFS('İş Planı'!$D$5:$D$204,$AK17,'İş Planı'!$N$5:$N$204,"Devam Ediyor")+COUNTIFS('İş Planı'!$E$5:$E$204,$AK17,'İş Planı'!$N$5:$N$204,"Devam Ediyor")+COUNTIFS('İş Planı'!$F$5:$F$204,$AK17,'İş Planı'!$N$5:$N$204,"Devam Ediyor")) | AM17: =IF($AK17="","",COUNTIFS('İş Planı'!$D$5:$D$204,$AK17,'İş Planı'!$N$5:$N$204,"Gecikmiş")+COUNTIFS('İş Planı'!$E$5:$E$204,$AK17,'İş Planı'!$N$5:$N$204,"Gecikmiş")+COUNTIFS('İş Planı'!$F$5:$F$204,$AK17,'İş Planı'!$N$5:$N$204,"Gecikmiş")) | BB17: =IF(Listeler!$B17="","",IF(COUNTIF('İş Planı'!$B$5:$B$204,Listeler!$B17)=0,"",ROW()-3)) | BD17: =IF(Listeler!$D17="","",IF(COUNTIF('İş Planı'!$D$5:$D$204,Listeler!$D17)+COUNTIF('İş Planı'!$E$5:$E$204,Listeler!$D17)+COUNTIF('İş Planı'!$F$5:$F$204,Listeler!$D17)=0,"",ROW()-3))
R18: =IF('İş Planı'!$C18="","",IF('İş Planı'!$N18="Tamamlandı",N('İş Planı'!$K18),MAX(N('İş Planı'!$K18),IF(AND('İş Planı'!$I18<>"",'İş Planı'!$I18<TODAY()),TODAY()-'İş Planı'!$I18,0)))+ROW()/1000000) | W18: =IFERROR(INDEX(Listeler!$B$4:$B$43,SMALL($BB$4:$BB$43,22-ROW())),"") | X18: =IF($W18="","",COUNTIFS('İş Planı'!$B$5:$B$204,$W18,'İş Planı'!$N$5:$N$204,"Tamamlandı")) | Y18: =IF($W18="","",COUNTIFS('İş Planı'!$B$5:$B$204,$W18,'İş Planı'!$N$5:$N$204,"Devam Ediyor")) | Z18: =IF($W18="","",COUNTIFS('İş Planı'!$B$5:$B$204,$W18,'İş Planı'!$N$5:$N$204,"Gecikmiş")) | AB18: 46141 | AC18: =SUMPRODUCT(('İş Planı'!$C$5:$C$204<>"")*('İş Planı'!$L$5:$L$204<>"")*('İş Planı'!$L$5:$L$204<=AB18)) | AD18: =SUMPRODUCT(('İş Planı'!$C$5:$C$204<>"")*('İş Planı'!$L$5:$L$204<>"")*('İş Planı'!$L$5:$L$204<=AB18)*('İş Planı'!$N$5:$N$204="Tamamlandı")) | AK18: =IFERROR(INDEX(Listeler!$D$4:$D$43,SMALL($BD$4:$BD$43,22-ROW())),"") | AL18: =IF($AK18="","",COUNTIFS('İş Planı'!$D$5:$D$204,$AK18,'İş Planı'!$N$5:$N$204,"Planlanan")+COUNTIFS('İş Planı'!$E$5:$E$204,$AK18,'İş Planı'!$N$5:$N$204,"Planlanan")+COUNTIFS('İş Planı'!$F$5:$F$204,$AK18,'İş Planı'!$N$5:$N$204,"Planlanan")+COUNTIFS('İş Planı'!$D$5:$D$204,$AK18,'İş Planı'!$N$5:$N$204,"Devam Ediyor")+COUNTIFS('İş Planı'!$E$5:$E$204,$AK18,'İş Planı'!$N$5:$N$204,"Devam Ediyor")+COUNTIFS('İş Planı'!$F$5:$F$204,$AK18,'İş Planı'!$N$5:$N$204,"Devam Ediyor")) | AM18: =IF($AK18="","",COUNTIFS('İş Planı'!$D$5:$D$204,$AK18,'İş Planı'!$N$5:$N$204,"Gecikmiş")+COUNTIFS('İş Planı'!$E$5:$E$204,$AK18,'İş Planı'!$N$5:$N$204,"Gecikmiş")+COUNTIFS('İş Planı'!$F$5:$F$204,$AK18,'İş Planı'!$N$5:$N$204,"Gecikmiş")) | BB18: =IF(Listeler!$B18="","",IF(COUNTIF('İş Planı'!$B$5:$B$204,Listeler!$B18)=0,"",ROW()-3)) | BD18: =IF(Listeler!$D18="","",IF(COUNTIF('İş Planı'!$D$5:$D$204,Listeler!$D18)+COUNTIF('İş Planı'!$E$5:$E$204,Listeler!$D18)+COUNTIF('İş Planı'!$F$5:$F$204,Listeler!$D18)=0,"",ROW()-3))
R19: =IF('İş Planı'!$C19="","",IF('İş Planı'!$N19="Tamamlandı",N('İş Planı'!$K19),MAX(N('İş Planı'!$K19),IF(AND('İş Planı'!$I19<>"",'İş Planı'!$I19<TODAY()),TODAY()-'İş Planı'!$I19,0)))+ROW()/1000000) | W19: =IFERROR(INDEX(Listeler!$B$4:$B$43,SMALL($BB$4:$BB$43,22-ROW())),"") | X19: =IF($W19="","",COUNTIFS('İş Planı'!$B$5:$B$204,$W19,'İş Planı'!$N$5:$N$204,"Tamamlandı")) | Y19: =IF($W19="","",COUNTIFS('İş Planı'!$B$5:$B$204,$W19,'İş Planı'!$N$5:$N$204,"Devam Ediyor")) | Z19: =IF($W19="","",COUNTIFS('İş Planı'!$B$5:$B$204,$W19,'İş Planı'!$N$5:$N$204,"Gecikmiş")) | AB19: 46148 | AC19: =SUMPRODUCT(('İş Planı'!$C$5:$C$204<>"")*('İş Planı'!$L$5:$L$204<>"")*('İş Planı'!$L$5:$L$204<=AB19)) | AD19: =SUMPRODUCT(('İş Planı'!$C$5:$C$204<>"")*('İş Planı'!$L$5:$L$204<>"")*('İş Planı'!$L$5:$L$204<=AB19)*('İş Planı'!$N$5:$N$204="Tamamlandı")) | AK19: =IFERROR(INDEX(Listeler!$D$4:$D$43,SMALL($BD$4:$BD$43,22-ROW())),"") | AL19: =IF($AK19="","",COUNTIFS('İş Planı'!$D$5:$D$204,$AK19,'İş Planı'!$N$5:$N$204,"Planlanan")+COUNTIFS('İş Planı'!$E$5:$E$204,$AK19,'İş Planı'!$N$5:$N$204,"Planlanan")+COUNTIFS('İş Planı'!$F$5:$F$204,$AK19,'İş Planı'!$N$5:$N$204,"Planlanan")+COUNTIFS('İş Planı'!$D$5:$D$204,$AK19,'İş Planı'!$N$5:$N$204,"Devam Ediyor")+COUNTIFS('İş Planı'!$E$5:$E$204,$AK19,'İş Planı'!$N$5:$N$204,"Devam Ediyor")+COUNTIFS('İş Planı'!$F$5:$F$204,$AK19,'İş Planı'!$N$5:$N$204,"Devam Ediyor")) | AM19: =IF($AK19="","",COUNTIFS('İş Planı'!$D$5:$D$204,$AK19,'İş Planı'!$N$5:$N$204,"Gecikmiş")+COUNTIFS('İş Planı'!$E$5:$E$204,$AK19,'İş Planı'!$N$5:$N$204,"Gecikmiş")+COUNTIFS('İş Planı'!$F$5:$F$204,$AK19,'İş Planı'!$N$5:$N$204,"Gecikmiş")) | BB19: =IF(Listeler!$B19="","",IF(COUNTIF('İş Planı'!$B$5:$B$204,Listeler!$B19)=0,"",ROW()-3)) | BD19: =IF(Listeler!$D19="","",IF(COUNTIF('İş Planı'!$D$5:$D$204,Listeler!$D19)+COUNTIF('İş Planı'!$E$5:$E$204,Listeler!$D19)+COUNTIF('İş Planı'!$F$5:$F$204,Listeler!$D19)=0,"",ROW()-3))
R20: =IF('İş Planı'!$C20="","",IF('İş Planı'!$N20="Tamamlandı",N('İş Planı'!$K20),MAX(N('İş Planı'!$K20),IF(AND('İş Planı'!$I20<>"",'İş Planı'!$I20<TODAY()),TODAY()-'İş Planı'!$I20,0)))+ROW()/1000000) | W20: =IFERROR(INDEX(Listeler!$B$4:$B$43,SMALL($BB$4:$BB$43,22-ROW())),"") | X20: =IF($W20="","",COUNTIFS('İş Planı'!$B$5:$B$204,$W20,'İş Planı'!$N$5:$N$204,"Tamamlandı")) | Y20: =IF($W20="","",COUNTIFS('İş Planı'!$B$5:$B$204,$W20,'İş Planı'!$N$5:$N$204,"Devam Ediyor")) | Z20: =IF($W20="","",COUNTIFS('İş Planı'!$B$5:$B$204,$W20,'İş Planı'!$N$5:$N$204,"Gecikmiş")) | AB20: 46155 | AC20: =SUMPRODUCT(('İş Planı'!$C$5:$C$204<>"")*('İş Planı'!$L$5:$L$204<>"")*('İş Planı'!$L$5:$L$204<=AB20)) | AD20: =SUMPRODUCT(('İş Planı'!$C$5:$C$204<>"")*('İş Planı'!$L$5:$L$204<>"")*('İş Planı'!$L$5:$L$204<=AB20)*('İş Planı'!$N$5:$N$204="Tamamlandı")) | AK20: =IFERROR(INDEX(Listeler!$D$4:$D$43,SMALL($BD$4:$BD$43,22-ROW())),"") | AL20: =IF($AK20="","",COUNTIFS('İş Planı'!$D$5:$D$204,$AK20,'İş Planı'!$N$5:$N$204,"Planlanan")+COUNTIFS('İş Planı'!$E$5:$E$204,$AK20,'İş Planı'!$N$5:$N$204,"Planlanan")+COUNTIFS('İş Planı'!$F$5:$F$204,$AK20,'İş Planı'!$N$5:$N$204,"Planlanan")+COUNTIFS('İş Planı'!$D$5:$D$204,$AK20,'İş Planı'!$N$5:$N$204,"Devam Ediyor")+COUNTIFS('İş Planı'!$E$5:$E$204,$AK20,'İş Planı'!$N$5:$N$204,"Devam Ediyor")+COUNTIFS('İş Planı'!$F$5:$F$204,$AK20,'İş Planı'!$N$5:$N$204,"Devam Ediyor")) | AM20: =IF($AK20="","",COUNTIFS('İş Planı'!$D$5:$D$204,$AK20,'İş Planı'!$N$5:$N$204,"Gecikmiş")+COUNTIFS('İş Planı'!$E$5:$E$204,$AK20,'İş Planı'!$N$5:$N$204,"Gecikmiş")+COUNTIFS('İş Planı'!$F$5:$F$204,$AK20,'İş Planı'!$N$5:$N$204,"Gecikmiş")) | BB20: =IF(Listeler!$B20="","",IF(COUNTIF('İş Planı'!$B$5:$B$204,Listeler!$B20)=0,"",ROW()-3)) | BD20: =IF(Listeler!$D20="","",IF(COUNTIF('İş Planı'!$D$5:$D$204,Listeler!$D20)+COUNTIF('İş Planı'!$E$5:$E$204,Listeler!$D20)+COUNTIF('İş Planı'!$F$5:$F$204,Listeler!$D20)=0,"",ROW()-3))
R21: =IF('İş Planı'!$C21="","",IF('İş Planı'!$N21="Tamamlandı",N('İş Planı'!$K21),MAX(N('İş Planı'!$K21),IF(AND('İş Planı'!$I21<>"",'İş Planı'!$I21<TODAY()),TODAY()-'İş Planı'!$I21,0)))+ROW()/1000000) | W21: =IFERROR(INDEX(Listeler!$B$4:$B$43,SMALL($BB$4:$BB$43,22-ROW())),"") | X21: =IF($W21="","",COUNTIFS('İş Planı'!$B$5:$B$204,$W21,'İş Planı'!$N$5:$N$204,"Tamamlandı")) | Y21: =IF($W21="","",COUNTIFS('İş Planı'!$B$5:$B$204,$W21,'İş Planı'!$N$5:$N$204,"Devam Ediyor")) | Z21: =IF($W21="","",COUNTIFS('İş Planı'!$B$5:$B$204,$W21,'İş Planı'!$N$5:$N$204,"Gecikmiş")) | AB21: 46162 | AC21: =SUMPRODUCT(('İş Planı'!$C$5:$C$204<>"")*('İş Planı'!$L$5:$L$204<>"")*('İş Planı'!$L$5:$L$204<=AB21)) | AD21: =SUMPRODUCT(('İş Planı'!$C$5:$C$204<>"")*('İş Planı'!$L$5:$L$204<>"")*('İş Planı'!$L$5:$L$204<=AB21)*('İş Planı'!$N$5:$N$204="Tamamlandı")) | AK21: =IFERROR(INDEX(Listeler!$D$4:$D$43,SMALL($BD$4:$BD$43,22-ROW())),"") | AL21: =IF($AK21="","",COUNTIFS('İş Planı'!$D$5:$D$204,$AK21,'İş Planı'!$N$5:$N$204,"Planlanan")+COUNTIFS('İş Planı'!$E$5:$E$204,$AK21,'İş Planı'!$N$5:$N$204,"Planlanan")+COUNTIFS('İş Planı'!$F$5:$F$204,$AK21,'İş Planı'!$N$5:$N$204,"Planlanan")+COUNTIFS('İş Planı'!$D$5:$D$204,$AK21,'İş Planı'!$N$5:$N$204,"Devam Ediyor")+COUNTIFS('İş Planı'!$E$5:$E$204,$AK21,'İş Planı'!$N$5:$N$204,"Devam Ediyor")+COUNTIFS('İş Planı'!$F$5:$F$204,$AK21,'İş Planı'!$N$5:$N$204,"Devam Ediyor")) | AM21: =IF($AK21="","",COUNTIFS('İş Planı'!$D$5:$D$204,$AK21,'İş Planı'!$N$5:$N$204,"Gecikmiş")+COUNTIFS('İş Planı'!$E$5:$E$204,$AK21,'İş Planı'!$N$5:$N$204,"Gecikmiş")+COUNTIFS('İş Planı'!$F$5:$F$204,$AK21,'İş Planı'!$N$5:$N$204,"Gecikmiş")) | BB21: =IF(Listeler!$B21="","",IF(COUNTIF('İş Planı'!$B$5:$B$204,Listeler!$B21)=0,"",ROW()-3)) | BD21: =IF(Listeler!$D21="","",IF(COUNTIF('İş Planı'!$D$5:$D$204,Listeler!$D21)+COUNTIF('İş Planı'!$E$5:$E$204,Listeler!$D21)+COUNTIF('İş Planı'!$F$5:$F$204,Listeler!$D21)=0,"",ROW()-3))
R22: =IF('İş Planı'!$C22="","",IF('İş Planı'!$N22="Tamamlandı",N('İş Planı'!$K22),MAX(N('İş Planı'!$K22),IF(AND('İş Planı'!$I22<>"",'İş Planı'!$I22<TODAY()),TODAY()-'İş Planı'!$I22,0)))+ROW()/1000000) | AB22: 46169 | AC22: =SUMPRODUCT(('İş Planı'!$C$5:$C$204<>"")*('İş Planı'!$L$5:$L$204<>"")*('İş Planı'!$L$5:$L$204<=AB22)) | AD22: =SUMPRODUCT(('İş Planı'!$C$5:$C$204<>"")*('İş Planı'!$L$5:$L$204<>"")*('İş Planı'!$L$5:$L$204<=AB22)*('İş Planı'!$N$5:$N$204="Tamamlandı")) | BB22: =IF(Listeler!$B22="","",IF(COUNTIF('İş Planı'!$B$5:$B$204,Listeler!$B22)=0,"",ROW()-3)) | BD22: =IF(Listeler!$D22="","",IF(COUNTIF('İş Planı'!$D$5:$D$204,Listeler!$D22)+COUNTIF('İş Planı'!$E$5:$E$204,Listeler!$D22)+COUNTIF('İş Planı'!$F$5:$F$204,Listeler!$D22)=0,"",ROW()-3))
R23: =IF('İş Planı'!$C23="","",IF('İş Planı'!$N23="Tamamlandı",N('İş Planı'!$K23),MAX(N('İş Planı'!$K23),IF(AND('İş Planı'!$I23<>"",'İş Planı'!$I23<TODAY()),TODAY()-'İş Planı'!$I23,0)))+ROW()/1000000) | AB23: 46176 | AC23: =SUMPRODUCT(('İş Planı'!$C$5:$C$204<>"")*('İş Planı'!$L$5:$L$204<>"")*('İş Planı'!$L$5:$L$204<=AB23)) | AD23: =SUMPRODUCT(('İş Planı'!$C$5:$C$204<>"")*('İş Planı'!$L$5:$L$204<>"")*('İş Planı'!$L$5:$L$204<=AB23)*('İş Planı'!$N$5:$N$204="Tamamlandı")) | BB23: =IF(Listeler!$B23="","",IF(COUNTIF('İş Planı'!$B$5:$B$204,Listeler!$B23)=0,"",ROW()-3)) | BD23: =IF(Listeler!$D23="","",IF(COUNTIF('İş Planı'!$D$5:$D$204,Listeler!$D23)+COUNTIF('İş Planı'!$E$5:$E$204,Listeler!$D23)+COUNTIF('İş Planı'!$F$5:$F$204,Listeler!$D23)=0,"",ROW()-3))
R24: =IF('İş Planı'!$C24="","",IF('İş Planı'!$N24="Tamamlandı",N('İş Planı'!$K24),MAX(N('İş Planı'!$K24),IF(AND('İş Planı'!$I24<>"",'İş Planı'!$I24<TODAY()),TODAY()-'İş Planı'!$I24,0)))+ROW()/1000000) | AB24: 46183 | AC24: =SUMPRODUCT(('İş Planı'!$C$5:$C$204<>"")*('İş Planı'!$L$5:$L$204<>"")*('İş Planı'!$L$5:$L$204<=AB24)) | AD24: =SUMPRODUCT(('İş Planı'!$C$5:$C$204<>"")*('İş Planı'!$L$5:$L$204<>"")*('İş Planı'!$L$5:$L$204<=AB24)*('İş Planı'!$N$5:$N$204="Tamamlandı")) | BB24: =IF(Listeler!$B24="","",IF(COUNTIF('İş Planı'!$B$5:$B$204,Listeler!$B24)=0,"",ROW()-3)) | BD24: =IF(Listeler!$D24="","",IF(COUNTIF('İş Planı'!$D$5:$D$204,Listeler!$D24)+COUNTIF('İş Planı'!$E$5:$E$204,Listeler!$D24)+COUNTIF('İş Planı'!$F$5:$F$204,Listeler!$D24)=0,"",ROW()-3))
R25: =IF('İş Planı'!$C25="","",IF('İş Planı'!$N25="Tamamlandı",N('İş Planı'!$K25),MAX(N('İş Planı'!$K25),IF(AND('İş Planı'!$I25<>"",'İş Planı'!$I25<TODAY()),TODAY()-'İş Planı'!$I25,0)))+ROW()/1000000) | AB25: 46190 | AC25: =SUMPRODUCT(('İş Planı'!$C$5:$C$204<>"")*('İş Planı'!$L$5:$L$204<>"")*('İş Planı'!$L$5:$L$204<=AB25)) | AD25: =SUMPRODUCT(('İş Planı'!$C$5:$C$204<>"")*('İş Planı'!$L$5:$L$204<>"")*('İş Planı'!$L$5:$L$204<=AB25)*('İş Planı'!$N$5:$N$204="Tamamlandı")) | BB25: =IF(Listeler!$B25="","",IF(COUNTIF('İş Planı'!$B$5:$B$204,Listeler!$B25)=0,"",ROW()-3)) | BD25: =IF(Listeler!$D25="","",IF(COUNTIF('İş Planı'!$D$5:$D$204,Listeler!$D25)+COUNTIF('İş Planı'!$E$5:$E$204,Listeler!$D25)+COUNTIF('İş Planı'!$F$5:$F$204,Listeler!$D25)=0,"",ROW()-3))
R26: =IF('İş Planı'!$C26="","",IF('İş Planı'!$N26="Tamamlandı",N('İş Planı'!$K26),MAX(N('İş Planı'!$K26),IF(AND('İş Planı'!$I26<>"",'İş Planı'!$I26<TODAY()),TODAY()-'İş Planı'!$I26,0)))+ROW()/1000000) | AB26: 46197 | AC26: =SUMPRODUCT(('İş Planı'!$C$5:$C$204<>"")*('İş Planı'!$L$5:$L$204<>"")*('İş Planı'!$L$5:$L$204<=AB26)) | AD26: =SUMPRODUCT(('İş Planı'!$C$5:$C$204<>"")*('İş Planı'!$L$5:$L$204<>"")*('İş Planı'!$L$5:$L$204<=AB26)*('İş Planı'!$N$5:$N$204="Tamamlandı")) | BB26: =IF(Listeler!$B26="","",IF(COUNTIF('İş Planı'!$B$5:$B$204,Listeler!$B26)=0,"",ROW()-3)) | BD26: =IF(Listeler!$D26="","",IF(COUNTIF('İş Planı'!$D$5:$D$204,Listeler!$D26)+COUNTIF('İş Planı'!$E$5:$E$204,Listeler!$D26)+COUNTIF('İş Planı'!$F$5:$F$204,Listeler!$D26)=0,"",ROW()-3))
R27: =IF('İş Planı'!$C27="","",IF('İş Planı'!$N27="Tamamlandı",N('İş Planı'!$K27),MAX(N('İş Planı'!$K27),IF(AND('İş Planı'!$I27<>"",'İş Planı'!$I27<TODAY()),TODAY()-'İş Planı'!$I27,0)))+ROW()/1000000) | AB27: 46204 | AC27: =SUMPRODUCT(('İş Planı'!$C$5:$C$204<>"")*('İş Planı'!$L$5:$L$204<>"")*('İş Planı'!$L$5:$L$204<=AB27)) | AD27: =SUMPRODUCT(('İş Planı'!$C$5:$C$204<>"")*('İş Planı'!$L$5:$L$204<>"")*('İş Planı'!$L$5:$L$204<=AB27)*('İş Planı'!$N$5:$N$204="Tamamlandı")) | BB27: =IF(Listeler!$B27="","",IF(COUNTIF('İş Planı'!$B$5:$B$204,Listeler!$B27)=0,"",ROW()-3)) | BD27: =IF(Listeler!$D27="","",IF(COUNTIF('İş Planı'!$D$5:$D$204,Listeler!$D27)+COUNTIF('İş Planı'!$E$5:$E$204,Listeler!$D27)+COUNTIF('İş Planı'!$F$5:$F$204,Listeler!$D27)=0,"",ROW()-3))
R28: =IF('İş Planı'!$C28="","",IF('İş Planı'!$N28="Tamamlandı",N('İş Planı'!$K28),MAX(N('İş Planı'!$K28),IF(AND('İş Planı'!$I28<>"",'İş Planı'!$I28<TODAY()),TODAY()-'İş Planı'!$I28,0)))+ROW()/1000000) | AB28: 46211 | AC28: =SUMPRODUCT(('İş Planı'!$C$5:$C$204<>"")*('İş Planı'!$L$5:$L$204<>"")*('İş Planı'!$L$5:$L$204<=AB28)) | AD28: =SUMPRODUCT(('İş Planı'!$C$5:$C$204<>"")*('İş Planı'!$L$5:$L$204<>"")*('İş Planı'!$L$5:$L$204<=AB28)*('İş Planı'!$N$5:$N$204="Tamamlandı")) | BB28: =IF(Listeler!$B28="","",IF(COUNTIF('İş Planı'!$B$5:$B$204,Listeler!$B28)=0,"",ROW()-3)) | BD28: =IF(Listeler!$D28="","",IF(COUNTIF('İş Planı'!$D$5:$D$204,Listeler!$D28)+COUNTIF('İş Planı'!$E$5:$E$204,Listeler!$D28)+COUNTIF('İş Planı'!$F$5:$F$204,Listeler!$D28)=0,"",ROW()-3))
R29: =IF('İş Planı'!$C29="","",IF('İş Planı'!$N29="Tamamlandı",N('İş Planı'!$K29),MAX(N('İş Planı'!$K29),IF(AND('İş Planı'!$I29<>"",'İş Planı'!$I29<TODAY()),TODAY()-'İş Planı'!$I29,0)))+ROW()/1000000) | AB29: 46218 | AC29: =SUMPRODUCT(('İş Planı'!$C$5:$C$204<>"")*('İş Planı'!$L$5:$L$204<>"")*('İş Planı'!$L$5:$L$204<=AB29)) | AD29: =SUMPRODUCT(('İş Planı'!$C$5:$C$204<>"")*('İş Planı'!$L$5:$L$204<>"")*('İş Planı'!$L$5:$L$204<=AB29)*('İş Planı'!$N$5:$N$204="Tamamlandı")) | BB29: =IF(Listeler!$B29="","",IF(COUNTIF('İş Planı'!$B$5:$B$204,Listeler!$B29)=0,"",ROW()-3)) | BD29: =IF(Listeler!$D29="","",IF(COUNTIF('İş Planı'!$D$5:$D$204,Listeler!$D29)+COUNTIF('İş Planı'!$E$5:$E$204,Listeler!$D29)+COUNTIF('İş Planı'!$F$5:$F$204,Listeler!$D29)=0,"",ROW()-3))
R30: =IF('İş Planı'!$C30="","",IF('İş Planı'!$N30="Tamamlandı",N('İş Planı'!$K30),MAX(N('İş Planı'!$K30),IF(AND('İş Planı'!$I30<>"",'İş Planı'!$I30<TODAY()),TODAY()-'İş Planı'!$I30,0)))+ROW()/1000000) | AB30: 46225 | AC30: =SUMPRODUCT(('İş Planı'!$C$5:$C$204<>"")*('İş Planı'!$L$5:$L$204<>"")*('İş Planı'!$L$5:$L$204<=AB30)) | AD30: =SUMPRODUCT(('İş Planı'!$C$5:$C$204<>"")*('İş Planı'!$L$5:$L$204<>"")*('İş Planı'!$L$5:$L$204<=AB30)*('İş Planı'!$N$5:$N$204="Tamamlandı")) | BB30: =IF(Listeler!$B30="","",IF(COUNTIF('İş Planı'!$B$5:$B$204,Listeler!$B30)=0,"",ROW()-3)) | BD30: =IF(Listeler!$D30="","",IF(COUNTIF('İş Planı'!$D$5:$D$204,Listeler!$D30)+COUNTIF('İş Planı'!$E$5:$E$204,Listeler!$D30)+COUNTIF('İş Planı'!$F$5:$F$204,Listeler!$D30)=0,"",ROW()-3))
R31: =IF('İş Planı'!$C31="","",IF('İş Planı'!$N31="Tamamlandı",N('İş Planı'!$K31),MAX(N('İş Planı'!$K31),IF(AND('İş Planı'!$I31<>"",'İş Planı'!$I31<TODAY()),TODAY()-'İş Planı'!$I31,0)))+ROW()/1000000) | AB31: 46232 | AC31: =SUMPRODUCT(('İş Planı'!$C$5:$C$204<>"")*('İş Planı'!$L$5:$L$204<>"")*('İş Planı'!$L$5:$L$204<=AB31)) | AD31: =SUMPRODUCT(('İş Planı'!$C$5:$C$204<>"")*('İş Planı'!$L$5:$L$204<>"")*('İş Planı'!$L$5:$L$204<=AB31)*('İş Planı'!$N$5:$N$204="Tamamlandı")) | BB31: =IF(Listeler!$B31="","",IF(COUNTIF('İş Planı'!$B$5:$B$204,Listeler!$B31)=0,"",ROW()-3)) | BD31: =IF(Listeler!$D31="","",IF(COUNTIF('İş Planı'!$D$5:$D$204,Listeler!$D31)+COUNTIF('İş Planı'!$E$5:$E$204,Listeler!$D31)+COUNTIF('İş Planı'!$F$5:$F$204,Listeler!$D31)=0,"",ROW()-3))
R32: =IF('İş Planı'!$C32="","",IF('İş Planı'!$N32="Tamamlandı",N('İş Planı'!$K32),MAX(N('İş Planı'!$K32),IF(AND('İş Planı'!$I32<>"",'İş Planı'!$I32<TODAY()),TODAY()-'İş Planı'!$I32,0)))+ROW()/1000000) | AB32: 46239 | AC32: =SUMPRODUCT(('İş Planı'!$C$5:$C$204<>"")*('İş Planı'!$L$5:$L$204<>"")*('İş Planı'!$L$5:$L$204<=AB32)) | AD32: =SUMPRODUCT(('İş Planı'!$C$5:$C$204<>"")*('İş Planı'!$L$5:$L$204<>"")*('İş Planı'!$L$5:$L$204<=AB32)*('İş Planı'!$N$5:$N$204="Tamamlandı")) | BB32: =IF(Listeler!$B32="","",IF(COUNTIF('İş Planı'!$B$5:$B$204,Listeler!$B32)=0,"",ROW()-3)) | BD32: =IF(Listeler!$D32="","",IF(COUNTIF('İş Planı'!$D$5:$D$204,Listeler!$D32)+COUNTIF('İş Planı'!$E$5:$E$204,Listeler!$D32)+COUNTIF('İş Planı'!$F$5:$F$204,Listeler!$D32)=0,"",ROW()-3))
R33: =IF('İş Planı'!$C33="","",IF('İş Planı'!$N33="Tamamlandı",N('İş Planı'!$K33),MAX(N('İş Planı'!$K33),IF(AND('İş Planı'!$I33<>"",'İş Planı'!$I33<TODAY()),TODAY()-'İş Planı'!$I33,0)))+ROW()/1000000) | AB33: 46246 | AC33: =SUMPRODUCT(('İş Planı'!$C$5:$C$204<>"")*('İş Planı'!$L$5:$L$204<>"")*('İş Planı'!$L$5:$L$204<=AB33)) | AD33: =SUMPRODUCT(('İş Planı'!$C$5:$C$204<>"")*('İş Planı'!$L$5:$L$204<>"")*('İş Planı'!$L$5:$L$204<=AB33)*('İş Planı'!$N$5:$N$204="Tamamlandı")) | BB33: =IF(Listeler!$B33="","",IF(COUNTIF('İş Planı'!$B$5:$B$204,Listeler!$B33)=0,"",ROW()-3)) | BD33: =IF(Listeler!$D33="","",IF(COUNTIF('İş Planı'!$D$5:$D$204,Listeler!$D33)+COUNTIF('İş Planı'!$E$5:$E$204,Listeler!$D33)+COUNTIF('İş Planı'!$F$5:$F$204,Listeler!$D33)=0,"",ROW()-3))
... R43: =IF('İş Planı'!$C43="","",IF('İş Planı'!$N43="Tamamlandı",N('İş Planı'!$K43),MAX(N('İş Planı'!$K43),IF(AND('İş Planı'!$I43<>"",'İş Planı'!$I43<TODAY()),TODAY()-'İş Planı'!$I43,0)))+ROW()/1000000) | AB43: 46316 | AC43: =SUMPRODUCT(('İş Planı'!$C$5:$C$204<>"")*('İş Planı'!$L$5:$L$204<>"")*('İş Planı'!$L$5:$L$204<=AB43)) | AD43: =SUMPRODUCT(('İş Planı'!$C$5:$C$204<>"")*('İş Planı'!$L$5:$L$204<>"")*('İş Planı'!$L$5:$L$204<=AB43)*('İş Planı'!$N$5:$N$204="Tamamlandı")) | BB43: =IF(Listeler!$B43="","",IF(COUNTIF('İş Planı'!$B$5:$B$204,Listeler!$B43)=0,"",ROW()-3)) | BD43: =IF(Listeler!$D43="","",IF(COUNTIF('İş Planı'!$D$5:$D$204,Listeler!$D43)+COUNTIF('İş Planı'!$E$5:$E$204,Listeler!$D43)+COUNTIF('İş Planı'!$F$5:$F$204,Listeler!$D43)=0,"",ROW()-3))
R44: =IF('İş Planı'!$C44="","",IF('İş Planı'!$N44="Tamamlandı",N('İş Planı'!$K44),MAX(N('İş Planı'!$K44),IF(AND('İş Planı'!$I44<>"",'İş Planı'!$I44<TODAY()),TODAY()-'İş Planı'!$I44,0)))+ROW()/1000000) | AB44: 46323 | AC44: =SUMPRODUCT(('İş Planı'!$C$5:$C$204<>"")*('İş Planı'!$L$5:$L$204<>"")*('İş Planı'!$L$5:$L$204<=AB44)) | AD44: =SUMPRODUCT(('İş Planı'!$C$5:$C$204<>"")*('İş Planı'!$L$5:$L$204<>"")*('İş Planı'!$L$5:$L$204<=AB44)*('İş Planı'!$N$5:$N$204="Tamamlandı"))
R45: =IF('İş Planı'!$C45="","",IF('İş Planı'!$N45="Tamamlandı",N('İş Planı'!$K45),MAX(N('İş Planı'!$K45),IF(AND('İş Planı'!$I45<>"",'İş Planı'!$I45<TODAY()),TODAY()-'İş Planı'!$I45,0)))+ROW()/1000000) | AB45: 46330 | AC45: =SUMPRODUCT(('İş Planı'!$C$5:$C$204<>"")*('İş Planı'!$L$5:$L$204<>"")*('İş Planı'!$L$5:$L$204<=AB45)) | AD45: =SUMPRODUCT(('İş Planı'!$C$5:$C$204<>"")*('İş Planı'!$L$5:$L$204<>"")*('İş Planı'!$L$5:$L$204<=AB45)*('İş Planı'!$N$5:$N$204="Tamamlandı"))
