Workbook

Sheet Yönetici Özeti
A1: 2026 YILLIK İŞ PLANI - YÖNETİCİ ÖZETİ
A5: Tüm değerler 'İş Planı' sayfasından otomatik hesaplanır.
B8: TOPLAM İŞ | I8: PLANLANAN | P8: DEVAM EDİYOR | W8: TAMAMLANDI | AD8: GECİKMİŞ | AK8: GENEL İLERLEME | AR8: MUTABAKAT TAMAM | AY8: PROJEKSİYON RİSKİ
B9: =Hesap!$U$2 -> 95 | I9: =Hesap!$U$6 -> 62 | P9: =Hesap!$U$4 -> 12 | W9: =Hesap!$U$3 -> 6 | AD9: =Hesap!$U$5 -> 15 | AK9: =Hesap!$U$7 -> 0.16789474 | AR9: =Hesap!$U$8 -> 0 | AY9: =Hesap!$U$9 -> 17
B11: Plandaki satır | I11: Başlamamış | P11: Açık çalışma | W11: Kapanan iş | AD11: Süresi geçmiş | AK11: Ortalama | AR11: Tarihi girilmiş | AY11: Gecikebilir
B15: DURUM DAĞILIMI | S15: AYLIK İŞ YÜKÜ
B16: Durum sütununa göre | S16: Her ayda aktif iş kalemi sayısı
B35: HAFTALIK İLERLEME EĞRİSİ
B36: Kümülatif: o haftaya kadar bitmesi planlanan iş ile bunlardan tamamlananlar
B57: AYLIK İLERLEME EĞRİSİ
B58: Aynı hesap ayın son gününe göre
B79: DENETİM BAŞLIĞINA GÖRE İŞ DURUMU
B80: Yalnızca İş Planı'nda kullanılan başlıklar listelenir
B105: KİŞİ BAZLI İŞ YÜKÜ
B106: Sorumlu 1-4 sütunlarının tamamı sayılır; tamamlanan işler hariçtir
B131: GECİKME ANALİZİ - SÜRE × ÖNCELİK
B132: Kaç iş ne kadar gecikmiş ve önceliği ne?
B156: MUTABAKAT DURUMU | U156: PROJEKSİYON RİSKİ
B157: Bitiş + 7 gün kuralına göre | U157: Geçen süre oranı ile ilerleme arasındaki fark %30'ı aşan işler
B181: RENK LEJANDI
E182: Planlanan
E183: Devam Ediyor
E184: Tamamlandı
E185: Gecikmiş

Sheet Listeler
B1: AÇILIR LİSTE KAYNAKLARI | J1: KİŞİ BAZLI GÜN YÜKÜ
B3: Denetim Başlıkları | D3: Kişiler | F3: Öncelik | H3: Durum (referans) | J3: Kişi | K3: İş Sayısı | L3: Toplam Gün | M3: Açık Gün | N3: Geciken İş
B4: Yönetim Beyanı | D4: Ornek User1 | F4: Yüksek | H4: Planlanan | J4: =IF($D4="","",$D4) -> Ornek User1 | K4: =IF($J4="","",COUNTIF('İş Planı'!$D$5:$D$204,$J4)+COUNTIF('İş Planı'!$E$5:$E$204,$J4)+COUNTIF('İş Planı'!$F$5:$F$204,$J4)+COUNTIF('İş Planı'!$G$5:$G$204,$J4)) -> 13 | L4: =IF($J4="","",SUMIF('İş Planı'!$D$5:$D$204,$J4,'İş Planı'!$K$5:$K$204)+SUMIF('İş Planı'!$E$5:$E$204,$J4,'İş Planı'!$K$5:$K$204)+SUMIF('İş Planı'!$F$5:$F$204,$J4,'İş Planı'!$K$5:$K$204)+SUMIF('İş Planı'!$G$5:$G$204,$J4,'İş Planı'!$K$5:$K$204)) -> 0 | M4: =IF($J4="","",SUMIFS('İş Planı'!$K$5:$K$204,'İş Planı'!$D$5:$D$204,$J4,'İş Planı'!$O$5:$O$204,"<>Tamamlandı")+SUMIFS('İş Planı'!$K$5:$K$204,'İş Planı'!$E$5:$E$204,$J4,'İş Planı'!$O$5:$O$204,"<>Tamamlandı")+SUMIFS('İş Planı'!$K$5:$K$204,'İş Planı'!$F$5:$F$204,$J4,'İş Planı'!$O$5:$O$204,"<>Tamamlandı")+SUMIFS('İş Planı'!$K$5:$K$204,'İş Planı'!$G$5:$G$204,$J4,'İş Planı'!$O$5:$O$204,"<>Tamamlandı")) -> 0 | N4: =IF($J4="","",COUNTIFS('İş Planı'!$D$5:$D$204,$J4,'İş Planı'!$O$5:$O$204,"Gecikmiş")+COUNTIFS('İş Planı'!$E$5:$E$204,$J4,'İş Planı'!$O$5:$O$204,"Gecikmiş")+COUNTIFS('İş Planı'!$F$5:$F$204,$J4,'İş Planı'!$O$5:$O$204,"Gecikmiş")+COUNTIFS('İş Planı'!$G$5:$G$204,$J4,'İş Planı'!$O$5:$O$204,"Gecikmiş")) -> 0
B5: BIGR (Yönetim Beyanı Ortak Maddeler) | D5: Ornek User2 | F5: Orta | H5: Devam Ediyor | J5: =IF($D5="","",$D5) -> Ornek User2 | K5: =IF($J5="","",COUNTIF('İş Planı'!$D$5:$D$204,$J5)+COUNTIF('İş Planı'!$E$5:$E$204,$J5)+COUNTIF('İş Planı'!$F$5:$F$204,$J5)+COUNTIF('İş Planı'!$G$5:$G$204,$J5)) -> 0 | L5: =IF($J5="","",SUMIF('İş Planı'!$D$5:$D$204,$J5,'İş Planı'!$K$5:$K$204)+SUMIF('İş Planı'!$E$5:$E$204,$J5,'İş Planı'!$K$5:$K$204)+SUMIF('İş Planı'!$F$5:$F$204,$J5,'İş Planı'!$K$5:$K$204)+SUMIF('İş Planı'!$G$5:$G$204,$J5,'İş Planı'!$K$5:$K$204)) -> 0 | M5: =IF($J5="","",SUMIFS('İş Planı'!$K$5:$K$204,'İş Planı'!$D$5:$D$204,$J5,'İş Planı'!$O$5:$O$204,"<>Tamamlandı")+SUMIFS('İş Planı'!$K$5:$K$204,'İş Planı'!$E$5:$E$204,$J5,'İş Planı'!$O$5:$O$204,"<>Tamamlandı")+SUMIFS('İş Planı'!$K$5:$K$204,'İş Planı'!$F$5:$F$204,$J5,'İş Planı'!$O$5:$O$204,"<>Tamamlandı")+SUMIFS('İş Planı'!$K$5:$K$204,'İş Planı'!$G$5:$G$204,$J5,'İş Planı'!$O$5:$O$204,"<>Tamamlandı")) -> 0 | N5: =IF($J5="","",COUNTIFS('İş Planı'!$D$5:$D$204,$J5,'İş Planı'!$O$5:$O$204,"Gecikmiş")+COUNTIFS('İş Planı'!$E$5:$E$204,$J5,'İş Planı'!$O$5:$O$204,"Gecikmiş")+COUNTIFS('İş Planı'!$F$5:$F$204,$J5,'İş Planı'!$O$5:$O$204,"Gecikmiş")+COUNTIFS('İş Planı'!$G$5:$G$204,$J5,'İş Planı'!$O$5:$O$204,"Gecikmiş")) -> 0
B6: BIGR | D6: Ornek User3 | F6: Düşük | H6: Tamamlandı | J6: =IF($D6="","",$D6) -> Ornek User3 | K6: =IF($J6="","",COUNTIF('İş Planı'!$D$5:$D$204,$J6)+COUNTIF('İş Planı'!$E$5:$E$204,$J6)+COUNTIF('İş Planı'!$F$5:$F$204,$J6)+COUNTIF('İş Planı'!$G$5:$G$204,$J6)) -> 4 | L6: =IF($J6="","",SUMIF('İş Planı'!$D$5:$D$204,$J6,'İş Planı'!$K$5:$K$204)+SUMIF('İş Planı'!$E$5:$E$204,$J6,'İş Planı'!$K$5:$K$204)+SUMIF('İş Planı'!$F$5:$F$204,$J6,'İş Planı'!$K$5:$K$204)+SUMIF('İş Planı'!$G$5:$G$204,$J6,'İş Planı'!$K$5:$K$204)) -> 101 | M6: =IF($J6="","",SUMIFS('İş Planı'!$K$5:$K$204,'İş Planı'!$D$5:$D$204,$J6,'İş Planı'!$O$5:$O$204,"<>Tamamlandı")+SUMIFS('İş Planı'!$K$5:$K$204,'İş Planı'!$E$5:$E$204,$J6,'İş Planı'!$O$5:$O$204,"<>Tamamlandı")+SUMIFS('İş Planı'!$K$5:$K$204,'İş Planı'!$F$5:$F$204,$J6,'İş Planı'!$O$5:$O$204,"<>Tamamlandı")+SUMIFS('İş Planı'!$K$5:$K$204,'İş Planı'!$G$5:$G$204,$J6,'İş Planı'!$O$5:$O$204,"<>Tamamlandı")) -> 72 | N6: =IF($J6="","",COUNTIFS('İş Planı'!$D$5:$D$204,$J6,'İş Planı'!$O$5:$O$204,"Gecikmiş")+COUNTIFS('İş Planı'!$E$5:$E$204,$J6,'İş Planı'!$O$5:$O$204,"Gecikmiş")+COUNTIFS('İş Planı'!$F$5:$F$204,$J6,'İş Planı'!$O$5:$O$204,"Gecikmiş")+COUNTIFS('İş Planı'!$G$5:$G$204,$J6,'İş Planı'!$O$5:$O$204,"Gecikmiş")) -> 2
B7: Buluteks | D7: Ornek User4 | H7: Gecikmiş | J7: =IF($D7="","",$D7) -> Ornek User4 | K7: =IF($J7="","",COUNTIF('İş Planı'!$D$5:$D$204,$J7)+COUNTIF('İş Planı'!$E$5:$E$204,$J7)+COUNTIF('İş Planı'!$F$5:$F$204,$J7)+COUNTIF('İş Planı'!$G$5:$G$204,$J7)) -> 29 | L7: =IF($J7="","",SUMIF('İş Planı'!$D$5:$D$204,$J7,'İş Planı'!$K$5:$K$204)+SUMIF('İş Planı'!$E$5:$E$204,$J7,'İş Planı'!$K$5:$K$204)+SUMIF('İş Planı'!$F$5:$F$204,$J7,'İş Planı'!$K$5:$K$204)+SUMIF('İş Planı'!$G$5:$G$204,$J7,'İş Planı'!$K$5:$K$204)) -> 370 | M7: =IF($J7="","",SUMIFS('İş Planı'!$K$5:$K$204,'İş Planı'!$D$5:$D$204,$J7,'İş Planı'!$O$5:$O$204,"<>Tamamlandı")+SUMIFS('İş Planı'!$K$5:$K$204,'İş Planı'!$E$5:$E$204,$J7,'İş Planı'!$O$5:$O$204,"<>Tamamlandı")+SUMIFS('İş Planı'!$K$5:$K$204,'İş Planı'!$F$5:$F$204,$J7,'İş Planı'!$O$5:$O$204,"<>Tamamlandı")+SUMIFS('İş Planı'!$K$5:$K$204,'İş Planı'!$G$5:$G$204,$J7,'İş Planı'!$O$5:$O$204,"<>Tamamlandı")) -> 348 | N7: =IF($J7="","",COUNTIFS('İş Planı'!$D$5:$D$204,$J7,'İş Planı'!$O$5:$O$204,"Gecikmiş")+COUNTIFS('İş Planı'!$E$5:$E$204,$J7,'İş Planı'!$O$5:$O$204,"Gecikmiş")+COUNTIFS('İş Planı'!$F$5:$F$204,$J7,'İş Planı'!$O$5:$O$204,"Gecikmiş")+COUNTIFS('İş Planı'!$G$5:$G$204,$J7,'İş Planı'!$O$5:$O$204,"Gecikmiş")) -> 8
B8: Buluteks Dendeks Bulut Altyapı Denetimi | D8: Ornek User5 | J8: =IF($D8="","",$D8) -> Ornek User5 | K8: =IF($J8="","",COUNTIF('İş Planı'!$D$5:$D$204,$J8)+COUNTIF('İş Planı'!$E$5:$E$204,$J8)+COUNTIF('İş Planı'!$F$5:$F$204,$J8)+COUNTIF('İş Planı'!$G$5:$G$204,$J8)) -> 0 | L8: =IF($J8="","",SUMIF('İş Planı'!$D$5:$D$204,$J8,'İş Planı'!$K$5:$K$204)+SUMIF('İş Planı'!$E$5:$E$204,$J8,'İş Planı'!$K$5:$K$204)+SUMIF('İş Planı'!$F$5:$F$204,$J8,'İş Planı'!$K$5:$K$204)+SUMIF('İş Planı'!$G$5:$G$204,$J8,'İş Planı'!$K$5:$K$204)) -> 0 | M8: =IF($J8="","",SUMIFS('İş Planı'!$K$5:$K$204,'İş Planı'!$D$5:$D$204,$J8,'İş Planı'!$O$5:$O$204,"<>Tamamlandı")+SUMIFS('İş Planı'!$K$5:$K$204,'İş Planı'!$E$5:$E$204,$J8,'İş Planı'!$O$5:$O$204,"<>Tamamlandı")+SUMIFS('İş Planı'!$K$5:$K$204,'İş Planı'!$F$5:$F$204,$J8,'İş Planı'!$O$5:$O$204,"<>Tamamlandı")+SUMIFS('İş Planı'!$K$5:$K$204,'İş Planı'!$G$5:$G$204,$J8,'İş Planı'!$O$5:$O$204,"<>Tamamlandı")) -> 0 | N8: =IF($J8="","",COUNTIFS('İş Planı'!$D$5:$D$204,$J8,'İş Planı'!$O$5:$O$204,"Gecikmiş")+COUNTIFS('İş Planı'!$E$5:$E$204,$J8,'İş Planı'!$O$5:$O$204,"Gecikmiş")+COUNTIFS('İş Planı'!$F$5:$F$204,$J8,'İş Planı'!$O$5:$O$204,"Gecikmiş")+COUNTIFS('İş Planı'!$G$5:$G$204,$J8,'İş Planı'!$O$5:$O$204,"Gecikmiş")) -> 0
B9: Dendeks WS Entegrasyon Denetimi | D9: Ornek User6 | J9: =IF($D9="","",$D9) -> Ornek User6 | K9: =IF($J9="","",COUNTIF('İş Planı'!$D$5:$D$204,$J9)+COUNTIF('İş Planı'!$E$5:$E$204,$J9)+COUNTIF('İş Planı'!$F$5:$F$204,$J9)+COUNTIF('İş Planı'!$G$5:$G$204,$J9)) -> 0 | L9: =IF($J9="","",SUMIF('İş Planı'!$D$5:$D$204,$J9,'İş Planı'!$K$5:$K$204)+SUMIF('İş Planı'!$E$5:$E$204,$J9,'İş Planı'!$K$5:$K$204)+SUMIF('İş Planı'!$F$5:$F$204,$J9,'İş Planı'!$K$5:$K$204)+SUMIF('İş Planı'!$G$5:$G$204,$J9,'İş Planı'!$K$5:$K$204)) -> 0 | M9: =IF($J9="","",SUMIFS('İş Planı'!$K$5:$K$204,'İş Planı'!$D$5:$D$204,$J9,'İş Planı'!$O$5:$O$204,"<>Tamamlandı")+SUMIFS('İş Planı'!$K$5:$K$204,'İş Planı'!$E$5:$E$204,$J9,'İş Planı'!$O$5:$O$204,"<>Tamamlandı")+SUMIFS('İş Planı'!$K$5:$K$204,'İş Planı'!$F$5:$F$204,$J9,'İş Planı'!$O$5:$O$204,"<>Tamamlandı")+SUMIFS('İş Planı'!$K$5:$K$204,'İş Planı'!$G$5:$G$204,$J9,'İş Planı'!$O$5:$O$204,"<>Tamamlandı")) -> 0 | N9: =IF($J9="","",COUNTIFS('İş Planı'!$D$5:$D$204,$J9,'İş Planı'!$O$5:$O$204,"Gecikmiş")+COUNTIFS('İş Planı'!$E$5:$E$204,$J9,'İş Planı'!$O$5:$O$204,"Gecikmiş")+COUNTIFS('İş Planı'!$F$5:$F$204,$J9,'İş Planı'!$O$5:$O$204,"Gecikmiş")+COUNTIFS('İş Planı'!$G$5:$G$204,$J9,'İş Planı'!$O$5:$O$204,"Gecikmiş")) -> 0
B10: Süreç Denetimleri | D10: Ornek User7 | J10: =IF($D10="","",$D10) -> Ornek User7 | K10: =IF($J10="","",COUNTIF('İş Planı'!$D$5:$D$204,$J10)+COUNTIF('İş Planı'!$E$5:$E$204,$J10)+COUNTIF('İş Planı'!$F$5:$F$204,$J10)+COUNTIF('İş Planı'!$G$5:$G$204,$J10)) -> 0 | L10: =IF($J10="","",SUMIF('İş Planı'!$D$5:$D$204,$J10,'İş Planı'!$K$5:$K$204)+SUMIF('İş Planı'!$E$5:$E$204,$J10,'İş Planı'!$K$5:$K$204)+SUMIF('İş Planı'!$F$5:$F$204,$J10,'İş Planı'!$K$5:$K$204)+SUMIF('İş Planı'!$G$5:$G$204,$J10,'İş Planı'!$K$5:$K$204)) -> 0 | M10: =IF($J10="","",SUMIFS('İş Planı'!$K$5:$K$204,'İş Planı'!$D$5:$D$204,$J10,'İş Planı'!$O$5:$O$204,"<>Tamamlandı")+SUMIFS('İş Planı'!$K$5:$K$204,'İş Planı'!$E$5:$E$204,$J10,'İş Planı'!$O$5:$O$204,"<>Tamamlandı")+SUMIFS('İş Planı'!$K$5:$K$204,'İş Planı'!$F$5:$F$204,$J10,'İş Planı'!$O$5:$O$204,"<>Tamamlandı")+SUMIFS('İş Planı'!$K$5:$K$204,'İş Planı'!$G$5:$G$204,$J10,'İş Planı'!$O$5:$O$204,"<>Tamamlandı")) -> 0 | N10: =IF($J10="","",COUNTIFS('İş Planı'!$D$5:$D$204,$J10,'İş Planı'!$O$5:$O$204,"Gecikmiş")+COUNTIFS('İş Planı'!$E$5:$E$204,$J10,'İş Planı'!$O$5:$O$204,"Gecikmiş")+COUNTIFS('İş Planı'!$F$5:$F$204,$J10,'İş Planı'!$O$5:$O$204,"Gecikmiş")+COUNTIFS('İş Planı'!$G$5:$G$204,$J10,'İş Planı'!$O$5:$O$204,"Gecikmiş")) -> 0
B11: Destek Hizmeti Denetimler | D11: Ornek User8 | J11: =IF($D11="","",$D11) -> Ornek User8 | K11: =IF($J11="","",COUNTIF('İş Planı'!$D$5:$D$204,$J11)+COUNTIF('İş Planı'!$E$5:$E$204,$J11)+COUNTIF('İş Planı'!$F$5:$F$204,$J11)+COUNTIF('İş Planı'!$G$5:$G$204,$J11)) -> 0 | L11: =IF($J11="","",SUMIF('İş Planı'!$D$5:$D$204,$J11,'İş Planı'!$K$5:$K$204)+SUMIF('İş Planı'!$E$5:$E$204,$J11,'İş Planı'!$K$5:$K$204)+SUMIF('İş Planı'!$F$5:$F$204,$J11,'İş Planı'!$K$5:$K$204)+SUMIF('İş Planı'!$G$5:$G$204,$J11,'İş Planı'!$K$5:$K$204)) -> 0 | M11: =IF($J11="","",SUMIFS('İş Planı'!$K$5:$K$204,'İş Planı'!$D$5:$D$204,$J11,'İş Planı'!$O$5:$O$204,"<>Tamamlandı")+SUMIFS('İş Planı'!$K$5:$K$204,'İş Planı'!$E$5:$E$204,$J11,'İş Planı'!$O$5:$O$204,"<>Tamamlandı")+SUMIFS('İş Planı'!$K$5:$K$204,'İş Planı'!$F$5:$F$204,$J11,'İş Planı'!$O$5:$O$204,"<>Tamamlandı")+SUMIFS('İş Planı'!$K$5:$K$204,'İş Planı'!$G$5:$G$204,$J11,'İş Planı'!$O$5:$O$204,"<>Tamamlandı")) -> 0 | N11: =IF($J11="","",COUNTIFS('İş Planı'!$D$5:$D$204,$J11,'İş Planı'!$O$5:$O$204,"Gecikmiş")+COUNTIFS('İş Planı'!$E$5:$E$204,$J11,'İş Planı'!$O$5:$O$204,"Gecikmiş")+COUNTIFS('İş Planı'!$F$5:$F$204,$J11,'İş Planı'!$O$5:$O$204,"Gecikmiş")+COUNTIFS('İş Planı'!$G$5:$G$204,$J11,'İş Planı'!$O$5:$O$204,"Gecikmiş")) -> 0
B12: Rehberlik Faaliyeti | D12: Ornek User9 | J12: =IF($D12="","",$D12) -> Ornek User9 | K12: =IF($J12="","",COUNTIF('İş Planı'!$D$5:$D$204,$J12)+COUNTIF('İş Planı'!$E$5:$E$204,$J12)+COUNTIF('İş Planı'!$F$5:$F$204,$J12)+COUNTIF('İş Planı'!$G$5:$G$204,$J12)) -> 20 | L12: =IF($J12="","",SUMIF('İş Planı'!$D$5:$D$204,$J12,'İş Planı'!$K$5:$K$204)+SUMIF('İş Planı'!$E$5:$E$204,$J12,'İş Planı'!$K$5:$K$204)+SUMIF('İş Planı'!$F$5:$F$204,$J12,'İş Planı'!$K$5:$K$204)+SUMIF('İş Planı'!$G$5:$G$204,$J12,'İş Planı'!$K$5:$K$204)) -> 287 | M12: =IF($J12="","",SUMIFS('İş Planı'!$K$5:$K$204,'İş Planı'!$D$5:$D$204,$J12,'İş Planı'!$O$5:$O$204,"<>Tamamlandı")+SUMIFS('İş Planı'!$K$5:$K$204,'İş Planı'!$E$5:$E$204,$J12,'İş Planı'!$O$5:$O$204,"<>Tamamlandı")+SUMIFS('İş Planı'!$K$5:$K$204,'İş Planı'!$F$5:$F$204,$J12,'İş Planı'!$O$5:$O$204,"<>Tamamlandı")+SUMIFS('İş Planı'!$K$5:$K$204,'İş Planı'!$G$5:$G$204,$J12,'İş Planı'!$O$5:$O$204,"<>Tamamlandı")) -> 239 | N12: =IF($J12="","",COUNTIFS('İş Planı'!$D$5:$D$204,$J12,'İş Planı'!$O$5:$O$204,"Gecikmiş")+COUNTIFS('İş Planı'!$E$5:$E$204,$J12,'İş Planı'!$O$5:$O$204,"Gecikmiş")+COUNTIFS('İş Planı'!$F$5:$F$204,$J12,'İş Planı'!$O$5:$O$204,"Gecikmiş")+COUNTIFS('İş Planı'!$G$5:$G$204,$J12,'İş Planı'!$O$5:$O$204,"Gecikmiş")) -> 5
B13: Projeler | D13: Ornek User10 | J13: =IF($D13="","",$D13) -> Ornek User10 | K13: =IF($J13="","",COUNTIF('İş Planı'!$D$5:$D$204,$J13)+COUNTIF('İş Planı'!$E$5:$E$204,$J13)+COUNTIF('İş Planı'!$F$5:$F$204,$J13)+COUNTIF('İş Planı'!$G$5:$G$204,$J13)) -> 0 | L13: =IF($J13="","",SUMIF('İş Planı'!$D$5:$D$204,$J13,'İş Planı'!$K$5:$K$204)+SUMIF('İş Planı'!$E$5:$E$204,$J13,'İş Planı'!$K$5:$K$204)+SUMIF('İş Planı'!$F$5:$F$204,$J13,'İş Planı'!$K$5:$K$204)+SUMIF('İş Planı'!$G$5:$G$204,$J13,'İş Planı'!$K$5:$K$204)) -> 0 | M13: =IF($J13="","",SUMIFS('İş Planı'!$K$5:$K$204,'İş Planı'!$D$5:$D$204,$J13,'İş Planı'!$O$5:$O$204,"<>Tamamlandı")+SUMIFS('İş Planı'!$K$5:$K$204,'İş Planı'!$E$5:$E$204,$J13,'İş Planı'!$O$5:$O$204,"<>Tamamlandı")+SUMIFS('İş Planı'!$K$5:$K$204,'İş Planı'!$F$5:$F$204,$J13,'İş Planı'!$O$5:$O$204,"<>Tamamlandı")+SUMIFS('İş Planı'!$K$5:$K$204,'İş Planı'!$G$5:$G$204,$J13,'İş Planı'!$O$5:$O$204,"<>Tamamlandı")) -> 0 | N13: =IF($J13="","",COUNTIFS('İş Planı'!$D$5:$D$204,$J13,'İş Planı'!$O$5:$O$204,"Gecikmiş")+COUNTIFS('İş Planı'!$E$5:$E$204,$J13,'İş Planı'!$O$5:$O$204,"Gecikmiş")+COUNTIFS('İş Planı'!$F$5:$F$204,$J13,'İş Planı'!$O$5:$O$204,"Gecikmiş")+COUNTIFS('İş Planı'!$G$5:$G$204,$J13,'İş Planı'!$O$5:$O$204,"Gecikmiş")) -> 0
B14: Ad-Hoc İşler | D14: Ornek User11 | J14: =IF($D14="","",$D14) -> Ornek User11 | K14: =IF($J14="","",COUNTIF('İş Planı'!$D$5:$D$204,$J14)+COUNTIF('İş Planı'!$E$5:$E$204,$J14)+COUNTIF('İş Planı'!$F$5:$F$204,$J14)+COUNTIF('İş Planı'!$G$5:$G$204,$J14)) -> 15 | L14: =IF($J14="","",SUMIF('İş Planı'!$D$5:$D$204,$J14,'İş Planı'!$K$5:$K$204)+SUMIF('İş Planı'!$E$5:$E$204,$J14,'İş Planı'!$K$5:$K$204)+SUMIF('İş Planı'!$F$5:$F$204,$J14,'İş Planı'!$K$5:$K$204)+SUMIF('İş Planı'!$G$5:$G$204,$J14,'İş Planı'!$K$5:$K$204)) -> 151 | M14: =IF($J14="","",SUMIFS('İş Planı'!$K$5:$K$204,'İş Planı'!$D$5:$D$204,$J14,'İş Planı'!$O$5:$O$204,"<>Tamamlandı")+SUMIFS('İş Planı'!$K$5:$K$204,'İş Planı'!$E$5:$E$204,$J14,'İş Planı'!$O$5:$O$204,"<>Tamamlandı")+SUMIFS('İş Planı'!$K$5:$K$204,'İş Planı'!$F$5:$F$204,$J14,'İş Planı'!$O$5:$O$204,"<>Tamamlandı")+SUMIFS('İş Planı'!$K$5:$K$204,'İş Planı'!$G$5:$G$204,$J14,'İş Planı'!$O$5:$O$204,"<>Tamamlandı")) -> 129 | N14: =IF($J14="","",COUNTIFS('İş Planı'!$D$5:$D$204,$J14,'İş Planı'!$O$5:$O$204,"Gecikmiş")+COUNTIFS('İş Planı'!$E$5:$E$204,$J14,'İş Planı'!$O$5:$O$204,"Gecikmiş")+COUNTIFS('İş Planı'!$F$5:$F$204,$J14,'İş Planı'!$O$5:$O$204,"Gecikmiş")+COUNTIFS('İş Planı'!$G$5:$G$204,$J14,'İş Planı'!$O$5:$O$204,"Gecikmiş")) -> 1
B15: Rutin Faaliyetler | D15: Ornek User12 | J15: =IF($D15="","",$D15) -> Ornek User12 | K15: =IF($J15="","",COUNTIF('İş Planı'!$D$5:$D$204,$J15)+COUNTIF('İş Planı'!$E$5:$E$204,$J15)+COUNTIF('İş Planı'!$F$5:$F$204,$J15)+COUNTIF('İş Planı'!$G$5:$G$204,$J15)) -> 11 | L15: =IF($J15="","",SUMIF('İş Planı'!$D$5:$D$204,$J15,'İş Planı'!$K$5:$K$204)+SUMIF('İş Planı'!$E$5:$E$204,$J15,'İş Planı'!$K$5:$K$204)+SUMIF('İş Planı'!$F$5:$F$204,$J15,'İş Planı'!$K$5:$K$204)+SUMIF('İş Planı'!$G$5:$G$204,$J15,'İş Planı'!$K$5:$K$204)) -> 80 | M15: =IF($J15="","",SUMIFS('İş Planı'!$K$5:$K$204,'İş Planı'!$D$5:$D$204,$J15,'İş Planı'!$O$5:$O$204,"<>Tamamlandı")+SUMIFS('İş Planı'!$K$5:$K$204,'İş Planı'!$E$5:$E$204,$J15,'İş Planı'!$O$5:$O$204,"<>Tamamlandı")+SUMIFS('İş Planı'!$K$5:$K$204,'İş Planı'!$F$5:$F$204,$J15,'İş Planı'!$O$5:$O$204,"<>Tamamlandı")+SUMIFS('İş Planı'!$K$5:$K$204,'İş Planı'!$G$5:$G$204,$J15,'İş Planı'!$O$5:$O$204,"<>Tamamlandı")) -> 80 | N15: =IF($J15="","",COUNTIFS('İş Planı'!$D$5:$D$204,$J15,'İş Planı'!$O$5:$O$204,"Gecikmiş")+COUNTIFS('İş Planı'!$E$5:$E$204,$J15,'İş Planı'!$O$5:$O$204,"Gecikmiş")+COUNTIFS('İş Planı'!$F$5:$F$204,$J15,'İş Planı'!$O$5:$O$204,"Gecikmiş")+COUNTIFS('İş Planı'!$G$5:$G$204,$J15,'İş Planı'!$O$5:$O$204,"Gecikmiş")) -> 1
D16: Ornek User13 | J16: =IF($D16="","",$D16) -> Ornek User13 | K16: =IF($J16="","",COUNTIF('İş Planı'!$D$5:$D$204,$J16)+COUNTIF('İş Planı'!$E$5:$E$204,$J16)+COUNTIF('İş Planı'!$F$5:$F$204,$J16)+COUNTIF('İş Planı'!$G$5:$G$204,$J16)) -> 16 | L16: =IF($J16="","",SUMIF('İş Planı'!$D$5:$D$204,$J16,'İş Planı'!$K$5:$K$204)+SUMIF('İş Planı'!$E$5:$E$204,$J16,'İş Planı'!$K$5:$K$204)+SUMIF('İş Planı'!$F$5:$F$204,$J16,'İş Planı'!$K$5:$K$204)+SUMIF('İş Planı'!$G$5:$G$204,$J16,'İş Planı'!$K$5:$K$204)) -> 293 | M16: =IF($J16="","",SUMIFS('İş Planı'!$K$5:$K$204,'İş Planı'!$D$5:$D$204,$J16,'İş Planı'!$O$5:$O$204,"<>Tamamlandı")+SUMIFS('İş Planı'!$K$5:$K$204,'İş Planı'!$E$5:$E$204,$J16,'İş Planı'!$O$5:$O$204,"<>Tamamlandı")+SUMIFS('İş Planı'!$K$5:$K$204,'İş Planı'!$F$5:$F$204,$J16,'İş Planı'!$O$5:$O$204,"<>Tamamlandı")+SUMIFS('İş Planı'!$K$5:$K$204,'İş Planı'!$G$5:$G$204,$J16,'İş Planı'!$O$5:$O$204,"<>Tamamlandı")) -> 255 | N16: =IF($J16="","",COUNTIFS('İş Planı'!$D$5:$D$204,$J16,'İş Planı'!$O$5:$O$204,"Gecikmiş")+COUNTIFS('İş Planı'!$E$5:$E$204,$J16,'İş Planı'!$O$5:$O$204,"Gecikmiş")+COUNTIFS('İş Planı'!$F$5:$F$204,$J16,'İş Planı'!$O$5:$O$204,"Gecikmiş")+COUNTIFS('İş Planı'!$G$5:$G$204,$J16,'İş Planı'!$O$5:$O$204,"Gecikmiş")) -> 2
J17: =IF($D17="","",$D17) | K17: =IF($J17="","",COUNTIF('İş Planı'!$D$5:$D$204,$J17)+COUNTIF('İş Planı'!$E$5:$E$204,$J17)+COUNTIF('İş Planı'!$F$5:$F$204,$J17)+COUNTIF('İş Planı'!$G$5:$G$204,$J17)) | L17: =IF($J17="","",SUMIF('İş Planı'!$D$5:$D$204,$J17,'İş Planı'!$K$5:$K$204)+SUMIF('İş Planı'!$E$5:$E$204,$J17,'İş Planı'!$K$5:$K$204)+SUMIF('İş Planı'!$F$5:$F$204,$J17,'İş Planı'!$K$5:$K$204)+SUMIF('İş Planı'!$G$5:$G$204,$J17,'İş Planı'!$K$5:$K$204)) | M17: =IF($J17="","",SUMIFS('İş Planı'!$K$5:$K$204,'İş Planı'!$D$5:$D$204,$J17,'İş Planı'!$O$5:$O$204,"<>Tamamlandı")+SUMIFS('İş Planı'!$K$5:$K$204,'İş Planı'!$E$5:$E$204,$J17,'İş Planı'!$O$5:$O$204,"<>Tamamlandı")+SUMIFS('İş Planı'!$K$5:$K$204,'İş Planı'!$F$5:$F$204,$J17,'İş Planı'!$O$5:$O$204,"<>Tamamlandı")+SUMIFS('İş Planı'!$K$5:$K$204,'İş Planı'!$G$5:$G$204,$J17,'İş Planı'!$O$5:$O$204,"<>Tamamlandı")) | N17: =IF($J17="","",COUNTIFS('İş Planı'!$D$5:$D$204,$J17,'İş Planı'!$O$5:$O$204,"Gecikmiş")+COUNTIFS('İş Planı'!$E$5:$E$204,$J17,'İş Planı'!$O$5:$O$204,"Gecikmiş")+COUNTIFS('İş Planı'!$F$5:$F$204,$J17,'İş Planı'!$O$5:$O$204,"Gecikmiş")+COUNTIFS('İş Planı'!$G$5:$G$204,$J17,'İş Planı'!$O$5:$O$204,"Gecikmiş"))
J18: =IF($D18="","",$D18) | K18: =IF($J18="","",COUNTIF('İş Planı'!$D$5:$D$204,$J18)+COUNTIF('İş Planı'!$E$5:$E$204,$J18)+COUNTIF('İş Planı'!$F$5:$F$204,$J18)+COUNTIF('İş Planı'!$G$5:$G$204,$J18)) | L18: =IF($J18="","",SUMIF('İş Planı'!$D$5:$D$204,$J18,'İş Planı'!$K$5:$K$204)+SUMIF('İş Planı'!$E$5:$E$204,$J18,'İş Planı'!$K$5:$K$204)+SUMIF('İş Planı'!$F$5:$F$204,$J18,'İş Planı'!$K$5:$K$204)+SUMIF('İş Planı'!$G$5:$G$204,$J18,'İş Planı'!$K$5:$K$204)) | M18: =IF($J18="","",SUMIFS('İş Planı'!$K$5:$K$204,'İş Planı'!$D$5:$D$204,$J18,'İş Planı'!$O$5:$O$204,"<>Tamamlandı")+SUMIFS('İş Planı'!$K$5:$K$204,'İş Planı'!$E$5:$E$204,$J18,'İş Planı'!$O$5:$O$204,"<>Tamamlandı")+SUMIFS('İş Planı'!$K$5:$K$204,'İş Planı'!$F$5:$F$204,$J18,'İş Planı'!$O$5:$O$204,"<>Tamamlandı")+SUMIFS('İş Planı'!$K$5:$K$204,'İş Planı'!$G$5:$G$204,$J18,'İş Planı'!$O$5:$O$204,"<>Tamamlandı")) | N18: =IF($J18="","",COUNTIFS('İş Planı'!$D$5:$D$204,$J18,'İş Planı'!$O$5:$O$204,"Gecikmiş")+COUNTIFS('İş Planı'!$E$5:$E$204,$J18,'İş Planı'!$O$5:$O$204,"Gecikmiş")+COUNTIFS('İş Planı'!$F$5:$F$204,$J18,'İş Planı'!$O$5:$O$204,"Gecikmiş")+COUNTIFS('İş Planı'!$G$5:$G$204,$J18,'İş Planı'!$O$5:$O$204,"Gecikmiş"))
J19: =IF($D19="","",$D19) | K19: =IF($J19="","",COUNTIF('İş Planı'!$D$5:$D$204,$J19)+COUNTIF('İş Planı'!$E$5:$E$204,$J19)+COUNTIF('İş Planı'!$F$5:$F$204,$J19)+COUNTIF('İş Planı'!$G$5:$G$204,$J19)) | L19: =IF($J19="","",SUMIF('İş Planı'!$D$5:$D$204,$J19,'İş Planı'!$K$5:$K$204)+SUMIF('İş Planı'!$E$5:$E$204,$J19,'İş Planı'!$K$5:$K$204)+SUMIF('İş Planı'!$F$5:$F$204,$J19,'İş Planı'!$K$5:$K$204)+SUMIF('İş Planı'!$G$5:$G$204,$J19,'İş Planı'!$K$5:$K$204)) | M19: =IF($J19="","",SUMIFS('İş Planı'!$K$5:$K$204,'İş Planı'!$D$5:$D$204,$J19,'İş Planı'!$O$5:$O$204,"<>Tamamlandı")+SUMIFS('İş Planı'!$K$5:$K$204,'İş Planı'!$E$5:$E$204,$J19,'İş Planı'!$O$5:$O$204,"<>Tamamlandı")+SUMIFS('İş Planı'!$K$5:$K$204,'İş Planı'!$F$5:$F$204,$J19,'İş Planı'!$O$5:$O$204,"<>Tamamlandı")+SUMIFS('İş Planı'!$K$5:$K$204,'İş Planı'!$G$5:$G$204,$J19,'İş Planı'!$O$5:$O$204,"<>Tamamlandı")) | N19: =IF($J19="","",COUNTIFS('İş Planı'!$D$5:$D$204,$J19,'İş Planı'!$O$5:$O$204,"Gecikmiş")+COUNTIFS('İş Planı'!$E$5:$E$204,$J19,'İş Planı'!$O$5:$O$204,"Gecikmiş")+COUNTIFS('İş Planı'!$F$5:$F$204,$J19,'İş Planı'!$O$5:$O$204,"Gecikmiş")+COUNTIFS('İş Planı'!$G$5:$G$204,$J19,'İş Planı'!$O$5:$O$204,"Gecikmiş"))
J20: =IF($D20="","",$D20) | K20: =IF($J20="","",COUNTIF('İş Planı'!$D$5:$D$204,$J20)+COUNTIF('İş Planı'!$E$5:$E$204,$J20)+COUNTIF('İş Planı'!$F$5:$F$204,$J20)+COUNTIF('İş Planı'!$G$5:$G$204,$J20)) | L20: =IF($J20="","",SUMIF('İş Planı'!$D$5:$D$204,$J20,'İş Planı'!$K$5:$K$204)+SUMIF('İş Planı'!$E$5:$E$204,$J20,'İş Planı'!$K$5:$K$204)+SUMIF('İş Planı'!$F$5:$F$204,$J20,'İş Planı'!$K$5:$K$204)+SUMIF('İş Planı'!$G$5:$G$204,$J20,'İş Planı'!$K$5:$K$204)) | M20: =IF($J20="","",SUMIFS('İş Planı'!$K$5:$K$204,'İş Planı'!$D$5:$D$204,$J20,'İş Planı'!$O$5:$O$204,"<>Tamamlandı")+SUMIFS('İş Planı'!$K$5:$K$204,'İş Planı'!$E$5:$E$204,$J20,'İş Planı'!$O$5:$O$204,"<>Tamamlandı")+SUMIFS('İş Planı'!$K$5:$K$204,'İş Planı'!$F$5:$F$204,$J20,'İş Planı'!$O$5:$O$204,"<>Tamamlandı")+SUMIFS('İş Planı'!$K$5:$K$204,'İş Planı'!$G$5:$G$204,$J20,'İş Planı'!$O$5:$O$204,"<>Tamamlandı")) | N20: =IF($J20="","",COUNTIFS('İş Planı'!$D$5:$D$204,$J20,'İş Planı'!$O$5:$O$204,"Gecikmiş")+COUNTIFS('İş Planı'!$E$5:$E$204,$J20,'İş Planı'!$O$5:$O$204,"Gecikmiş")+COUNTIFS('İş Planı'!$F$5:$F$204,$J20,'İş Planı'!$O$5:$O$204,"Gecikmiş")+COUNTIFS('İş Planı'!$G$5:$G$204,$J20,'İş Planı'!$O$5:$O$204,"Gecikmiş"))
J21: =IF($D21="","",$D21) | K21: =IF($J21="","",COUNTIF('İş Planı'!$D$5:$D$204,$J21)+COUNTIF('İş Planı'!$E$5:$E$204,$J21)+COUNTIF('İş Planı'!$F$5:$F$204,$J21)+COUNTIF('İş Planı'!$G$5:$G$204,$J21)) | L21: =IF($J21="","",SUMIF('İş Planı'!$D$5:$D$204,$J21,'İş Planı'!$K$5:$K$204)+SUMIF('İş Planı'!$E$5:$E$204,$J21,'İş Planı'!$K$5:$K$204)+SUMIF('İş Planı'!$F$5:$F$204,$J21,'İş Planı'!$K$5:$K$204)+SUMIF('İş Planı'!$G$5:$G$204,$J21,'İş Planı'!$K$5:$K$204)) | M21: =IF($J21="","",SUMIFS('İş Planı'!$K$5:$K$204,'İş Planı'!$D$5:$D$204,$J21,'İş Planı'!$O$5:$O$204,"<>Tamamlandı")+SUMIFS('İş Planı'!$K$5:$K$204,'İş Planı'!$E$5:$E$204,$J21,'İş Planı'!$O$5:$O$204,"<>Tamamlandı")+SUMIFS('İş Planı'!$K$5:$K$204,'İş Planı'!$F$5:$F$204,$J21,'İş Planı'!$O$5:$O$204,"<>Tamamlandı")+SUMIFS('İş Planı'!$K$5:$K$204,'İş Planı'!$G$5:$G$204,$J21,'İş Planı'!$O$5:$O$204,"<>Tamamlandı")) | N21: =IF($J21="","",COUNTIFS('İş Planı'!$D$5:$D$204,$J21,'İş Planı'!$O$5:$O$204,"Gecikmiş")+COUNTIFS('İş Planı'!$E$5:$E$204,$J21,'İş Planı'!$O$5:$O$204,"Gecikmiş")+COUNTIFS('İş Planı'!$F$5:$F$204,$J21,'İş Planı'!$O$5:$O$204,"Gecikmiş")+COUNTIFS('İş Planı'!$G$5:$G$204,$J21,'İş Planı'!$O$5:$O$204,"Gecikmiş"))
J22: =IF($D22="","",$D22) | K22: =IF($J22="","",COUNTIF('İş Planı'!$D$5:$D$204,$J22)+COUNTIF('İş Planı'!$E$5:$E$204,$J22)+COUNTIF('İş Planı'!$F$5:$F$204,$J22)+COUNTIF('İş Planı'!$G$5:$G$204,$J22)) | L22: =IF($J22="","",SUMIF('İş Planı'!$D$5:$D$204,$J22,'İş Planı'!$K$5:$K$204)+SUMIF('İş Planı'!$E$5:$E$204,$J22,'İş Planı'!$K$5:$K$204)+SUMIF('İş Planı'!$F$5:$F$204,$J22,'İş Planı'!$K$5:$K$204)+SUMIF('İş Planı'!$G$5:$G$204,$J22,'İş Planı'!$K$5:$K$204)) | M22: =IF($J22="","",SUMIFS('İş Planı'!$K$5:$K$204,'İş Planı'!$D$5:$D$204,$J22,'İş Planı'!$O$5:$O$204,"<>Tamamlandı")+SUMIFS('İş Planı'!$K$5:$K$204,'İş Planı'!$E$5:$E$204,$J22,'İş Planı'!$O$5:$O$204,"<>Tamamlandı")+SUMIFS('İş Planı'!$K$5:$K$204,'İş Planı'!$F$5:$F$204,$J22,'İş Planı'!$O$5:$O$204,"<>Tamamlandı")+SUMIFS('İş Planı'!$K$5:$K$204,'İş Planı'!$G$5:$G$204,$J22,'İş Planı'!$O$5:$O$204,"<>Tamamlandı")) | N22: =IF($J22="","",COUNTIFS('İş Planı'!$D$5:$D$204,$J22,'İş Planı'!$O$5:$O$204,"Gecikmiş")+COUNTIFS('İş Planı'!$E$5:$E$204,$J22,'İş Planı'!$O$5:$O$204,"Gecikmiş")+COUNTIFS('İş Planı'!$F$5:$F$204,$J22,'İş Planı'!$O$5:$O$204,"Gecikmiş")+COUNTIFS('İş Planı'!$G$5:$G$204,$J22,'İş Planı'!$O$5:$O$204,"Gecikmiş"))
J23: =IF($D23="","",$D23) | K23: =IF($J23="","",COUNTIF('İş Planı'!$D$5:$D$204,$J23)+COUNTIF('İş Planı'!$E$5:$E$204,$J23)+COUNTIF('İş Planı'!$F$5:$F$204,$J23)+COUNTIF('İş Planı'!$G$5:$G$204,$J23)) | L23: =IF($J23="","",SUMIF('İş Planı'!$D$5:$D$204,$J23,'İş Planı'!$K$5:$K$204)+SUMIF('İş Planı'!$E$5:$E$204,$J23,'İş Planı'!$K$5:$K$204)+SUMIF('İş Planı'!$F$5:$F$204,$J23,'İş Planı'!$K$5:$K$204)+SUMIF('İş Planı'!$G$5:$G$204,$J23,'İş Planı'!$K$5:$K$204)) | M23: =IF($J23="","",SUMIFS('İş Planı'!$K$5:$K$204,'İş Planı'!$D$5:$D$204,$J23,'İş Planı'!$O$5:$O$204,"<>Tamamlandı")+SUMIFS('İş Planı'!$K$5:$K$204,'İş Planı'!$E$5:$E$204,$J23,'İş Planı'!$O$5:$O$204,"<>Tamamlandı")+SUMIFS('İş Planı'!$K$5:$K$204,'İş Planı'!$F$5:$F$204,$J23,'İş Planı'!$O$5:$O$204,"<>Tamamlandı")+SUMIFS('İş Planı'!$K$5:$K$204,'İş Planı'!$G$5:$G$204,$J23,'İş Planı'!$O$5:$O$204,"<>Tamamlandı")) | N23: =IF($J23="","",COUNTIFS('İş Planı'!$D$5:$D$204,$J23,'İş Planı'!$O$5:$O$204,"Gecikmiş")+COUNTIFS('İş Planı'!$E$5:$E$204,$J23,'İş Planı'!$O$5:$O$204,"Gecikmiş")+COUNTIFS('İş Planı'!$F$5:$F$204,$J23,'İş Planı'!$O$5:$O$204,"Gecikmiş")+COUNTIFS('İş Planı'!$G$5:$G$204,$J23,'İş Planı'!$O$5:$O$204,"Gecikmiş"))
J24: =IF($D24="","",$D24) | K24: =IF($J24="","",COUNTIF('İş Planı'!$D$5:$D$204,$J24)+COUNTIF('İş Planı'!$E$5:$E$204,$J24)+COUNTIF('İş Planı'!$F$5:$F$204,$J24)+COUNTIF('İş Planı'!$G$5:$G$204,$J24)) | L24: =IF($J24="","",SUMIF('İş Planı'!$D$5:$D$204,$J24,'İş Planı'!$K$5:$K$204)+SUMIF('İş Planı'!$E$5:$E$204,$J24,'İş Planı'!$K$5:$K$204)+SUMIF('İş Planı'!$F$5:$F$204,$J24,'İş Planı'!$K$5:$K$204)+SUMIF('İş Planı'!$G$5:$G$204,$J24,'İş Planı'!$K$5:$K$204)) | M24: =IF($J24="","",SUMIFS('İş Planı'!$K$5:$K$204,'İş Planı'!$D$5:$D$204,$J24,'İş Planı'!$O$5:$O$204,"<>Tamamlandı")+SUMIFS('İş Planı'!$K$5:$K$204,'İş Planı'!$E$5:$E$204,$J24,'İş Planı'!$O$5:$O$204,"<>Tamamlandı")+SUMIFS('İş Planı'!$K$5:$K$204,'İş Planı'!$F$5:$F$204,$J24,'İş Planı'!$O$5:$O$204,"<>Tamamlandı")+SUMIFS('İş Planı'!$K$5:$K$204,'İş Planı'!$G$5:$G$204,$J24,'İş Planı'!$O$5:$O$204,"<>Tamamlandı")) | N24: =IF($J24="","",COUNTIFS('İş Planı'!$D$5:$D$204,$J24,'İş Planı'!$O$5:$O$204,"Gecikmiş")+COUNTIFS('İş Planı'!$E$5:$E$204,$J24,'İş Planı'!$O$5:$O$204,"Gecikmiş")+COUNTIFS('İş Planı'!$F$5:$F$204,$J24,'İş Planı'!$O$5:$O$204,"Gecikmiş")+COUNTIFS('İş Planı'!$G$5:$G$204,$J24,'İş Planı'!$O$5:$O$204,"Gecikmiş"))
J25: =IF($D25="","",$D25) | K25: =IF($J25="","",COUNTIF('İş Planı'!$D$5:$D$204,$J25)+COUNTIF('İş Planı'!$E$5:$E$204,$J25)+COUNTIF('İş Planı'!$F$5:$F$204,$J25)+COUNTIF('İş Planı'!$G$5:$G$204,$J25)) | L25: =IF($J25="","",SUMIF('İş Planı'!$D$5:$D$204,$J25,'İş Planı'!$K$5:$K$204)+SUMIF('İş Planı'!$E$5:$E$204,$J25,'İş Planı'!$K$5:$K$204)+SUMIF('İş Planı'!$F$5:$F$204,$J25,'İş Planı'!$K$5:$K$204)+SUMIF('İş Planı'!$G$5:$G$204,$J25,'İş Planı'!$K$5:$K$204)) | M25: =IF($J25="","",SUMIFS('İş Planı'!$K$5:$K$204,'İş Planı'!$D$5:$D$204,$J25,'İş Planı'!$O$5:$O$204,"<>Tamamlandı")+SUMIFS('İş Planı'!$K$5:$K$204,'İş Planı'!$E$5:$E$204,$J25,'İş Planı'!$O$5:$O$204,"<>Tamamlandı")+SUMIFS('İş Planı'!$K$5:$K$204,'İş Planı'!$F$5:$F$204,$J25,'İş Planı'!$O$5:$O$204,"<>Tamamlandı")+SUMIFS('İş Planı'!$K$5:$K$204,'İş Planı'!$G$5:$G$204,$J25,'İş Planı'!$O$5:$O$204,"<>Tamamlandı")) | N25: =IF($J25="","",COUNTIFS('İş Planı'!$D$5:$D$204,$J25,'İş Planı'!$O$5:$O$204,"Gecikmiş")+COUNTIFS('İş Planı'!$E$5:$E$204,$J25,'İş Planı'!$O$5:$O$204,"Gecikmiş")+COUNTIFS('İş Planı'!$F$5:$F$204,$J25,'İş Planı'!$O$5:$O$204,"Gecikmiş")+COUNTIFS('İş Planı'!$G$5:$G$204,$J25,'İş Planı'!$O$5:$O$204,"Gecikmiş"))
J26: =IF($D26="","",$D26) | K26: =IF($J26="","",COUNTIF('İş Planı'!$D$5:$D$204,$J26)+COUNTIF('İş Planı'!$E$5:$E$204,$J26)+COUNTIF('İş Planı'!$F$5:$F$204,$J26)+COUNTIF('İş Planı'!$G$5:$G$204,$J26)) | L26: =IF($J26="","",SUMIF('İş Planı'!$D$5:$D$204,$J26,'İş Planı'!$K$5:$K$204)+SUMIF('İş Planı'!$E$5:$E$204,$J26,'İş Planı'!$K$5:$K$204)+SUMIF('İş Planı'!$F$5:$F$204,$J26,'İş Planı'!$K$5:$K$204)+SUMIF('İş Planı'!$G$5:$G$204,$J26,'İş Planı'!$K$5:$K$204)) | M26: =IF($J26="","",SUMIFS('İş Planı'!$K$5:$K$204,'İş Planı'!$D$5:$D$204,$J26,'İş Planı'!$O$5:$O$204,"<>Tamamlandı")+SUMIFS('İş Planı'!$K$5:$K$204,'İş Planı'!$E$5:$E$204,$J26,'İş Planı'!$O$5:$O$204,"<>Tamamlandı")+SUMIFS('İş Planı'!$K$5:$K$204,'İş Planı'!$F$5:$F$204,$J26,'İş Planı'!$O$5:$O$204,"<>Tamamlandı")+SUMIFS('İş Planı'!$K$5:$K$204,'İş Planı'!$G$5:$G$204,$J26,'İş Planı'!$O$5:$O$204,"<>Tamamlandı")) | N26: =IF($J26="","",COUNTIFS('İş Planı'!$D$5:$D$204,$J26,'İş Planı'!$O$5:$O$204,"Gecikmiş")+COUNTIFS('İş Planı'!$E$5:$E$204,$J26,'İş Planı'!$O$5:$O$204,"Gecikmiş")+COUNTIFS('İş Planı'!$F$5:$F$204,$J26,'İş Planı'!$O$5:$O$204,"Gecikmiş")+COUNTIFS('İş Planı'!$G$5:$G$204,$J26,'İş Planı'!$O$5:$O$204,"Gecikmiş"))
J27: =IF($D27="","",$D27) | K27: =IF($J27="","",COUNTIF('İş Planı'!$D$5:$D$204,$J27)+COUNTIF('İş Planı'!$E$5:$E$204,$J27)+COUNTIF('İş Planı'!$F$5:$F$204,$J27)+COUNTIF('İş Planı'!$G$5:$G$204,$J27)) | L27: =IF($J27="","",SUMIF('İş Planı'!$D$5:$D$204,$J27,'İş Planı'!$K$5:$K$204)+SUMIF('İş Planı'!$E$5:$E$204,$J27,'İş Planı'!$K$5:$K$204)+SUMIF('İş Planı'!$F$5:$F$204,$J27,'İş Planı'!$K$5:$K$204)+SUMIF('İş Planı'!$G$5:$G$204,$J27,'İş Planı'!$K$5:$K$204)) | M27: =IF($J27="","",SUMIFS('İş Planı'!$K$5:$K$204,'İş Planı'!$D$5:$D$204,$J27,'İş Planı'!$O$5:$O$204,"<>Tamamlandı")+SUMIFS('İş Planı'!$K$5:$K$204,'İş Planı'!$E$5:$E$204,$J27,'İş Planı'!$O$5:$O$204,"<>Tamamlandı")+SUMIFS('İş Planı'!$K$5:$K$204,'İş Planı'!$F$5:$F$204,$J27,'İş Planı'!$O$5:$O$204,"<>Tamamlandı")+SUMIFS('İş Planı'!$K$5:$K$204,'İş Planı'!$G$5:$G$204,$J27,'İş Planı'!$O$5:$O$204,"<>Tamamlandı")) | N27: =IF($J27="","",COUNTIFS('İş Planı'!$D$5:$D$204,$J27,'İş Planı'!$O$5:$O$204,"Gecikmiş")+COUNTIFS('İş Planı'!$E$5:$E$204,$J27,'İş Planı'!$O$5:$O$204,"Gecikmiş")+COUNTIFS('İş Planı'!$F$5:$F$204,$J27,'İş Planı'!$O$5:$O$204,"Gecikmiş")+COUNTIFS('İş Planı'!$G$5:$G$204,$J27,'İş Planı'!$O$5:$O$204,"Gecikmiş"))
J28: =IF($D28="","",$D28) | K28: =IF($J28="","",COUNTIF('İş Planı'!$D$5:$D$204,$J28)+COUNTIF('İş Planı'!$E$5:$E$204,$J28)+COUNTIF('İş Planı'!$F$5:$F$204,$J28)+COUNTIF('İş Planı'!$G$5:$G$204,$J28)) | L28: =IF($J28="","",SUMIF('İş Planı'!$D$5:$D$204,$J28,'İş Planı'!$K$5:$K$204)+SUMIF('İş Planı'!$E$5:$E$204,$J28,'İş Planı'!$K$5:$K$204)+SUMIF('İş Planı'!$F$5:$F$204,$J28,'İş Planı'!$K$5:$K$204)+SUMIF('İş Planı'!$G$5:$G$204,$J28,'İş Planı'!$K$5:$K$204)) | M28: =IF($J28="","",SUMIFS('İş Planı'!$K$5:$K$204,'İş Planı'!$D$5:$D$204,$J28,'İş Planı'!$O$5:$O$204,"<>Tamamlandı")+SUMIFS('İş Planı'!$K$5:$K$204,'İş Planı'!$E$5:$E$204,$J28,'İş Planı'!$O$5:$O$204,"<>Tamamlandı")+SUMIFS('İş Planı'!$K$5:$K$204,'İş Planı'!$F$5:$F$204,$J28,'İş Planı'!$O$5:$O$204,"<>Tamamlandı")+SUMIFS('İş Planı'!$K$5:$K$204,'İş Planı'!$G$5:$G$204,$J28,'İş Planı'!$O$5:$O$204,"<>Tamamlandı")) | N28: =IF($J28="","",COUNTIFS('İş Planı'!$D$5:$D$204,$J28,'İş Planı'!$O$5:$O$204,"Gecikmiş")+COUNTIFS('İş Planı'!$E$5:$E$204,$J28,'İş Planı'!$O$5:$O$204,"Gecikmiş")+COUNTIFS('İş Planı'!$F$5:$F$204,$J28,'İş Planı'!$O$5:$O$204,"Gecikmiş")+COUNTIFS('İş Planı'!$G$5:$G$204,$J28,'İş Planı'!$O$5:$O$204,"Gecikmiş"))
... J43: =IF($D43="","",$D43) | K43: =IF($J43="","",COUNTIF('İş Planı'!$D$5:$D$204,$J43)+COUNTIF('İş Planı'!$E$5:$E$204,$J43)+COUNTIF('İş Planı'!$F$5:$F$204,$J43)+COUNTIF('İş Planı'!$G$5:$G$204,$J43)) | L43: =IF($J43="","",SUMIF('İş Planı'!$D$5:$D$204,$J43,'İş Planı'!$K$5:$K$204)+SUMIF('İş Planı'!$E$5:$E$204,$J43,'İş Planı'!$K$5:$K$204)+SUMIF('İş Planı'!$F$5:$F$204,$J43,'İş Planı'!$K$5:$K$204)+SUMIF('İş Planı'!$G$5:$G$204,$J43,'İş Planı'!$K$5:$K$204)) | M43: =IF($J43="","",SUMIFS('İş Planı'!$K$5:$K$204,'İş Planı'!$D$5:$D$204,$J43,'İş Planı'!$O$5:$O$204,"<>Tamamlandı")+SUMIFS('İş Planı'!$K$5:$K$204,'İş Planı'!$E$5:$E$204,$J43,'İş Planı'!$O$5:$O$204,"<>Tamamlandı")+SUMIFS('İş Planı'!$K$5:$K$204,'İş Planı'!$F$5:$F$204,$J43,'İş Planı'!$O$5:$O$204,"<>Tamamlandı")+SUMIFS('İş Planı'!$K$5:$K$204,'İş Planı'!$G$5:$G$204,$J43,'İş Planı'!$O$5:$O$204,"<>Tamamlandı")) | N43: =IF($J43="","",COUNTIFS('İş Planı'!$D$5:$D$204,$J43,'İş Planı'!$O$5:$O$204,"Gecikmiş")+COUNTIFS('İş Planı'!$E$5:$E$204,$J43,'İş Planı'!$O$5:$O$204,"Gecikmiş")+COUNTIFS('İş Planı'!$F$5:$F$204,$J43,'İş Planı'!$O$5:$O$204,"Gecikmiş")+COUNTIFS('İş Planı'!$G$5:$G$204,$J43,'İş Planı'!$O$5:$O$204,"Gecikmiş"))
J44: TOPLAM | K44: =SUM(K4:K43) -> 108 | L44: =SUM(L4:L43) -> 1282 | M44: =SUM(M4:M43) -> 1123 | N44: =SUM(N4:N43) -> 19
B60: Denetim Başlıkları, Kişiler ve Öncelik sütunları 'İş Planı' sayfasındaki açılır listeleri besler; ilgili sütundaki ilk boş hücreye yazmanız yeterlidir. Durum (referans) açılır liste DEĞİLDİR - durum İlerleme % ve tarihlerden otomatik hesaplanır. KİŞİ BAZLI GÜN YÜKÜ: gün sayısı Süre (Gün) sütunundan gelir (Bitiş - Başlangıç + 1). Sorumlu 1-4'ün dördü birden sayılır; bir işte iki kişi varsa o işin tüm günleri ikisine de yazılır (adam-gün değil, kişi başı yük). Tarihi girilmemiş işler gün üretmez, yalnızca İş Sayısı'na girer.

Sheet Hesap
A1: Bu sayfa Yönetici Özeti grafiklerinin veri kaynağıdır. Elle değiştirmeyin; tüm hücreler İş Planı'ndan hesaplanır. | E1: Durum | F1: Adet | H1: Ay | I1: Ay Başı | J1: Aktif İş | L1: Sıra | M1: İş Kalemi | N1: Gecikme (Gün) | T1: KPI | W1: Denetim Başlığı | X1: Tamamlanan | Y1: Devam Eden | Z1: Gecikmiş | AB1: Hafta | AC1: Planlanan (Küm.) | AD1: Gerçekleşen (Küm.) | AF1: Ay | AG1: Ay Sonu | AH1: Planlanan (Küm.) | AI1: Gerçekleşen (Küm.) | AK1: Kişi | AL1: Açık İş | AM1: Gecikmiş | AO1: Gecikme Aralığı | AP1: Yüksek | AQ1: Orta | AR1: Düşük | AS1: Öncelik girilmemiş | AU1: Mutabakat Durumu | AV1: Adet | AX1: Projeksiyon Geriliği | AY1: İş Sayısı
E2: Planlanan | F2: =COUNTIFS('İş Planı'!$O$5:$O$204,E2,'İş Planı'!$C$5:$C$204,"<>") -> 62 | H2: Oca | I2: 46023 | J2: =SUMPRODUCT(('İş Planı'!$C$5:$C$204<>"")*('İş Planı'!$I$5:$I$204<>"")*('İş Planı'!$J$5:$J$204<>"")*('İş Planı'!$I$5:$I$204<=EOMONTH(I2,0))*('İş Planı'!$M$5:$M$204>=I2)) -> 0 | L2: 10 | M2: =IFERROR(IF(LARGE('İş Planı'!$W$5:$W$204,L2)<0.5,"",LEFT(SUBSTITUTE(SUBSTITUTE(TRIM(INDEX('İş Planı'!$C$5:$C$204,MATCH(LARGE('İş Planı'!$W$5:$W$204,L2),'İş Planı'!$W$5:$W$204,0))),CHAR(10)," "),CHAR(13)," "),45)),"") -> 4.1.3 Yetkilendirme | N2: =IFERROR(IF(LARGE('İş Planı'!$W$5:$W$204,L2)<0.5,0,INT(LARGE('İş Planı'!$W$5:$W$204,L2))),0) -> 5 | T2: Toplam İş Kalemi | U2: =COUNTA('İş Planı'!$C$5:$C$204) -> 95 | W2: =IFERROR(INDEX(Listeler!$B$4:$B$43,SMALL($BB$4:$BB$43,22-ROW())),"") | X2: =IF($W2="","",IF(COUNTIFS('İş Planı'!$B$5:$B$204,$W2,'İş Planı'!$O$5:$O$204,"Tamamlandı")=0,"",COUNTIFS('İş Planı'!$B$5:$B$204,$W2,'İş Planı'!$O$5:$O$204,"Tamamlandı"))) | Y2: =IF($W2="","",IF(COUNTIFS('İş Planı'!$B$5:$B$204,$W2,'İş Planı'!$O$5:$O$204,"Devam Ediyor")=0,"",COUNTIFS('İş Planı'!$B$5:$B$204,$W2,'İş Planı'!$O$5:$O$204,"Devam Ediyor"))) | Z2: =IF($W2="","",IF(COUNTIFS('İş Planı'!$B$5:$B$204,$W2,'İş Planı'!$O$5:$O$204,"Gecikmiş")=0,"",COUNTIFS('İş Planı'!$B$5:$B$204,$W2,'İş Planı'!$O$5:$O$204,"Gecikmiş"))) | AB2: 46029 | AC2: =SUMPRODUCT(('İş Planı'!$C$5:$C$204<>"")*('İş Planı'!$M$5:$M$204<>"")*('İş Planı'!$M$5:$M$204<=AB2)) -> 0 | AD2: =SUMPRODUCT(('İş Planı'!$C$5:$C$204<>"")*('İş Planı'!$M$5:$M$204<>"")*('İş Planı'!$M$5:$M$204<=AB2)*('İş Planı'!$O$5:$O$204="Tamamlandı")) -> 0 | AF2: Oca | AG2: 46053 | AH2: =SUMPRODUCT(('İş Planı'!$C$5:$C$204<>"")*('İş Planı'!$M$5:$M$204<>"")*('İş Planı'!$M$5:$M$204<=AG2)) -> 0 | AI2: =SUMPRODUCT(('İş Planı'!$C$5:$C$204<>"")*('İş Planı'!$M$5:$M$204<>"")*('İş Planı'!$M$5:$M$204<=AG2)*('İş Planı'!$O$5:$O$204="Tamamlandı")) -> 0 | AK2: =IFERROR(INDEX(Listeler!$D$4:$D$43,SMALL($BD$4:$BD$43,22-ROW())),"") | AL2: =IF($AK2="","",IF(COUNTIFS('İş Planı'!$D$5:$D$204,$AK2,'İş Planı'!$O$5:$O$204,"Planlanan")+COUNTIFS('İş Planı'!$E$5:$E$204,$AK2,'İş Planı'!$O$5:$O$204,"Planlanan")+COUNTIFS('İş Planı'!$F$5:$F$204,$AK2,'İş Planı'!$O$5:$O$204,"Planlanan")+COUNTIFS('İş Planı'!$G$5:$G$204,$AK2,'İş Planı'!$O$5:$O$204,"Planlanan")+COUNTIFS('İş Planı'!$D$5:$D$204,$AK2,'İş Planı'!$O$5:$O$204,"Devam Ediyor")+COUNTIFS('İş Planı'!$E$5:$E$204,$AK2,'İş Planı'!$O$5:$O$204,"Devam Ediyor")+COUNTIFS('İş Planı'!$F$5:$F$204,$AK2,'İş Planı'!$O$5:$O$204,"Devam Ediyor")+COUNTIFS('İş Planı'!$G$5:$G$204,$AK2,'İş Planı'!$O$5:$O$204,"Devam Ediyor")=0,"",COUNTIFS('İş Planı'!$D$5:$D$204,$AK2,'İş Planı'!$O$5:$O$204,"Planlanan")+COUNTIFS('İş Planı'!$E$5:$E$204,$AK2,'İş Planı'!$O$5:$O$204,"Planlanan")+COUNTIFS('İş Planı'!$F$5:$F$204,$AK2,'İş Planı'!$O$5:$O$204,"Planlanan")+COUNTIFS('İş Planı'!$G$5:$G$204,$AK2,'İş Planı'!$O$5:$O$204,"Planlanan")+COUNTIFS('İş Planı'!$D$5:$D$204,$AK2,'İş Planı'!$O$5:$O$204,"Devam Ediyor")+COUNTIFS('İş Planı'!$E$5:$E$204,$AK2,'İş Planı'!$O$5:$O$204,"Devam Ediyor")+COUNTIFS('İş Planı'!$F$5:$F$204,$AK2,'İş Planı'!$O$5:$O$204,"Devam Ediyor")+COUNTIFS('İş Planı'!$G$5:$G$204,$AK2,'İş Planı'!$O$5:$O$204,"Devam Ediyor"))) | AM2: =IF($AK2="","",IF(COUNTIFS('İş Planı'!$D$5:$D$204,$AK2,'İş Planı'!$O$5:$O$204,"Gecikmiş")+COUNTIFS('İş Planı'!$E$5:$E$204,$AK2,'İş Planı'!$O$5:$O$204,"Gecikmiş")+COUNTIFS('İş Planı'!$F$5:$F$204,$AK2,'İş Planı'!$O$5:$O$204,"Gecikmiş")+COUNTIFS('İş Planı'!$G$5:$G$204,$AK2,'İş Planı'!$O$5:$O$204,"Gecikmiş")=0,"",COUNTIFS('İş Planı'!$D$5:$D$204,$AK2,'İş Planı'!$O$5:$O$204,"Gecikmiş")+COUNTIFS('İş Planı'!$E$5:$E$204,$AK2,'İş Planı'!$O$5:$O$204,"Gecikmiş")+COUNTIFS('İş Planı'!$F$5:$F$204,$AK2,'İş Planı'!$O$5:$O$204,"Gecikmiş")+COUNTIFS('İş Planı'!$G$5:$G$204,$AK2,'İş Planı'!$O$5:$O$204,"Gecikmiş"))) | AO2: 1-7 gün | AP2: =IF(COUNTIFS('İş Planı'!$X$5:$X$204,">=1",'İş Planı'!$X$5:$X$204,"<=7",'İş Planı'!$H$5:$H$204,"Yüksek")=0,"",COUNTIFS('İş Planı'!$X$5:$X$204,">=1",'İş Planı'!$X$5:$X$204,"<=7",'İş Planı'!$H$5:$H$204,"Yüksek")) | AQ2: =IF(COUNTIFS('İş Planı'!$X$5:$X$204,">=1",'İş Planı'!$X$5:$X$204,"<=7",'İş Planı'!$H$5:$H$204,"Orta")=0,"",COUNTIFS('İş Planı'!$X$5:$X$204,">=1",'İş Planı'!$X$5:$X$204,"<=7",'İş Planı'!$H$5:$H$204,"Orta")) -> 7 | AR2: =IF(COUNTIFS('İş Planı'!$X$5:$X$204,">=1",'İş Planı'!$X$5:$X$204,"<=7",'İş Planı'!$H$5:$H$204,"Düşük")=0,"",COUNTIFS('İş Planı'!$X$5:$X$204,">=1",'İş Planı'!$X$5:$X$204,"<=7",'İş Planı'!$H$5:$H$204,"Düşük")) | AS2: =IF(COUNTIFS('İş Planı'!$X$5:$X$204,">=1",'İş Planı'!$X$5:$X$204,"<=7",'İş Planı'!$H$5:$H$204,"")=0,"",COUNTIFS('İş Planı'!$X$5:$X$204,">=1",'İş Planı'!$X$5:$X$204,"<=7",'İş Planı'!$H$5:$H$204,"")) -> 2 | AU2: Mutabakatı yapıldı | AV2: =COUNTIFS('İş Planı'!$R$5:$R$204,"<>",'İş Planı'!$C$5:$C$204,"<>") -> 0 | AX2: %30-50 geride | AY2: =COUNTIFS('İş Planı'!$Y$5:$Y$204,">0.3",'İş Planı'!$Y$5:$Y$204,"<=0.5") -> 10
A3: Bugün | B3: =TODAY() -> 46300 | E3: Devam Ediyor | F3: =COUNTIFS('İş Planı'!$O$5:$O$204,E3,'İş Planı'!$C$5:$C$204,"<>") -> 12 | H3: Şub | I3: 46054 | J3: =SUMPRODUCT(('İş Planı'!$C$5:$C$204<>"")*('İş Planı'!$I$5:$I$204<>"")*('İş Planı'!$J$5:$J$204<>"")*('İş Planı'!$I$5:$I$204<=EOMONTH(I3,0))*('İş Planı'!$M$5:$M$204>=I3)) -> 0 | L3: 9 | M3: =IFERROR(IF(LARGE('İş Planı'!$W$5:$W$204,L3)<0.5,"",LEFT(SUBSTITUTE(SUBSTITUTE(TRIM(INDEX('İş Planı'!$C$5:$C$204,MATCH(LARGE('İş Planı'!$W$5:$W$204,L3),'İş Planı'!$W$5:$W$204,0))),CHAR(10)," "),CHAR(13)," "),45)),"") -> Hesapkurdu firması ağustos ayında Glasshouse' | N3: =IFERROR(IF(LARGE('İş Planı'!$W$5:$W$204,L3)<0.5,0,INT(LARGE('İş Planı'!$W$5:$W$204,L3))),0) -> 6 | T3: Tamamlandı | U3: =F4 -> 6 | W3: =IFERROR(INDEX(Listeler!$B$4:$B$43,SMALL($BB$4:$BB$43,22-ROW())),"") | X3: =IF($W3="","",IF(COUNTIFS('İş Planı'!$B$5:$B$204,$W3,'İş Planı'!$O$5:$O$204,"Tamamlandı")=0,"",COUNTIFS('İş Planı'!$B$5:$B$204,$W3,'İş Planı'!$O$5:$O$204,"Tamamlandı"))) | Y3: =IF($W3="","",IF(COUNTIFS('İş Planı'!$B$5:$B$204,$W3,'İş Planı'!$O$5:$O$204,"Devam Ediyor")=0,"",COUNTIFS('İş Planı'!$B$5:$B$204,$W3,'İş Planı'!$O$5:$O$204,"Devam Ediyor"))) | Z3: =IF($W3="","",IF(COUNTIFS('İş Planı'!$B$5:$B$204,$W3,'İş Planı'!$O$5:$O$204,"Gecikmiş")=0,"",COUNTIFS('İş Planı'!$B$5:$B$204,$W3,'İş Planı'!$O$5:$O$204,"Gecikmiş"))) | AB3: 46036 | AC3: =SUMPRODUCT(('İş Planı'!$C$5:$C$204<>"")*('İş Planı'!$M$5:$M$204<>"")*('İş Planı'!$M$5:$M$204<=AB3)) -> 0 | AD3: =SUMPRODUCT(('İş Planı'!$C$5:$C$204<>"")*('İş Planı'!$M$5:$M$204<>"")*('İş Planı'!$M$5:$M$204<=AB3)*('İş Planı'!$O$5:$O$204="Tamamlandı")) -> 0 | AF3: Şub | AG3: 46081 | AH3: =SUMPRODUCT(('İş Planı'!$C$5:$C$204<>"")*('İş Planı'!$M$5:$M$204<>"")*('İş Planı'!$M$5:$M$204<=AG3)) -> 0 | AI3: =SUMPRODUCT(('İş Planı'!$C$5:$C$204<>"")*('İş Planı'!$M$5:$M$204<>"")*('İş Planı'!$M$5:$M$204<=AG3)*('İş Planı'!$O$5:$O$204="Tamamlandı")) -> 0 | AK3: =IFERROR(INDEX(Listeler!$D$4:$D$43,SMALL($BD$4:$BD$43,22-ROW())),"") | AL3: =IF($AK3="","",IF(COUNTIFS('İş Planı'!$D$5:$D$204,$AK3,'İş Planı'!$O$5:$O$204,"Planlanan")+COUNTIFS('İş Planı'!$E$5:$E$204,$AK3,'İş Planı'!$O$5:$O$204,"Planlanan")+COUNTIFS('İş Planı'!$F$5:$F$204,$AK3,'İş Planı'!$O$5:$O$204,"Planlanan")+COUNTIFS('İş Planı'!$G$5:$G$204,$AK3,'İş Planı'!$O$5:$O$204,"Planlanan")+COUNTIFS('İş Planı'!$D$5:$D$204,$AK3,'İş Planı'!$O$5:$O$204,"Devam Ediyor")+COUNTIFS('İş Planı'!$E$5:$E$204,$AK3,'İş Planı'!$O$5:$O$204,"Devam Ediyor")+COUNTIFS('İş Planı'!$F$5:$F$204,$AK3,'İş Planı'!$O$5:$O$204,"Devam Ediyor")+COUNTIFS('İş Planı'!$G$5:$G$204,$AK3,'İş Planı'!$O$5:$O$204,"Devam Ediyor")=0,"",COUNTIFS('İş Planı'!$D$5:$D$204,$AK3,'İş Planı'!$O$5:$O$204,"Planlanan")+COUNTIFS('İş Planı'!$E$5:$E$204,$AK3,'İş Planı'!$O$5:$O$204,"Planlanan")+COUNTIFS('İş Planı'!$F$5:$F$204,$AK3,'İş Planı'!$O$5:$O$204,"Planlanan")+COUNTIFS('İş Planı'!$G$5:$G$204,$AK3,'İş Planı'!$O$5:$O$204,"Planlanan")+COUNTIFS('İş Planı'!$D$5:$D$204,$AK3,'İş Planı'!$O$5:$O$204,"Devam Ediyor")+COUNTIFS('İş Planı'!$E$5:$E$204,$AK3,'İş Planı'!$O$5:$O$204,"Devam Ediyor")+COUNTIFS('İş Planı'!$F$5:$F$204,$AK3,'İş Planı'!$O$5:$O$204,"Devam Ediyor")+COUNTIFS('İş Planı'!$G$5:$G$204,$AK3,'İş Planı'!$O$5:$O$204,"Devam Ediyor"))) | AM3: =IF($AK3="","",IF(COUNTIFS('İş Planı'!$D$5:$D$204,$AK3,'İş Planı'!$O$5:$O$204,"Gecikmiş")+COUNTIFS('İş Planı'!$E$5:$E$204,$AK3,'İş Planı'!$O$5:$O$204,"Gecikmiş")+COUNTIFS('İş Planı'!$F$5:$F$204,$AK3,'İş Planı'!$O$5:$O$204,"Gecikmiş")+COUNTIFS('İş Planı'!$G$5:$G$204,$AK3,'İş Planı'!$O$5:$O$204,"Gecikmiş")=0,"",COUNTIFS('İş Planı'!$D$5:$D$204,$AK3,'İş Planı'!$O$5:$O$204,"Gecikmiş")+COUNTIFS('İş Planı'!$E$5:$E$204,$AK3,'İş Planı'!$O$5:$O$204,"Gecikmiş")+COUNTIFS('İş Planı'!$F$5:$F$204,$AK3,'İş Planı'!$O$5:$O$204,"Gecikmiş")+COUNTIFS('İş Planı'!$G$5:$G$204,$AK3,'İş Planı'!$O$5:$O$204,"Gecikmiş"))) | AO3: 8-30 gün | AP3: =IF(COUNTIFS('İş Planı'!$X$5:$X$204,">=8",'İş Planı'!$X$5:$X$204,"<=30",'İş Planı'!$H$5:$H$204,"Yüksek")=0,"",COUNTIFS('İş Planı'!$X$5:$X$204,">=8",'İş Planı'!$X$5:$X$204,"<=30",'İş Planı'!$H$5:$H$204,"Yüksek")) | AQ3: =IF(COUNTIFS('İş Planı'!$X$5:$X$204,">=8",'İş Planı'!$X$5:$X$204,"<=30",'İş Planı'!$H$5:$H$204,"Orta")=0,"",COUNTIFS('İş Planı'!$X$5:$X$204,">=8",'İş Planı'!$X$5:$X$204,"<=30",'İş Planı'!$H$5:$H$204,"Orta")) -> 6 | AR3: =IF(COUNTIFS('İş Planı'!$X$5:$X$204,">=8",'İş Planı'!$X$5:$X$204,"<=30",'İş Planı'!$H$5:$H$204,"Düşük")=0,"",COUNTIFS('İş Planı'!$X$5:$X$204,">=8",'İş Planı'!$X$5:$X$204,"<=30",'İş Planı'!$H$5:$H$204,"Düşük")) | AS3: =IF(COUNTIFS('İş Planı'!$X$5:$X$204,">=8",'İş Planı'!$X$5:$X$204,"<=30",'İş Planı'!$H$5:$H$204,"")=0,"",COUNTIFS('İş Planı'!$X$5:$X$204,">=8",'İş Planı'!$X$5:$X$204,"<=30",'İş Planı'!$H$5:$H$204,"")) | AU3: Süresi var | AV3: =COUNTIF('İş Planı'!$T$5:$T$204,"●*") -> 11 | AX3: %50-70 geride | AY3: =COUNTIFS('İş Planı'!$Y$5:$Y$204,">0.5",'İş Planı'!$Y$5:$Y$204,"<=0.7") -> 0 | BA3: Kullanılan başlık indeksi | BC3: Yükü olan kişi indeksi
A4: Tüm tarih karşılaştırmaları bu tek hücreyi okur. | E4: Tamamlandı | F4: =COUNTIFS('İş Planı'!$O$5:$O$204,E4,'İş Planı'!$C$5:$C$204,"<>") -> 6 | H4: Mar | I4: 46082 | J4: =SUMPRODUCT(('İş Planı'!$C$5:$C$204<>"")*('İş Planı'!$I$5:$I$204<>"")*('İş Planı'!$J$5:$J$204<>"")*('İş Planı'!$I$5:$I$204<=EOMONTH(I4,0))*('İş Planı'!$M$5:$M$204>=I4)) -> 0 | L4: 8 | M4: =IFERROR(IF(LARGE('İş Planı'!$W$5:$W$204,L4)<0.5,"",LEFT(SUBSTITUTE(SUBSTITUTE(TRIM(INDEX('İş Planı'!$C$5:$C$204,MATCH(LARGE('İş Planı'!$W$5:$W$204,L4),'İş Planı'!$W$5:$W$204,0))),CHAR(10)," "),CHAR(13)," "),45)),"") -> Madde 21 | N4: =IFERROR(IF(LARGE('İş Planı'!$W$5:$W$204,L4)<0.5,0,INT(LARGE('İş Planı'!$W$5:$W$204,L4))),0) -> 7 | T4: Devam Ediyor | U4: =F3 -> 12 | W4: =IFERROR(INDEX(Listeler!$B$4:$B$43,SMALL($BB$4:$BB$43,22-ROW())),"") | X4: =IF($W4="","",IF(COUNTIFS('İş Planı'!$B$5:$B$204,$W4,'İş Planı'!$O$5:$O$204,"Tamamlandı")=0,"",COUNTIFS('İş Planı'!$B$5:$B$204,$W4,'İş Planı'!$O$5:$O$204,"Tamamlandı"))) | Y4: =IF($W4="","",IF(COUNTIFS('İş Planı'!$B$5:$B$204,$W4,'İş Planı'!$O$5:$O$204,"Devam Ediyor")=0,"",COUNTIFS('İş Planı'!$B$5:$B$204,$W4,'İş Planı'!$O$5:$O$204,"Devam Ediyor"))) | Z4: =IF($W4="","",IF(COUNTIFS('İş Planı'!$B$5:$B$204,$W4,'İş Planı'!$O$5:$O$204,"Gecikmiş")=0,"",COUNTIFS('İş Planı'!$B$5:$B$204,$W4,'İş Planı'!$O$5:$O$204,"Gecikmiş"))) | AB4: 46043 | AC4: =SUMPRODUCT(('İş Planı'!$C$5:$C$204<>"")*('İş Planı'!$M$5:$M$204<>"")*('İş Planı'!$M$5:$M$204<=AB4)) -> 0 | AD4: =SUMPRODUCT(('İş Planı'!$C$5:$C$204<>"")*('İş Planı'!$M$5:$M$204<>"")*('İş Planı'!$M$5:$M$204<=AB4)*('İş Planı'!$O$5:$O$204="Tamamlandı")) -> 0 | AF4: Mar | AG4: 46112 | AH4: =SUMPRODUCT(('İş Planı'!$C$5:$C$204<>"")*('İş Planı'!$M$5:$M$204<>"")*('İş Planı'!$M$5:$M$204<=AG4)) -> 0 | AI4: =SUMPRODUCT(('İş Planı'!$C$5:$C$204<>"")*('İş Planı'!$M$5:$M$204<>"")*('İş Planı'!$M$5:$M$204<=AG4)*('İş Planı'!$O$5:$O$204="Tamamlandı")) -> 0 | AK4: =IFERROR(INDEX(Listeler!$D$4:$D$43,SMALL($BD$4:$BD$43,22-ROW())),"") | AL4: =IF($AK4="","",IF(COUNTIFS('İş Planı'!$D$5:$D$204,$AK4,'İş Planı'!$O$5:$O$204,"Planlanan")+COUNTIFS('İş Planı'!$E$5:$E$204,$AK4,'İş Planı'!$O$5:$O$204,"Planlanan")+COUNTIFS('İş Planı'!$F$5:$F$204,$AK4,'İş Planı'!$O$5:$O$204,"Planlanan")+COUNTIFS('İş Planı'!$G$5:$G$204,$AK4,'İş Planı'!$O$5:$O$204,"Planlanan")+COUNTIFS('İş Planı'!$D$5:$D$204,$AK4,'İş Planı'!$O$5:$O$204,"Devam Ediyor")+COUNTIFS('İş Planı'!$E$5:$E$204,$AK4,'İş Planı'!$O$5:$O$204,"Devam Ediyor")+COUNTIFS('İş Planı'!$F$5:$F$204,$AK4,'İş Planı'!$O$5:$O$204,"Devam Ediyor")+COUNTIFS('İş Planı'!$G$5:$G$204,$AK4,'İş Planı'!$O$5:$O$204,"Devam Ediyor")=0,"",COUNTIFS('İş Planı'!$D$5:$D$204,$AK4,'İş Planı'!$O$5:$O$204,"Planlanan")+COUNTIFS('İş Planı'!$E$5:$E$204,$AK4,'İş Planı'!$O$5:$O$204,"Planlanan")+COUNTIFS('İş Planı'!$F$5:$F$204,$AK4,'İş Planı'!$O$5:$O$204,"Planlanan")+COUNTIFS('İş Planı'!$G$5:$G$204,$AK4,'İş Planı'!$O$5:$O$204,"Planlanan")+COUNTIFS('İş Planı'!$D$5:$D$204,$AK4,'İş Planı'!$O$5:$O$204,"Devam Ediyor")+COUNTIFS('İş Planı'!$E$5:$E$204,$AK4,'İş Planı'!$O$5:$O$204,"Devam Ediyor")+COUNTIFS('İş Planı'!$F$5:$F$204,$AK4,'İş Planı'!$O$5:$O$204,"Devam Ediyor")+COUNTIFS('İş Planı'!$G$5:$G$204,$AK4,'İş Planı'!$O$5:$O$204,"Devam Ediyor"))) | AM4: =IF($AK4="","",IF(COUNTIFS('İş Planı'!$D$5:$D$204,$AK4,'İş Planı'!$O$5:$O$204,"Gecikmiş")+COUNTIFS('İş Planı'!$E$5:$E$204,$AK4,'İş Planı'!$O$5:$O$204,"Gecikmiş")+COUNTIFS('İş Planı'!$F$5:$F$204,$AK4,'İş Planı'!$O$5:$O$204,"Gecikmiş")+COUNTIFS('İş Planı'!$G$5:$G$204,$AK4,'İş Planı'!$O$5:$O$204,"Gecikmiş")=0,"",COUNTIFS('İş Planı'!$D$5:$D$204,$AK4,'İş Planı'!$O$5:$O$204,"Gecikmiş")+COUNTIFS('İş Planı'!$E$5:$E$204,$AK4,'İş Planı'!$O$5:$O$204,"Gecikmiş")+COUNTIFS('İş Planı'!$F$5:$F$204,$AK4,'İş Planı'!$O$5:$O$204,"Gecikmiş")+COUNTIFS('İş Planı'!$G$5:$G$204,$AK4,'İş Planı'!$O$5:$O$204,"Gecikmiş"))) | AO4: 31-90 gün | AP4: =IF(COUNTIFS('İş Planı'!$X$5:$X$204,">=31",'İş Planı'!$X$5:$X$204,"<=90",'İş Planı'!$H$5:$H$204,"Yüksek")=0,"",COUNTIFS('İş Planı'!$X$5:$X$204,">=31",'İş Planı'!$X$5:$X$204,"<=90",'İş Planı'!$H$5:$H$204,"Yüksek")) | AQ4: =IF(COUNTIFS('İş Planı'!$X$5:$X$204,">=31",'İş Planı'!$X$5:$X$204,"<=90",'İş Planı'!$H$5:$H$204,"Orta")=0,"",COUNTIFS('İş Planı'!$X$5:$X$204,">=31",'İş Planı'!$X$5:$X$204,"<=90",'İş Planı'!$H$5:$H$204,"Orta")) | AR4: =IF(COUNTIFS('İş Planı'!$X$5:$X$204,">=31",'İş Planı'!$X$5:$X$204,"<=90",'İş Planı'!$H$5:$H$204,"Düşük")=0,"",COUNTIFS('İş Planı'!$X$5:$X$204,">=31",'İş Planı'!$X$5:$X$204,"<=90",'İş Planı'!$H$5:$H$204,"Düşük")) | AS4: =IF(COUNTIFS('İş Planı'!$X$5:$X$204,">=31",'İş Planı'!$X$5:$X$204,"<=90",'İş Planı'!$H$5:$H$204,"")=0,"",COUNTIFS('İş Planı'!$X$5:$X$204,">=31",'İş Planı'!$X$5:$X$204,"<=90",'İş Planı'!$H$5:$H$204,"")) | AU4: Mutabakat gecikti | AV4: =COUNTIF('İş Planı'!$T$5:$T$204,"*gecikti*") -> 9 | AX4: %70+ geride | AY4: =COUNTIFS('İş Planı'!$Y$5:$Y$204,">0.7") -> 7 | BB4: =IF(Listeler!$B4="","",IF(COUNTIF('İş Planı'!$B$5:$B$204,Listeler!$B4)=0,"",ROW()-3)) -> 1 | BD4: =IF(Listeler!$D4="","",IF(COUNTIF('İş Planı'!$D$5:$D$204,Listeler!$D4)+COUNTIF('İş Planı'!$E$5:$E$204,Listeler!$D4)+COUNTIF('İş Planı'!$F$5:$F$204,Listeler!$D4)+COUNTIF('İş Planı'!$G$5:$G$204,Listeler!$D4)=0,"",ROW()-3)) -> 1
E5: Gecikmiş | F5: =COUNTIFS('İş Planı'!$O$5:$O$204,E5,'İş Planı'!$C$5:$C$204,"<>") -> 15 | H5: Nis | I5: 46113 | J5: =SUMPRODUCT(('İş Planı'!$C$5:$C$204<>"")*('İş Planı'!$I$5:$I$204<>"")*('İş Planı'!$J$5:$J$204<>"")*('İş Planı'!$I$5:$I$204<=EOMONTH(I5,0))*('İş Planı'!$M$5:$M$204>=I5)) -> 0 | L5: 7 | M5: =IFERROR(IF(LARGE('İş Planı'!$W$5:$W$204,L5)<0.5,"",LEFT(SUBSTITUTE(SUBSTITUTE(TRIM(INDEX('İş Planı'!$C$5:$C$204,MATCH(LARGE('İş Planı'!$W$5:$W$204,L5),'İş Planı'!$W$5:$W$204,0))),CHAR(10)," "),CHAR(13)," "),45)),"") -> Madde 10 | N5: =IFERROR(IF(LARGE('İş Planı'!$W$5:$W$204,L5)<0.5,0,INT(LARGE('İş Planı'!$W$5:$W$204,L5))),0) -> 7 | T5: Gecikmiş | U5: =F5 -> 15 | W5: =IFERROR(INDEX(Listeler!$B$4:$B$43,SMALL($BB$4:$BB$43,22-ROW())),"") | X5: =IF($W5="","",IF(COUNTIFS('İş Planı'!$B$5:$B$204,$W5,'İş Planı'!$O$5:$O$204,"Tamamlandı")=0,"",COUNTIFS('İş Planı'!$B$5:$B$204,$W5,'İş Planı'!$O$5:$O$204,"Tamamlandı"))) | Y5: =IF($W5="","",IF(COUNTIFS('İş Planı'!$B$5:$B$204,$W5,'İş Planı'!$O$5:$O$204,"Devam Ediyor")=0,"",COUNTIFS('İş Planı'!$B$5:$B$204,$W5,'İş Planı'!$O$5:$O$204,"Devam Ediyor"))) | Z5: =IF($W5="","",IF(COUNTIFS('İş Planı'!$B$5:$B$204,$W5,'İş Planı'!$O$5:$O$204,"Gecikmiş")=0,"",COUNTIFS('İş Planı'!$B$5:$B$204,$W5,'İş Planı'!$O$5:$O$204,"Gecikmiş"))) | AB5: 46050 | AC5: =SUMPRODUCT(('İş Planı'!$C$5:$C$204<>"")*('İş Planı'!$M$5:$M$204<>"")*('İş Planı'!$M$5:$M$204<=AB5)) -> 0 | AD5: =SUMPRODUCT(('İş Planı'!$C$5:$C$204<>"")*('İş Planı'!$M$5:$M$204<>"")*('İş Planı'!$M$5:$M$204<=AB5)*('İş Planı'!$O$5:$O$204="Tamamlandı")) -> 0 | AF5: Nis | AG5: 46142 | AH5: =SUMPRODUCT(('İş Planı'!$C$5:$C$204<>"")*('İş Planı'!$M$5:$M$204<>"")*('İş Planı'!$M$5:$M$204<=AG5)) -> 0 | AI5: =SUMPRODUCT(('İş Planı'!$C$5:$C$204<>"")*('İş Planı'!$M$5:$M$204<>"")*('İş Planı'!$M$5:$M$204<=AG5)*('İş Planı'!$O$5:$O$204="Tamamlandı")) -> 0 | AK5: =IFERROR(INDEX(Listeler!$D$4:$D$43,SMALL($BD$4:$BD$43,22-ROW())),"") | AL5: =IF($AK5="","",IF(COUNTIFS('İş Planı'!$D$5:$D$204,$AK5,'İş Planı'!$O$5:$O$204,"Planlanan")+COUNTIFS('İş Planı'!$E$5:$E$204,$AK5,'İş Planı'!$O$5:$O$204,"Planlanan")+COUNTIFS('İş Planı'!$F$5:$F$204,$AK5,'İş Planı'!$O$5:$O$204,"Planlanan")+COUNTIFS('İş Planı'!$G$5:$G$204,$AK5,'İş Planı'!$O$5:$O$204,"Planlanan")+COUNTIFS('İş Planı'!$D$5:$D$204,$AK5,'İş Planı'!$O$5:$O$204,"Devam Ediyor")+COUNTIFS('İş Planı'!$E$5:$E$204,$AK5,'İş Planı'!$O$5:$O$204,"Devam Ediyor")+COUNTIFS('İş Planı'!$F$5:$F$204,$AK5,'İş Planı'!$O$5:$O$204,"Devam Ediyor")+COUNTIFS('İş Planı'!$G$5:$G$204,$AK5,'İş Planı'!$O$5:$O$204,"Devam Ediyor")=0,"",COUNTIFS('İş Planı'!$D$5:$D$204,$AK5,'İş Planı'!$O$5:$O$204,"Planlanan")+COUNTIFS('İş Planı'!$E$5:$E$204,$AK5,'İş Planı'!$O$5:$O$204,"Planlanan")+COUNTIFS('İş Planı'!$F$5:$F$204,$AK5,'İş Planı'!$O$5:$O$204,"Planlanan")+COUNTIFS('İş Planı'!$G$5:$G$204,$AK5,'İş Planı'!$O$5:$O$204,"Planlanan")+COUNTIFS('İş Planı'!$D$5:$D$204,$AK5,'İş Planı'!$O$5:$O$204,"Devam Ediyor")+COUNTIFS('İş Planı'!$E$5:$E$204,$AK5,'İş Planı'!$O$5:$O$204,"Devam Ediyor")+COUNTIFS('İş Planı'!$F$5:$F$204,$AK5,'İş Planı'!$O$5:$O$204,"Devam Ediyor")+COUNTIFS('İş Planı'!$G$5:$G$204,$AK5,'İş Planı'!$O$5:$O$204,"Devam Ediyor"))) | AM5: =IF($AK5="","",IF(COUNTIFS('İş Planı'!$D$5:$D$204,$AK5,'İş Planı'!$O$5:$O$204,"Gecikmiş")+COUNTIFS('İş Planı'!$E$5:$E$204,$AK5,'İş Planı'!$O$5:$O$204,"Gecikmiş")+COUNTIFS('İş Planı'!$F$5:$F$204,$AK5,'İş Planı'!$O$5:$O$204,"Gecikmiş")+COUNTIFS('İş Planı'!$G$5:$G$204,$AK5,'İş Planı'!$O$5:$O$204,"Gecikmiş")=0,"",COUNTIFS('İş Planı'!$D$5:$D$204,$AK5,'İş Planı'!$O$5:$O$204,"Gecikmiş")+COUNTIFS('İş Planı'!$E$5:$E$204,$AK5,'İş Planı'!$O$5:$O$204,"Gecikmiş")+COUNTIFS('İş Planı'!$F$5:$F$204,$AK5,'İş Planı'!$O$5:$O$204,"Gecikmiş")+COUNTIFS('İş Planı'!$G$5:$G$204,$AK5,'İş Planı'!$O$5:$O$204,"Gecikmiş"))) | AO5: 90+ gün | AP5: =IF(COUNTIFS('İş Planı'!$X$5:$X$204,">=91",'İş Planı'!$H$5:$H$204,"Yüksek")=0,"",COUNTIFS('İş Planı'!$X$5:$X$204,">=91",'İş Planı'!$H$5:$H$204,"Yüksek")) | AQ5: =IF(COUNTIFS('İş Planı'!$X$5:$X$204,">=91",'İş Planı'!$H$5:$H$204,"Orta")=0,"",COUNTIFS('İş Planı'!$X$5:$X$204,">=91",'İş Planı'!$H$5:$H$204,"Orta")) | AR5: =IF(COUNTIFS('İş Planı'!$X$5:$X$204,">=91",'İş Planı'!$H$5:$H$204,"Düşük")=0,"",COUNTIFS('İş Planı'!$X$5:$X$204,">=91",'İş Planı'!$H$5:$H$204,"Düşük")) | AS5: =IF(COUNTIFS('İş Planı'!$X$5:$X$204,">=91",'İş Planı'!$H$5:$H$204,"")=0,"",COUNTIFS('İş Planı'!$X$5:$X$204,">=91",'İş Planı'!$H$5:$H$204,"")) | BB5: =IF(Listeler!$B5="","",IF(COUNTIF('İş Planı'!$B$5:$B$204,Listeler!$B5)=0,"",ROW()-3)) -> 2 | BD5: =IF(Listeler!$D5="","",IF(COUNTIF('İş Planı'!$D$5:$D$204,Listeler!$D5)+COUNTIF('İş Planı'!$E$5:$E$204,Listeler!$D5)+COUNTIF('İş Planı'!$F$5:$F$204,Listeler!$D5)+COUNTIF('İş Planı'!$G$5:$G$204,Listeler!$D5)=0,"",ROW()-3))
H6: May | I6: 46143 | J6: =SUMPRODUCT(('İş Planı'!$C$5:$C$204<>"")*('İş Planı'!$I$5:$I$204<>"")*('İş Planı'!$J$5:$J$204<>"")*('İş Planı'!$I$5:$I$204<=EOMONTH(I6,0))*('İş Planı'!$M$5:$M$204>=I6)) -> 0 | L6: 6 | M6: =IFERROR(IF(LARGE('İş Planı'!$W$5:$W$204,L6)<0.5,"",LEFT(SUBSTITUTE(SUBSTITUTE(TRIM(INDEX('İş Planı'!$C$5:$C$204,MATCH(LARGE('İş Planı'!$W$5:$W$204,L6),'İş Planı'!$W$5:$W$204,0))),CHAR(10)," "),CHAR(13)," "),45)),"") -> 3.1.7 Veri Sızıntısı Önleme | N6: =IFERROR(IF(LARGE('İş Planı'!$W$5:$W$204,L6)<0.5,0,INT(LARGE('İş Planı'!$W$5:$W$204,L6))),0) -> 12 | T6: Planlanan | U6: =F2 -> 62 | W6: =IFERROR(INDEX(Listeler!$B$4:$B$43,SMALL($BB$4:$BB$43,22-ROW())),"") | X6: =IF($W6="","",IF(COUNTIFS('İş Planı'!$B$5:$B$204,$W6,'İş Planı'!$O$5:$O$204,"Tamamlandı")=0,"",COUNTIFS('İş Planı'!$B$5:$B$204,$W6,'İş Planı'!$O$5:$O$204,"Tamamlandı"))) | Y6: =IF($W6="","",IF(COUNTIFS('İş Planı'!$B$5:$B$204,$W6,'İş Planı'!$O$5:$O$204,"Devam Ediyor")=0,"",COUNTIFS('İş Planı'!$B$5:$B$204,$W6,'İş Planı'!$O$5:$O$204,"Devam Ediyor"))) | Z6: =IF($W6="","",IF(COUNTIFS('İş Planı'!$B$5:$B$204,$W6,'İş Planı'!$O$5:$O$204,"Gecikmiş")=0,"",COUNTIFS('İş Planı'!$B$5:$B$204,$W6,'İş Planı'!$O$5:$O$204,"Gecikmiş"))) | AB6: 46057 | AC6: =SUMPRODUCT(('İş Planı'!$C$5:$C$204<>"")*('İş Planı'!$M$5:$M$204<>"")*('İş Planı'!$M$5:$M$204<=AB6)) -> 0 | AD6: =SUMPRODUCT(('İş Planı'!$C$5:$C$204<>"")*('İş Planı'!$M$5:$M$204<>"")*('İş Planı'!$M$5:$M$204<=AB6)*('İş Planı'!$O$5:$O$204="Tamamlandı")) -> 0 | AF6: May | AG6: 46173 | AH6: =SUMPRODUCT(('İş Planı'!$C$5:$C$204<>"")*('İş Planı'!$M$5:$M$204<>"")*('İş Planı'!$M$5:$M$204<=AG6)) -> 0 | AI6: =SUMPRODUCT(('İş Planı'!$C$5:$C$204<>"")*('İş Planı'!$M$5:$M$204<>"")*('İş Planı'!$M$5:$M$204<=AG6)*('İş Planı'!$O$5:$O$204="Tamamlandı")) -> 0 | AK6: =IFERROR(INDEX(Listeler!$D$4:$D$43,SMALL($BD$4:$BD$43,22-ROW())),"") | AL6: =IF($AK6="","",IF(COUNTIFS('İş Planı'!$D$5:$D$204,$AK6,'İş Planı'!$O$5:$O$204,"Planlanan")+COUNTIFS('İş Planı'!$E$5:$E$204,$AK6,'İş Planı'!$O$5:$O$204,"Planlanan")+COUNTIFS('İş Planı'!$F$5:$F$204,$AK6,'İş Planı'!$O$5:$O$204,"Planlanan")+COUNTIFS('İş Planı'!$G$5:$G$204,$AK6,'İş Planı'!$O$5:$O$204,"Planlanan")+COUNTIFS('İş Planı'!$D$5:$D$204,$AK6,'İş Planı'!$O$5:$O$204,"Devam Ediyor")+COUNTIFS('İş Planı'!$E$5:$E$204,$AK6,'İş Planı'!$O$5:$O$204,"Devam Ediyor")+COUNTIFS('İş Planı'!$F$5:$F$204,$AK6,'İş Planı'!$O$5:$O$204,"Devam Ediyor")+COUNTIFS('İş Planı'!$G$5:$G$204,$AK6,'İş Planı'!$O$5:$O$204,"Devam Ediyor")=0,"",COUNTIFS('İş Planı'!$D$5:$D$204,$AK6,'İş Planı'!$O$5:$O$204,"Planlanan")+COUNTIFS('İş Planı'!$E$5:$E$204,$AK6,'İş Planı'!$O$5:$O$204,"Planlanan")+COUNTIFS('İş Planı'!$F$5:$F$204,$AK6,'İş Planı'!$O$5:$O$204,"Planlanan")+COUNTIFS('İş Planı'!$G$5:$G$204,$AK6,'İş Planı'!$O$5:$O$204,"Planlanan")+COUNTIFS('İş Planı'!$D$5:$D$204,$AK6,'İş Planı'!$O$5:$O$204,"Devam Ediyor")+COUNTIFS('İş Planı'!$E$5:$E$204,$AK6,'İş Planı'!$O$5:$O$204,"Devam Ediyor")+COUNTIFS('İş Planı'!$F$5:$F$204,$AK6,'İş Planı'!$O$5:$O$204,"Devam Ediyor")+COUNTIFS('İş Planı'!$G$5:$G$204,$AK6,'İş Planı'!$O$5:$O$204,"Devam Ediyor"))) | AM6: =IF($AK6="","",IF(COUNTIFS('İş Planı'!$D$5:$D$204,$AK6,'İş Planı'!$O$5:$O$204,"Gecikmiş")+COUNTIFS('İş Planı'!$E$5:$E$204,$AK6,'İş Planı'!$O$5:$O$204,"Gecikmiş")+COUNTIFS('İş Planı'!$F$5:$F$204,$AK6,'İş Planı'!$O$5:$O$204,"Gecikmiş")+COUNTIFS('İş Planı'!$G$5:$G$204,$AK6,'İş Planı'!$O$5:$O$204,"Gecikmiş")=0,"",COUNTIFS('İş Planı'!$D$5:$D$204,$AK6,'İş Planı'!$O$5:$O$204,"Gecikmiş")+COUNTIFS('İş Planı'!$E$5:$E$204,$AK6,'İş Planı'!$O$5:$O$204,"Gecikmiş")+COUNTIFS('İş Planı'!$F$5:$F$204,$AK6,'İş Planı'!$O$5:$O$204,"Gecikmiş")+COUNTIFS('İş Planı'!$G$5:$G$204,$AK6,'İş Planı'!$O$5:$O$204,"Gecikmiş"))) | BB6: =IF(Listeler!$B6="","",IF(COUNTIF('İş Planı'!$B$5:$B$204,Listeler!$B6)=0,"",ROW()-3)) -> 3 | BD6: =IF(Listeler!$D6="","",IF(COUNTIF('İş Planı'!$D$5:$D$204,Listeler!$D6)+COUNTIF('İş Planı'!$E$5:$E$204,Listeler!$D6)+COUNTIF('İş Planı'!$F$5:$F$204,Listeler!$D6)+COUNTIF('İş Planı'!$G$5:$G$204,Listeler!$D6)=0,"",ROW()-3)) -> 3
